Workbook

Sheet ANLEITUNG
B2: Dienstdokumentation – so funktioniert's
B4: EINMALIG | C4: LISTEN | D4: Jahr, Einrichtung, Angebote und Namen des Teams eintragen (gelbe Zellen). Neue Angebote/Namen erscheinen sofort in allen Dropdowns und Auswertungen.
B5: TÄGLICH | C5: ERFASSUNG | D5: Pro durchgeführtem Angebot EINE Zeile: Datum, Angebot, Stunden, Anzahl w/d/m, Altersgruppen, wer Dienst hatte und Notizen. Einfach unten weiterschreiben.
B6: WÖCHENTLICH | C6: WOCHE | D6: Kalenderwoche oben eintragen → Tage, Angebote, Team-Einsätze und 'Wichtiges der Woche' auf einen Blick (z. B. für die Teamsitzung).
B7: MONATLICH | C7: MONAT | D7: Monat oben auswählen → Monatszusammenfassung mit Kennzahlen, Tabellen und Diagrammen.
B8: JÄHRLICH | C8: JAHRESBERICHT | D8: Alles für den Jahresbericht: Kennzahlen mit Vorjahresvergleich, fertiger Textbaustein, Monats-, Angebots-, Wochentags- und Wochenstatistik, Diagramme.
B10: Beispiel – so sieht eine Zeile in ERFASSUNG aus
B11: Datum | C11: Tag | D11: KW | E11: Angebot | F11: Stunden | G11: w | H11: d | I11: m | J11: gesamt | K11: unter 10 | L11: ab 10 | M11: ab 14 | N11: ab 16 | O11: ab 18 | P11: Alters-Check | Q11: Dienst 1 | R11: Dienst 2 | S11: Dienst 3 | T11: Was war los? | U11: Wichtig / Vorkommnisse
B12: 22.09.2026 | C12: Di | D12: 39 | E12: JUGENDCAFE | F12: 4 | G12: 7 | H12: 1 | I12: 12 | J12: 20 | K12: 0 | L12: 5 | M12: 9 | N12: 4 | O12: 2 | P12: ✓ | Q12: Anna | R12: Max | T12: Billard-Turnier | U12: Fenster WC defekt
B14: Farben
C15: Auswahl / Einstellung (z. B. Kalenderwoche, Monat, Jahr, Listen)
C16: Eingabe
C17: rechnet automatisch – nicht überschreiben (Blätter sind ohne Passwort geschützt: Überprüfen → Blattschutz aufheben)
C18: Alters-Check passt nicht: Summe der Altersgruppen ≠ gesamt
B20: Begriffe
B21: Kontakte | C21: Anzahl Besuche. Wer an 3 Tagen kommt, zählt 3 Kontakte.
B22: Einträge | C22: Wie oft ein Angebot stattgefunden hat (= Anzahl Zeilen).
B23: Öffnungstage | C23: Tage mit mindestens einem Eintrag.
B24: Altersgruppen | C24: unter 10 · ab 10 = 10–13 · ab 14 = 14–15 · ab 16 = 16–17 · ab 18 = 18+
B25: Team-Stunden | C25: Stunden des Angebots, bei dem die Person im Dienst eingetragen ist.

Sheet ERFASSUNG
A1: ="Tägliche Erfassung "&LISTEN!$F$2&" – "&LISTEN!$F$3
A2: Pro durchgeführtem Angebot eine Zeile. Weiß = eingeben, grau = rechnet automatisch. Dropdowns für Angebot und Dienst kommen aus dem Blatt LISTEN.
D4: SUMME (Filter beachtet) | E4: =SUBTOTAL(9,E6:E3005) | F4: =SUBTOTAL(9,F6:F3005) | G4: =SUBTOTAL(9,G6:G3005) | H4: =SUBTOTAL(9,H6:H3005) | I4: =SUBTOTAL(9,I6:I3005) | J4: =SUBTOTAL(9,J6:J3005) | K4: =SUBTOTAL(9,K6:K3005) | L4: =SUBTOTAL(9,L6:L3005) | ... N4: =SUBTOTAL(9,N6:N3005)
A5: Datum | B5: Tag | C5: KW | D5: Angebot | E5: Stunden | F5: w | G5: d | H5: m | I5: gesamt | J5: unter 10 | K5: ab 10 | L5: ab 14 | M5: ab 16 | N5: ab 18 | O5: Alters-Check | P5: Dienst 1 | Q5: Dienst 2 | R5: Dienst 3 | S5: Was war los? | T5: Wichtig / Vorkommnisse | V5: Monat | W5: lfd Wichtig Woche | X5: lfd Wichtig Monat
B6: =IF(A6="","",CHOOSE(WEEKDAY(A6,2),"Mo","Di","Mi","Do","Fr","Sa","So")) | C6: =IF(A6="","",INT((A6-DATE(YEAR(A6-WEEKDAY(A6-1)+4),1,3)+WEEKDAY(DATE(YEAR(A6-WEEKDAY(A6-1)+4),1,3))+5)/7)) | I6: =IF(COUNT(F6:H6)=0,"",SUM(F6:H6)) | O6: =IF(OR(I6="",COUNT(J6:N6)=0),"",IF(SUM(J6:N6)=I6,"✓","⚠ "&SUM(J6:N6)&" statt "&I6)) | V6: =IF(A6="","",MONTH(A6)) | W6: =N(W5)+IF(AND(C6<>"",T6<>""),IF(C6=WOCHE!$B$3,1,0),0) | X6: =N(X5)+IF(AND(V6<>"",T6<>""),IF(V6=MONAT!$AZ$3,1,0),0)
B7: =IF(A7="","",CHOOSE(WEEKDAY(A7,2),"Mo","Di","Mi","Do","Fr","Sa","So")) | C7: =IF(A7="","",INT((A7-DATE(YEAR(A7-WEEKDAY(A7-1)+4),1,3)+WEEKDAY(DATE(YEAR(A7-WEEKDAY(A7-1)+4),1,3))+5)/7)) | I7: =IF(COUNT(F7:H7)=0,"",SUM(F7:H7)) | O7: =IF(OR(I7="",COUNT(J7:N7)=0),"",IF(SUM(J7:N7)=I7,"✓","⚠ "&SUM(J7:N7)&" statt "&I7)) | V7: =IF(A7="","",MONTH(A7)) | W7: =N(W6)+IF(AND(C7<>"",T7<>""),IF(C7=WOCHE!$B$3,1,0),0) | X7: =N(X6)+IF(AND(V7<>"",T7<>""),IF(V7=MONAT!$AZ$3,1,0),0)
B8: =IF(A8="","",CHOOSE(WEEKDAY(A8,2),"Mo","Di","Mi","Do","Fr","Sa","So")) | C8: =IF(A8="","",INT((A8-DATE(YEAR(A8-WEEKDAY(A8-1)+4),1,3)+WEEKDAY(DATE(YEAR(A8-WEEKDAY(A8-1)+4),1,3))+5)/7)) | I8: =IF(COUNT(F8:H8)=0,"",SUM(F8:H8)) | O8: =IF(OR(I8="",COUNT(J8:N8)=0),"",IF(SUM(J8:N8)=I8,"✓","⚠ "&SUM(J8:N8)&" statt "&I8)) | V8: =IF(A8="","",MONTH(A8)) | W8: =N(W7)+IF(AND(C8<>"",T8<>""),IF(C8=WOCHE!$B$3,1,0),0) | X8: =N(X7)+IF(AND(V8<>"",T8<>""),IF(V8=MONAT!$AZ$3,1,0),0)
B9: =IF(A9="","",CHOOSE(WEEKDAY(A9,2),"Mo","Di","Mi","Do","Fr","Sa","So")) | C9: =IF(A9="","",INT((A9-DATE(YEAR(A9-WEEKDAY(A9-1)+4),1,3)+WEEKDAY(DATE(YEAR(A9-WEEKDAY(A9-1)+4),1,3))+5)/7)) | I9: =IF(COUNT(F9:H9)=0,"",SUM(F9:H9)) | O9: =IF(OR(I9="",COUNT(J9:N9)=0),"",IF(SUM(J9:N9)=I9,"✓","⚠ "&SUM(J9:N9)&" statt "&I9)) | V9: =IF(A9="","",MONTH(A9)) | W9: =N(W8)+IF(AND(C9<>"",T9<>""),IF(C9=WOCHE!$B$3,1,0),0) | X9: =N(X8)+IF(AND(V9<>"",T9<>""),IF(V9=MONAT!$AZ$3,1,0),0)
B10: =IF(A10="","",CHOOSE(WEEKDAY(A10,2),"Mo","Di","Mi","Do","Fr","Sa","So")) | C10: =IF(A10="","",INT((A10-DATE(YEAR(A10-WEEKDAY(A10-1)+4),1,3)+WEEKDAY(DATE(YEAR(A10-WEEKDAY(A10-1)+4),1,3))+5)/7)) | I10: =IF(COUNT(F10:H10)=0,"",SUM(F10:H10)) | O10: =IF(OR(I10="",COUNT(J10:N10)=0),"",IF(SUM(J10:N10)=I10,"✓","⚠ "&SUM(J10:N10)&" statt "&I10)) | V10: =IF(A10="","",MONTH(A10)) | W10: =N(W9)+IF(AND(C10<>"",T10<>""),IF(C10=WOCHE!$B$3,1,0),0) | X10: =N(X9)+IF(AND(V10<>"",T10<>""),IF(V10=MONAT!$AZ$3,1,0),0)
B11: =IF(A11="","",CHOOSE(WEEKDAY(A11,2),"Mo","Di","Mi","Do","Fr","Sa","So")) | C11: =IF(A11="","",INT((A11-DATE(YEAR(A11-WEEKDAY(A11-1)+4),1,3)+WEEKDAY(DATE(YEAR(A11-WEEKDAY(A11-1)+4),1,3))+5)/7)) | I11: =IF(COUNT(F11:H11)=0,"",SUM(F11:H11)) | O11: =IF(OR(I11="",COUNT(J11:N11)=0),"",IF(SUM(J11:N11)=I11,"✓","⚠ "&SUM(J11:N11)&" statt "&I11)) | V11: =IF(A11="","",MONTH(A11)) | W11: =N(W10)+IF(AND(C11<>"",T11<>""),IF(C11=WOCHE!$B$3,1,0),0) | X11: =N(X10)+IF(AND(V11<>"",T11<>""),IF(V11=MONAT!$AZ$3,1,0),0)
B12: =IF(A12="","",CHOOSE(WEEKDAY(A12,2),"Mo","Di","Mi","Do","Fr","Sa","So")) | C12: =IF(A12="","",INT((A12-DATE(YEAR(A12-WEEKDAY(A12-1)+4),1,3)+WEEKDAY(DATE(YEAR(A12-WEEKDAY(A12-1)+4),1,3))+5)/7)) | I12: =IF(COUNT(F12:H12)=0,"",SUM(F12:H12)) | O12: =IF(OR(I12="",COUNT(J12:N12)=0),"",IF(SUM(J12:N12)=I12,"✓","⚠ "&SUM(J12:N12)&" statt "&I12)) | V12: =IF(A12="","",MONTH(A12)) | W12: =N(W11)+IF(AND(C12<>"",T12<>""),IF(C12=WOCHE!$B$3,1,0),0) | X12: =N(X11)+IF(AND(V12<>"",T12<>""),IF(V12=MONAT!$AZ$3,1,0),0)
B13: =IF(A13="","",CHOOSE(WEEKDAY(A13,2),"Mo","Di","Mi","Do","Fr","Sa","So")) | C13: =IF(A13="","",INT((A13-DATE(YEAR(A13-WEEKDAY(A13-1)+4),1,3)+WEEKDAY(DATE(YEAR(A13-WEEKDAY(A13-1)+4),1,3))+5)/7)) | I13: =IF(COUNT(F13:H13)=0,"",SUM(F13:H13)) | O13: =IF(OR(I13="",COUNT(J13:N13)=0),"",IF(SUM(J13:N13)=I13,"✓","⚠ "&SUM(J13:N13)&" statt "&I13)) | V13: =IF(A13="","",MONTH(A13)) | W13: =N(W12)+IF(AND(C13<>"",T13<>""),IF(C13=WOCHE!$B$3,1,0),0) | X13: =N(X12)+IF(AND(V13<>"",T13<>""),IF(V13=MONAT!$AZ$3,1,0),0)
B14: =IF(A14="","",CHOOSE(WEEKDAY(A14,2),"Mo","Di","Mi","Do","Fr","Sa","So")) | C14: =IF(A14="","",INT((A14-DATE(YEAR(A14-WEEKDAY(A14-1)+4),1,3)+WEEKDAY(DATE(YEAR(A14-WEEKDAY(A14-1)+4),1,3))+5)/7)) | I14: =IF(COUNT(F14:H14)=0,"",SUM(F14:H14)) | O14: =IF(OR(I14="",COUNT(J14:N14)=0),"",IF(SUM(J14:N14)=I14,"✓","⚠ "&SUM(J14:N14)&" statt "&I14)) | V14: =IF(A14="","",MONTH(A14)) | W14: =N(W13)+IF(AND(C14<>"",T14<>""),IF(C14=WOCHE!$B$3,1,0),0) | X14: =N(X13)+IF(AND(V14<>"",T14<>""),IF(V14=MONAT!$AZ$3,1,0),0)
B15: =IF(A15="","",CHOOSE(WEEKDAY(A15,2),"Mo","Di","Mi","Do","Fr","Sa","So")) | C15: =IF(A15="","",INT((A15-DATE(YEAR(A15-WEEKDAY(A15-1)+4),1,3)+WEEKDAY(DATE(YEAR(A15-WEEKDAY(A15-1)+4),1,3))+5)/7)) | I15: =IF(COUNT(F15:H15)=0,"",SUM(F15:H15)) | O15: =IF(OR(I15="",COUNT(J15:N15)=0),"",IF(SUM(J15:N15)=I15,"✓","⚠ "&SUM(J15:N15)&" statt "&I15)) | V15: =IF(A15="","",MONTH(A15)) | W15: =N(W14)+IF(AND(C15<>"",T15<>""),IF(C15=WOCHE!$B$3,1,0),0) | X15: =N(X14)+IF(AND(V15<>"",T15<>""),IF(V15=MONAT!$AZ$3,1,0),0)
B16: =IF(A16="","",CHOOSE(WEEKDAY(A16,2),"Mo","Di","Mi","Do","Fr","Sa","So")) | C16: =IF(A16="","",INT((A16-DATE(YEAR(A16-WEEKDAY(A16-1)+4),1,3)+WEEKDAY(DATE(YEAR(A16-WEEKDAY(A16-1)+4),1,3))+5)/7)) | I16: =IF(COUNT(F16:H16)=0,"",SUM(F16:H16)) | O16: =IF(OR(I16="",COUNT(J16:N16)=0),"",IF(SUM(J16:N16)=I16,"✓","⚠ "&SUM(J16:N16)&" statt "&I16)) | V16: =IF(A16="","",MONTH(A16)) | W16: =N(W15)+IF(AND(C16<>"",T16<>""),IF(C16=WOCHE!$B$3,1,0),0) | X16: =N(X15)+IF(AND(V16<>"",T16<>""),IF(V16=MONAT!$AZ$3,1,0),0)
B17: =IF(A17="","",CHOOSE(WEEKDAY(A17,2),"Mo","Di","Mi","Do","Fr","Sa","So")) | C17: =IF(A17="","",INT((A17-DATE(YEAR(A17-WEEKDAY(A17-1)+4),1,3)+WEEKDAY(DATE(YEAR(A17-WEEKDAY(A17-1)+4),1,3))+5)/7)) | I17: =IF(COUNT(F17:H17)=0,"",SUM(F17:H17)) | O17: =IF(OR(I17="",COUNT(J17:N17)=0),"",IF(SUM(J17:N17)=I17,"✓","⚠ "&SUM(J17:N17)&" statt "&I17)) | V17: =IF(A17="","",MONTH(A17)) | W17: =N(W16)+IF(AND(C17<>"",T17<>""),IF(C17=WOCHE!$B$3,1,0),0) | X17: =N(X16)+IF(AND(V17<>"",T17<>""),IF(V17=MONAT!$AZ$3,1,0),0)
... B3005: =IF(A3005="","",CHOOSE(WEEKDAY(A3005,2),"Mo","Di","Mi","Do","Fr","Sa","So")) | C3005: =IF(A3005="","",INT((A3005-DATE(YEAR(A3005-WEEKDAY(A3005-1)+4),1,3)+WEEKDAY(DATE(YEAR(A3005-WEEKDAY(A3005-1)+4),1,3))+5)/7)) | I3005: =IF(COUNT(F3005:H3005)=0,"",SUM(F3005:H3005)) | O3005: =IF(OR(I3005="",COUNT(J3005:N3005)=0),"",IF(SUM(J3005:N3005)=I3005,"✓","⚠ "&SUM(J3005:N3005)&" statt "&I3005)) | V3005: =IF(A3005="","",MONTH(A3005)) | W3005: =N(W3004)+IF(AND(C3005<>"",T3005<>""),IF(C3005=WOCHE!$B$3,1,0),0) | X3005: =N(X3004)+IF(AND(V3005<>"",T3005<>""),IF(V3005=MONAT!$AZ$3,1,0),0)

Sheet WOCHE
A1: ="Wochenübersicht "&LISTEN!$F$3
A2: Kalenderwoche in der gelben Zelle eintragen – alles andere rechnet automatisch.
A3: Kalenderwoche: | B3: 39 | C3: von | D3: =DATE(LISTEN!$F$2,1,4)-WEEKDAY(DATE(LISTEN!$F$2,1,4),2)+1+($B$3-1)*7 | F3: bis | G3: =D3+6
A5: Öffnungstage | C5: Einträge (Angebote) | E5: Kontakte gesamt | G5: Ø Kontakte pro Öffnungstag | I5: Stunden | K5: weiblich | M5: divers | O5: männlich
A6: =COUNTIF($C$10:$C$16,">0") | C6: =$C$17 | E6: =($E$17+$F$17+$G$17) | G6: =IF(N(COUNTIF($C$10:$C$16,">0"))=0,0,($E$17+$F$17+$G$17)/COUNTIF($C$10:$C$16,">0")) | I6: =$D$17 | K6: =IF(($E$17+$F$17+$G$17)=0,0,$E$17/($E$17+$F$17+$G$17)) | M6: =IF(($E$17+$F$17+$G$17)=0,0,$F$17/($E$17+$F$17+$G$17)) | O6: =IF(($E$17+$F$17+$G$17)=0,0,$G$17/($E$17+$F$17+$G$17))
A8: Tage der Woche
A9: Tag | B9: Datum | C9: Einträge | D9: Stunden | E9: w | F9: d | G9: m | H9: gesamt | I9: unter 10 | J9: ab 10 | K9: ab 14 | L9: ab 16 | M9: ab 18
A10: =CHOOSE(1,"Mo","Di","Mi","Do","Fr","Sa","So")&" "&DAY(B10)&"."&MONTH(B10)&"." | B10: =$D$3+0 | C10: =SUMIFS(KALENDER!$F$5:$F$370,KALENDER!$A$5:$A$370,B10) | D10: =SUMIFS(KALENDER!$H$5:$H$370,KALENDER!$A$5:$A$370,B10) | E10: =SUMIFS(KALENDER!$I$5:$I$370,KALENDER!$A$5:$A$370,B10) | F10: =SUMIFS(KALENDER!$J$5:$J$370,KALENDER!$A$5:$A$370,B10) | G10: =SUMIFS(KALENDER!$K$5:$K$370,KALENDER!$A$5:$A$370,B10) | H10: =SUMIFS(KALENDER!$L$5:$L$370,KALENDER!$A$5:$A$370,B10) | I10: =SUMIFS(KALENDER!$M$5:$M$370,KALENDER!$A$5:$A$370,B10) | J10: =SUMIFS(KALENDER!$N$5:$N$370,KALENDER!$A$5:$A$370,B10) | K10: =SUMIFS(KALENDER!$O$5:$O$370,KALENDER!$A$5:$A$370,B10) | L10: =SUMIFS(KALENDER!$P$5:$P$370,KALENDER!$A$5:$A$370,B10) | M10: =SUMIFS(KALENDER!$Q$5:$Q$370,KALENDER!$A$5:$A$370,B10)
A11: =CHOOSE(2,"Mo","Di","Mi","Do","Fr","Sa","So")&" "&DAY(B11)&"."&MONTH(B11)&"." | B11: =$D$3+1 | C11: =SUMIFS(KALENDER!$F$5:$F$370,KALENDER!$A$5:$A$370,B11) | D11: =SUMIFS(KALENDER!$H$5:$H$370,KALENDER!$A$5:$A$370,B11) | E11: =SUMIFS(KALENDER!$I$5:$I$370,KALENDER!$A$5:$A$370,B11) | F11: =SUMIFS(KALENDER!$J$5:$J$370,KALENDER!$A$5:$A$370,B11) | G11: =SUMIFS(KALENDER!$K$5:$K$370,KALENDER!$A$5:$A$370,B11) | H11: =SUMIFS(KALENDER!$L$5:$L$370,KALENDER!$A$5:$A$370,B11) | I11: =SUMIFS(KALENDER!$M$5:$M$370,KALENDER!$A$5:$A$370,B11) | J11: =SUMIFS(KALENDER!$N$5:$N$370,KALENDER!$A$5:$A$370,B11) | K11: =SUMIFS(KALENDER!$O$5:$O$370,KALENDER!$A$5:$A$370,B11) | L11: =SUMIFS(KALENDER!$P$5:$P$370,KALENDER!$A$5:$A$370,B11) | M11: =SUMIFS(KALENDER!$Q$5:$Q$370,KALENDER!$A$5:$A$370,B11)
A12: =CHOOSE(3,"Mo","Di","Mi","Do","Fr","Sa","So")&" "&DAY(B12)&"."&MONTH(B12)&"." | B12: =$D$3+2 | C12: =SUMIFS(KALENDER!$F$5:$F$370,KALENDER!$A$5:$A$370,B12) | D12: =SUMIFS(KALENDER!$H$5:$H$370,KALENDER!$A$5:$A$370,B12) | E12: =SUMIFS(KALENDER!$I$5:$I$370,KALENDER!$A$5:$A$370,B12) | F12: =SUMIFS(KALENDER!$J$5:$J$370,KALENDER!$A$5:$A$370,B12) | G12: =SUMIFS(KALENDER!$K$5:$K$370,KALENDER!$A$5:$A$370,B12) | H12: =SUMIFS(KALENDER!$L$5:$L$370,KALENDER!$A$5:$A$370,B12) | I12: =SUMIFS(KALENDER!$M$5:$M$370,KALENDER!$A$5:$A$370,B12) | J12: =SUMIFS(KALENDER!$N$5:$N$370,KALENDER!$A$5:$A$370,B12) | K12: =SUMIFS(KALENDER!$O$5:$O$370,KALENDER!$A$5:$A$370,B12) | L12: =SUMIFS(KALENDER!$P$5:$P$370,KALENDER!$A$5:$A$370,B12) | M12: =SUMIFS(KALENDER!$Q$5:$Q$370,KALENDER!$A$5:$A$370,B12)
A13: =CHOOSE(4,"Mo","Di","Mi","Do","Fr","Sa","So")&" "&DAY(B13)&"."&MONTH(B13)&"." | B13: =$D$3+3 | C13: =SUMIFS(KALENDER!$F$5:$F$370,KALENDER!$A$5:$A$370,B13) | D13: =SUMIFS(KALENDER!$H$5:$H$370,KALENDER!$A$5:$A$370,B13) | E13: =SUMIFS(KALENDER!$I$5:$I$370,KALENDER!$A$5:$A$370,B13) | F13: =SUMIFS(KALENDER!$J$5:$J$370,KALENDER!$A$5:$A$370,B13) | G13: =SUMIFS(KALENDER!$K$5:$K$370,KALENDER!$A$5:$A$370,B13) | H13: =SUMIFS(KALENDER!$L$5:$L$370,KALENDER!$A$5:$A$370,B13) | I13: =SUMIFS(KALENDER!$M$5:$M$370,KALENDER!$A$5:$A$370,B13) | J13: =SUMIFS(KALENDER!$N$5:$N$370,KALENDER!$A$5:$A$370,B13) | K13: =SUMIFS(KALENDER!$O$5:$O$370,KALENDER!$A$5:$A$370,B13) | L13: =SUMIFS(KALENDER!$P$5:$P$370,KALENDER!$A$5:$A$370,B13) | M13: =SUMIFS(KALENDER!$Q$5:$Q$370,KALENDER!$A$5:$A$370,B13)
A14: =CHOOSE(5,"Mo","Di","Mi","Do","Fr","Sa","So")&" "&DAY(B14)&"."&MONTH(B14)&"." | B14: =$D$3+4 | C14: =SUMIFS(KALENDER!$F$5:$F$370,KALENDER!$A$5:$A$370,B14) | D14: =SUMIFS(KALENDER!$H$5:$H$370,KALENDER!$A$5:$A$370,B14) | E14: =SUMIFS(KALENDER!$I$5:$I$370,KALENDER!$A$5:$A$370,B14) | F14: =SUMIFS(KALENDER!$J$5:$J$370,KALENDER!$A$5:$A$370,B14) | G14: =SUMIFS(KALENDER!$K$5:$K$370,KALENDER!$A$5:$A$370,B14) | H14: =SUMIFS(KALENDER!$L$5:$L$370,KALENDER!$A$5:$A$370,B14) | I14: =SUMIFS(KALENDER!$M$5:$M$370,KALENDER!$A$5:$A$370,B14) | J14: =SUMIFS(KALENDER!$N$5:$N$370,KALENDER!$A$5:$A$370,B14) | K14: =SUMIFS(KALENDER!$O$5:$O$370,KALENDER!$A$5:$A$370,B14) | L14: =SUMIFS(KALENDER!$P$5:$P$370,KALENDER!$A$5:$A$370,B14) | M14: =SUMIFS(KALENDER!$Q$5:$Q$370,KALENDER!$A$5:$A$370,B14)
A15: =CHOOSE(6,"Mo","Di","Mi","Do","Fr","Sa","So")&" "&DAY(B15)&"."&MONTH(B15)&"." | B15: =$D$3+5 | C15: =SUMIFS(KALENDER!$F$5:$F$370,KALENDER!$A$5:$A$370,B15) | D15: =SUMIFS(KALENDER!$H$5:$H$370,KALENDER!$A$5:$A$370,B15) | E15: =SUMIFS(KALENDER!$I$5:$I$370,KALENDER!$A$5:$A$370,B15) | F15: =SUMIFS(KALENDER!$J$5:$J$370,KALENDER!$A$5:$A$370,B15) | G15: =SUMIFS(KALENDER!$K$5:$K$370,KALENDER!$A$5:$A$370,B15) | H15: =SUMIFS(KALENDER!$L$5:$L$370,KALENDER!$A$5:$A$370,B15) | I15: =SUMIFS(KALENDER!$M$5:$M$370,KALENDER!$A$5:$A$370,B15) | J15: =SUMIFS(KALENDER!$N$5:$N$370,KALENDER!$A$5:$A$370,B15) | K15: =SUMIFS(KALENDER!$O$5:$O$370,KALENDER!$A$5:$A$370,B15) | L15: =SUMIFS(KALENDER!$P$5:$P$370,KALENDER!$A$5:$A$370,B15) | M15: =SUMIFS(KALENDER!$Q$5:$Q$370,KALENDER!$A$5:$A$370,B15)
A16: =CHOOSE(7,"Mo","Di","Mi","Do","Fr","Sa","So")&" "&DAY(B16)&"."&MONTH(B16)&"." | B16: =$D$3+6 | C16: =SUMIFS(KALENDER!$F$5:$F$370,KALENDER!$A$5:$A$370,B16) | D16: =SUMIFS(KALENDER!$H$5:$H$370,KALENDER!$A$5:$A$370,B16) | E16: =SUMIFS(KALENDER!$I$5:$I$370,KALENDER!$A$5:$A$370,B16) | F16: =SUMIFS(KALENDER!$J$5:$J$370,KALENDER!$A$5:$A$370,B16) | G16: =SUMIFS(KALENDER!$K$5:$K$370,KALENDER!$A$5:$A$370,B16) | H16: =SUMIFS(KALENDER!$L$5:$L$370,KALENDER!$A$5:$A$370,B16) | I16: =SUMIFS(KALENDER!$M$5:$M$370,KALENDER!$A$5:$A$370,B16) | J16: =SUMIFS(KALENDER!$N$5:$N$370,KALENDER!$A$5:$A$370,B16) | K16: =SUMIFS(KALENDER!$O$5:$O$370,KALENDER!$A$5:$A$370,B16) | L16: =SUMIFS(KALENDER!$P$5:$P$370,KALENDER!$A$5:$A$370,B16) | M16: =SUMIFS(KALENDER!$Q$5:$Q$370,KALENDER!$A$5:$A$370,B16)
A17: SUMME | C17: =SUM(C10:C16) | D17: =SUM(D10:D16) | E17: =SUM(E10:E16) | F17: =SUM(F10:F16) | G17: =SUM(G10:G16) | H17: =SUM(H10:H16) | I17: =SUM(I10:I16) | J17: =SUM(J10:J16) | ... M17: =SUM(M10:M16)
A19: Angebote dieser Woche
A20: Angebot | B20: Einträge | C20: Stunden | D20: w | E20: d | F20: m | G20: gesamt | H20: unter 10 | I20: ab 10 | J20: ab 14 | K20: ab 16 | L20: ab 18 | M20: Anteil
A21: =IF(LISTEN!$A$2="","",LISTEN!$A$2) | B21: =IF($A21="","",COUNTIFS(ERFASSUNG!$D$6:$D$3005,$A21,ERFASSUNG!$C$6:$C$3005,$B$3)) | C21: =IF($A21="","",SUMIFS(ERFASSUNG!$E$6:$E$3005,ERFASSUNG!$D$6:$D$3005,$A21,ERFASSUNG!$C$6:$C$3005,$B$3)) | D21: =IF($A21="","",SUMIFS(ERFASSUNG!$F$6:$F$3005,ERFASSUNG!$D$6:$D$3005,$A21,ERFASSUNG!$C$6:$C$3005,$B$3)) | E21: =IF($A21="","",SUMIFS(ERFASSUNG!$G$6:$G$3005,ERFASSUNG!$D$6:$D$3005,$A21,ERFASSUNG!$C$6:$C$3005,$B$3)) | F21: =IF($A21="","",SUMIFS(ERFASSUNG!$H$6:$H$3005,ERFASSUNG!$D$6:$D$3005,$A21,ERFASSUNG!$C$6:$C$3005,$B$3)) | G21: =IF($A21="","",SUMIFS(ERFASSUNG!$I$6:$I$3005,ERFASSUNG!$D$6:$D$3005,$A21,ERFASSUNG!$C$6:$C$3005,$B$3)) | H21: =IF($A21="","",SUMIFS(ERFASSUNG!$J$6:$J$3005,ERFASSUNG!$D$6:$D$3005,$A21,ERFASSUNG!$C$6:$C$3005,$B$3)) | I21: =IF($A21="","",SUMIFS(ERFASSUNG!$K$6:$K$3005,ERFASSUNG!$D$6:$D$3005,$A21,ERFASSUNG!$C$6:$C$3005,$B$3)) | J21: =IF($A21="","",SUMIFS(ERFASSUNG!$L$6:$L$3005,ERFASSUNG!$D$6:$D$3005,$A21,ERFASSUNG!$C$6:$C$3005,$B$3)) | K21: =IF($A21="","",SUMIFS(ERFASSUNG!$M$6:$M$3005,ERFASSUNG!$D$6:$D$3005,$A21,ERFASSUNG!$C$6:$C$3005,$B$3)) | L21: =IF($A21="","",SUMIFS(ERFASSUNG!$N$6:$N$3005,ERFASSUNG!$D$6:$D$3005,$A21,ERFASSUNG!$C$6:$C$3005,$B$3)) | M21: =IF(OR($A21="",N($G$51)=0),"",G21/$G$51)
A22: =IF(LISTEN!$A$3="","",LISTEN!$A$3) | B22: =IF($A22="","",COUNTIFS(ERFASSUNG!$D$6:$D$3005,$A22,ERFASSUNG!$C$6:$C$3005,$B$3)) | C22: =IF($A22="","",SUMIFS(ERFASSUNG!$E$6:$E$3005,ERFASSUNG!$D$6:$D$3005,$A22,ERFASSUNG!$C$6:$C$3005,$B$3)) | D22: =IF($A22="","",SUMIFS(ERFASSUNG!$F$6:$F$3005,ERFASSUNG!$D$6:$D$3005,$A22,ERFASSUNG!$C$6:$C$3005,$B$3)) | E22: =IF($A22="","",SUMIFS(ERFASSUNG!$G$6:$G$3005,ERFASSUNG!$D$6:$D$3005,$A22,ERFASSUNG!$C$6:$C$3005,$B$3)) | F22: =IF($A22="","",SUMIFS(ERFASSUNG!$H$6:$H$3005,ERFASSUNG!$D$6:$D$3005,$A22,ERFASSUNG!$C$6:$C$3005,$B$3)) | G22: =IF($A22="","",SUMIFS(ERFASSUNG!$I$6:$I$3005,ERFASSUNG!$D$6:$D$3005,$A22,ERFASSUNG!$C$6:$C$3005,$B$3)) | H22: =IF($A22="","",SUMIFS(ERFASSUNG!$J$6:$J$3005,ERFASSUNG!$D$6:$D$3005,$A22,ERFASSUNG!$C$6:$C$3005,$B$3)) | I22: =IF($A22="","",SUMIFS(ERFASSUNG!$K$6:$K$3005,ERFASSUNG!$D$6:$D$3005,$A22,ERFASSUNG!$C$6:$C$3005,$B$3)) | J22: =IF($A22="","",SUMIFS(ERFASSUNG!$L$6:$L$3005,ERFASSUNG!$D$6:$D$3005,$A22,ERFASSUNG!$C$6:$C$3005,$B$3)) | K22: =IF($A22="","",SUMIFS(ERFASSUNG!$M$6:$M$3005,ERFASSUNG!$D$6:$D$3005,$A22,ERFASSUNG!$C$6:$C$3005,$B$3)) | L22: =IF($A22="","",SUMIFS(ERFASSUNG!$N$6:$N$3005,ERFASSUNG!$D$6:$D$3005,$A22,ERFASSUNG!$C$6:$C$3005,$B$3)) | M22: =IF(OR($A22="",N($G$51)=0),"",G22/$G$51)
A23: =IF(LISTEN!$A$4="","",LISTEN!$A$4) | B23: =IF($A23="","",COUNTIFS(ERFASSUNG!$D$6:$D$3005,$A23,ERFASSUNG!$C$6:$C$3005,$B$3)) | C23: =IF($A23="","",SUMIFS(ERFASSUNG!$E$6:$E$3005,ERFASSUNG!$D$6:$D$3005,$A23,ERFASSUNG!$C$6:$C$3005,$B$3)) | D23: =IF($A23="","",SUMIFS(ERFASSUNG!$F$6:$F$3005,ERFASSUNG!$D$6:$D$3005,$A23,ERFASSUNG!$C$6:$C$3005,$B$3)) | E23: =IF($A23="","",SUMIFS(ERFASSUNG!$G$6:$G$3005,ERFASSUNG!$D$6:$D$3005,$A23,ERFASSUNG!$C$6:$C$3005,$B$3)) | F23: =IF($A23="","",SUMIFS(ERFASSUNG!$H$6:$H$3005,ERFASSUNG!$D$6:$D$3005,$A23,ERFASSUNG!$C$6:$C$3005,$B$3)) | G23: =IF($A23="","",SUMIFS(ERFASSUNG!$I$6:$I$3005,ERFASSUNG!$D$6:$D$3005,$A23,ERFASSUNG!$C$6:$C$3005,$B$3)) | H23: =IF($A23="","",SUMIFS(ERFASSUNG!$J$6:$J$3005,ERFASSUNG!$D$6:$D$3005,$A23,ERFASSUNG!$C$6:$C$3005,$B$3)) | I23: =IF($A23="","",SUMIFS(ERFASSUNG!$K$6:$K$3005,ERFASSUNG!$D$6:$D$3005,$A23,ERFASSUNG!$C$6:$C$3005,$B$3)) | J23: =IF($A23="","",SUMIFS(ERFASSUNG!$L$6:$L$3005,ERFASSUNG!$D$6:$D$3005,$A23,ERFASSUNG!$C$6:$C$3005,$B$3)) | K23: =IF($A23="","",SUMIFS(ERFASSUNG!$M$6:$M$3005,ERFASSUNG!$D$6:$D$3005,$A23,ERFASSUNG!$C$6:$C$3005,$B$3)) | L23: =IF($A23="","",SUMIFS(ERFASSUNG!$N$6:$N$3005,ERFASSUNG!$D$6:$D$3005,$A23,ERFASSUNG!$C$6:$C$3005,$B$3)) | M23: =IF(OR($A23="",N($G$51)=0),"",G23/$G$51)
A24: =IF(LISTEN!$A$5="","",LISTEN!$A$5) | B24: =IF($A24="","",COUNTIFS(ERFASSUNG!$D$6:$D$3005,$A24,ERFASSUNG!$C$6:$C$3005,$B$3)) | C24: =IF($A24="","",SUMIFS(ERFASSUNG!$E$6:$E$3005,ERFASSUNG!$D$6:$D$3005,$A24,ERFASSUNG!$C$6:$C$3005,$B$3)) | D24: =IF($A24="","",SUMIFS(ERFASSUNG!$F$6:$F$3005,ERFASSUNG!$D$6:$D$3005,$A24,ERFASSUNG!$C$6:$C$3005,$B$3)) | E24: =IF($A24="","",SUMIFS(ERFASSUNG!$G$6:$G$3005,ERFASSUNG!$D$6:$D$3005,$A24,ERFASSUNG!$C$6:$C$3005,$B$3)) | F24: =IF($A24="","",SUMIFS(ERFASSUNG!$H$6:$H$3005,ERFASSUNG!$D$6:$D$3005,$A24,ERFASSUNG!$C$6:$C$3005,$B$3)) | G24: =IF($A24="","",SUMIFS(ERFASSUNG!$I$6:$I$3005,ERFASSUNG!$D$6:$D$3005,$A24,ERFASSUNG!$C$6:$C$3005,$B$3)) | H24: =IF($A24="","",SUMIFS(ERFASSUNG!$J$6:$J$3005,ERFASSUNG!$D$6:$D$3005,$A24,ERFASSUNG!$C$6:$C$3005,$B$3)) | I24: =IF($A24="","",SUMIFS(ERFASSUNG!$K$6:$K$3005,ERFASSUNG!$D$6:$D$3005,$A24,ERFASSUNG!$C$6:$C$3005,$B$3)) | J24: =IF($A24="","",SUMIFS(ERFASSUNG!$L$6:$L$3005,ERFASSUNG!$D$6:$D$3005,$A24,ERFASSUNG!$C$6:$C$3005,$B$3)) | K24: =IF($A24="","",SUMIFS(ERFASSUNG!$M$6:$M$3005,ERFASSUNG!$D$6:$D$3005,$A24,ERFASSUNG!$C$6:$C$3005,$B$3)) | L24: =IF($A24="","",SUMIFS(ERFASSUNG!$N$6:$N$3005,ERFASSUNG!$D$6:$D$3005,$A24,ERFASSUNG!$C$6:$C$3005,$B$3)) | M24: =IF(OR($A24="",N($G$51)=0),"",G24/$G$51)
A25: =IF(LISTEN!$A$6="","",LISTEN!$A$6) | B25: =IF($A25="","",COUNTIFS(ERFASSUNG!$D$6:$D$3005,$A25,ERFASSUNG!$C$6:$C$3005,$B$3)) | C25: =IF($A25="","",SUMIFS(ERFASSUNG!$E$6:$E$3005,ERFASSUNG!$D$6:$D$3005,$A25,ERFASSUNG!$C$6:$C$3005,$B$3)) | D25: =IF($A25="","",SUMIFS(ERFASSUNG!$F$6:$F$3005,ERFASSUNG!$D$6:$D$3005,$A25,ERFASSUNG!$C$6:$C$3005,$B$3)) | E25: =IF($A25="","",SUMIFS(ERFASSUNG!$G$6:$G$3005,ERFASSUNG!$D$6:$D$3005,$A25,ERFASSUNG!$C$6:$C$3005,$B$3)) | F25: =IF($A25="","",SUMIFS(ERFASSUNG!$H$6:$H$3005,ERFASSUNG!$D$6:$D$3005,$A25,ERFASSUNG!$C$6:$C$3005,$B$3)) | G25: =IF($A25="","",SUMIFS(ERFASSUNG!$I$6:$I$3005,ERFASSUNG!$D$6:$D$3005,$A25,ERFASSUNG!$C$6:$C$3005,$B$3)) | H25: =IF($A25="","",SUMIFS(ERFASSUNG!$J$6:$J$3005,ERFASSUNG!$D$6:$D$3005,$A25,ERFASSUNG!$C$6:$C$3005,$B$3)) | I25: =IF($A25="","",SUMIFS(ERFASSUNG!$K$6:$K$3005,ERFASSUNG!$D$6:$D$3005,$A25,ERFASSUNG!$C$6:$C$3005,$B$3)) | J25: =IF($A25="","",SUMIFS(ERFASSUNG!$L$6:$L$3005,ERFASSUNG!$D$6:$D$3005,$A25,ERFASSUNG!$C$6:$C$3005,$B$3)) | K25: =IF($A25="","",SUMIFS(ERFASSUNG!$M$6:$M$3005,ERFASSUNG!$D$6:$D$3005,$A25,ERFASSUNG!$C$6:$C$3005,$B$3)) | L25: =IF($A25="","",SUMIFS(ERFASSUNG!$N$6:$N$3005,ERFASSUNG!$D$6:$D$3005,$A25,ERFASSUNG!$C$6:$C$3005,$B$3)) | M25: =IF(OR($A25="",N($G$51)=0),"",G25/$G$51)
A26: =IF(LISTEN!$A$7="","",LISTEN!$A$7) | B26: =IF($A26="","",COUNTIFS(ERFASSUNG!$D$6:$D$3005,$A26,ERFASSUNG!$C$6:$C$3005,$B$3)) | C26: =IF($A26="","",SUMIFS(ERFASSUNG!$E$6:$E$3005,ERFASSUNG!$D$6:$D$3005,$A26,ERFASSUNG!$C$6:$C$3005,$B$3)) | D26: =IF($A26="","",SUMIFS(ERFASSUNG!$F$6:$F$3005,ERFASSUNG!$D$6:$D$3005,$A26,ERFASSUNG!$C$6:$C$3005,$B$3)) | E26: =IF($A26="","",SUMIFS(ERFASSUNG!$G$6:$G$3005,ERFASSUNG!$D$6:$D$3005,$A26,ERFASSUNG!$C$6:$C$3005,$B$3)) | F26: =IF($A26="","",SUMIFS(ERFASSUNG!$H$6:$H$3005,ERFASSUNG!$D$6:$D$3005,$A26,ERFASSUNG!$C$6:$C$3005,$B$3)) | G26: =IF($A26="","",SUMIFS(ERFASSUNG!$I$6:$I$3005,ERFASSUNG!$D$6:$D$3005,$A26,ERFASSUNG!$C$6:$C$3005,$B$3)) | H26: =IF($A26="","",SUMIFS(ERFASSUNG!$J$6:$J$3005,ERFASSUNG!$D$6:$D$3005,$A26,ERFASSUNG!$C$6:$C$3005,$B$3)) | I26: =IF($A26="","",SUMIFS(ERFASSUNG!$K$6:$K$3005,ERFASSUNG!$D$6:$D$3005,$A26,ERFASSUNG!$C$6:$C$3005,$B$3)) | J26: =IF($A26="","",SUMIFS(ERFASSUNG!$L$6:$L$3005,ERFASSUNG!$D$6:$D$3005,$A26,ERFASSUNG!$C$6:$C$3005,$B$3)) | K26: =IF($A26="","",SUMIFS(ERFASSUNG!$M$6:$M$3005,ERFASSUNG!$D$6:$D$3005,$A26,ERFASSUNG!$C$6:$C$3005,$B$3)) | L26: =IF($A26="","",SUMIFS(ERFASSUNG!$N$6:$N$3005,ERFASSUNG!$D$6:$D$3005,$A26,ERFASSUNG!$C$6:$C$3005,$B$3)) | M26: =IF(OR($A26="",N($G$51)=0),"",G26/$G$51)
A27: =IF(LISTEN!$A$8="","",LISTEN!$A$8) | B27: =IF($A27="","",COUNTIFS(ERFASSUNG!$D$6:$D$3005,$A27,ERFASSUNG!$C$6:$C$3005,$B$3)) | C27: =IF($A27="","",SUMIFS(ERFASSUNG!$E$6:$E$3005,ERFASSUNG!$D$6:$D$3005,$A27,ERFASSUNG!$C$6:$C$3005,$B$3)) | D27: =IF($A27="","",SUMIFS(ERFASSUNG!$F$6:$F$3005,ERFASSUNG!$D$6:$D$3005,$A27,ERFASSUNG!$C$6:$C$3005,$B$3)) | E27: =IF($A27="","",SUMIFS(ERFASSUNG!$G$6:$G$3005,ERFASSUNG!$D$6:$D$3005,$A27,ERFASSUNG!$C$6:$C$3005,$B$3)) | F27: =IF($A27="","",SUMIFS(ERFASSUNG!$H$6:$H$3005,ERFASSUNG!$D$6:$D$3005,$A27,ERFASSUNG!$C$6:$C$3005,$B$3)) | G27: =IF($A27="","",SUMIFS(ERFASSUNG!$I$6:$I$3005,ERFASSUNG!$D$6:$D$3005,$A27,ERFASSUNG!$C$6:$C$3005,$B$3)) | H27: =IF($A27="","",SUMIFS(ERFASSUNG!$J$6:$J$3005,ERFASSUNG!$D$6:$D$3005,$A27,ERFASSUNG!$C$6:$C$3005,$B$3)) | I27: =IF($A27="","",SUMIFS(ERFASSUNG!$K$6:$K$3005,ERFASSUNG!$D$6:$D$3005,$A27,ERFASSUNG!$C$6:$C$3005,$B$3)) | J27: =IF($A27="","",SUMIFS(ERFASSUNG!$L$6:$L$3005,ERFASSUNG!$D$6:$D$3005,$A27,ERFASSUNG!$C$6:$C$3005,$B$3)) | K27: =IF($A27="","",SUMIFS(ERFASSUNG!$M$6:$M$3005,ERFASSUNG!$D$6:$D$3005,$A27,ERFASSUNG!$C$6:$C$3005,$B$3)) | L27: =IF($A27="","",SUMIFS(ERFASSUNG!$N$6:$N$3005,ERFASSUNG!$D$6:$D$3005,$A27,ERFASSUNG!$C$6:$C$3005,$B$3)) | M27: =IF(OR($A27="",N($G$51)=0),"",G27/$G$51)
A28: =IF(LISTEN!$A$9="","",LISTEN!$A$9) | B28: =IF($A28="","",COUNTIFS(ERFASSUNG!$D$6:$D$3005,$A28,ERFASSUNG!$C$6:$C$3005,$B$3)) | C28: =IF($A28="","",SUMIFS(ERFASSUNG!$E$6:$E$3005,ERFASSUNG!$D$6:$D$3005,$A28,ERFASSUNG!$C$6:$C$3005,$B$3)) | D28: =IF($A28="","",SUMIFS(ERFASSUNG!$F$6:$F$3005,ERFASSUNG!$D$6:$D$3005,$A28,ERFASSUNG!$C$6:$C$3005,$B$3)) | E28: =IF($A28="","",SUMIFS(ERFASSUNG!$G$6:$G$3005,ERFASSUNG!$D$6:$D$3005,$A28,ERFASSUNG!$C$6:$C$3005,$B$3)) | F28: =IF($A28="","",SUMIFS(ERFASSUNG!$H$6:$H$3005,ERFASSUNG!$D$6:$D$3005,$A28,ERFASSUNG!$C$6:$C$3005,$B$3)) | G28: =IF($A28="","",SUMIFS(ERFASSUNG!$I$6:$I$3005,ERFASSUNG!$D$6:$D$3005,$A28,ERFASSUNG!$C$6:$C$3005,$B$3)) | H28: =IF($A28="","",SUMIFS(ERFASSUNG!$J$6:$J$3005,ERFASSUNG!$D$6:$D$3005,$A28,ERFASSUNG!$C$6:$C$3005,$B$3)) | I28: =IF($A28="","",SUMIFS(ERFASSUNG!$K$6:$K$3005,ERFASSUNG!$D$6:$D$3005,$A28,ERFASSUNG!$C$6:$C$3005,$B$3)) | J28: =IF($A28="","",SUMIFS(ERFASSUNG!$L$6:$L$3005,ERFASSUNG!$D$6:$D$3005,$A28,ERFASSUNG!$C$6:$C$3005,$B$3)) | K28: =IF($A28="","",SUMIFS(ERFASSUNG!$M$6:$M$3005,ERFASSUNG!$D$6:$D$3005,$A28,ERFASSUNG!$C$6:$C$3005,$B$3)) | L28: =IF($A28="","",SUMIFS(ERFASSUNG!$N$6:$N$3005,ERFASSUNG!$D$6:$D$3005,$A28,ERFASSUNG!$C$6:$C$3005,$B$3)) | M28: =IF(OR($A28="",N($G$51)=0),"",G28/$G$51)
A29: =IF(LISTEN!$A$10="","",LISTEN!$A$10) | B29: =IF($A29="","",COUNTIFS(ERFASSUNG!$D$6:$D$3005,$A29,ERFASSUNG!$C$6:$C$3005,$B$3)) | C29: =IF($A29="","",SUMIFS(ERFASSUNG!$E$6:$E$3005,ERFASSUNG!$D$6:$D$3005,$A29,ERFASSUNG!$C$6:$C$3005,$B$3)) | D29: =IF($A29="","",SUMIFS(ERFASSUNG!$F$6:$F$3005,ERFASSUNG!$D$6:$D$3005,$A29,ERFASSUNG!$C$6:$C$3005,$B$3)) | E29: =IF($A29="","",SUMIFS(ERFASSUNG!$G$6:$G$3005,ERFASSUNG!$D$6:$D$3005,$A29,ERFASSUNG!$C$6:$C$3005,$B$3)) | F29: =IF($A29="","",SUMIFS(ERFASSUNG!$H$6:$H$3005,ERFASSUNG!$D$6:$D$3005,$A29,ERFASSUNG!$C$6:$C$3005,$B$3)) | G29: =IF($A29="","",SUMIFS(ERFASSUNG!$I$6:$I$3005,ERFASSUNG!$D$6:$D$3005,$A29,ERFASSUNG!$C$6:$C$3005,$B$3)) | H29: =IF($A29="","",SUMIFS(ERFASSUNG!$J$6:$J$3005,ERFASSUNG!$D$6:$D$3005,$A29,ERFASSUNG!$C$6:$C$3005,$B$3)) | I29: =IF($A29="","",SUMIFS(ERFASSUNG!$K$6:$K$3005,ERFASSUNG!$D$6:$D$3005,$A29,ERFASSUNG!$C$6:$C$3005,$B$3)) | J29: =IF($A29="","",SUMIFS(ERFASSUNG!$L$6:$L$3005,ERFASSUNG!$D$6:$D$3005,$A29,ERFASSUNG!$C$6:$C$3005,$B$3)) | K29: =IF($A29="","",SUMIFS(ERFASSUNG!$M$6:$M$3005,ERFASSUNG!$D$6:$D$3005,$A29,ERFASSUNG!$C$6:$C$3005,$B$3)) | L29: =IF($A29="","",SUMIFS(ERFASSUNG!$N$6:$N$3005,ERFASSUNG!$D$6:$D$3005,$A29,ERFASSUNG!$C$6:$C$3005,$B$3)) | M29: =IF(OR($A29="",N($G$51)=0),"",G29/$G$51)
A30: =IF(LISTEN!$A$11="","",LISTEN!$A$11) | B30: =IF($A30="","",COUNTIFS(ERFASSUNG!$D$6:$D$3005,$A30,ERFASSUNG!$C$6:$C$3005,$B$3)) | C30: =IF($A30="","",SUMIFS(ERFASSUNG!$E$6:$E$3005,ERFASSUNG!$D$6:$D$3005,$A30,ERFASSUNG!$C$6:$C$3005,$B$3)) | D30: =IF($A30="","",SUMIFS(ERFASSUNG!$F$6:$F$3005,ERFASSUNG!$D$6:$D$3005,$A30,ERFASSUNG!$C$6:$C$3005,$B$3)) | E30: =IF($A30="","",SUMIFS(ERFASSUNG!$G$6:$G$3005,ERFASSUNG!$D$6:$D$3005,$A30,ERFASSUNG!$C$6:$C$3005,$B$3)) | F30: =IF($A30="","",SUMIFS(ERFASSUNG!$H$6:$H$3005,ERFASSUNG!$D$6:$D$3005,$A30,ERFASSUNG!$C$6:$C$3005,$B$3)) | G30: =IF($A30="","",SUMIFS(ERFASSUNG!$I$6:$I$3005,ERFASSUNG!$D$6:$D$3005,$A30,ERFASSUNG!$C$6:$C$3005,$B$3)) | H30: =IF($A30="","",SUMIFS(ERFASSUNG!$J$6:$J$3005,ERFASSUNG!$D$6:$D$3005,$A30,ERFASSUNG!$C$6:$C$3005,$B$3)) | I30: =IF($A30="","",SUMIFS(ERFASSUNG!$K$6:$K$3005,ERFASSUNG!$D$6:$D$3005,$A30,ERFASSUNG!$C$6:$C$3005,$B$3)) | J30: =IF($A30="","",SUMIFS(ERFASSUNG!$L$6:$L$3005,ERFASSUNG!$D$6:$D$3005,$A30,ERFASSUNG!$C$6:$C$3005,$B$3)) | K30: =IF($A30="","",SUMIFS(ERFASSUNG!$M$6:$M$3005,ERFASSUNG!$D$6:$D$3005,$A30,ERFASSUNG!$C$6:$C$3005,$B$3)) | L30: =IF($A30="","",SUMIFS(ERFASSUNG!$N$6:$N$3005,ERFASSUNG!$D$6:$D$3005,$A30,ERFASSUNG!$C$6:$C$3005,$B$3)) | M30: =IF(OR($A30="",N($G$51)=0),"",G30/$G$51)
A31: =IF(LISTEN!$A$12="","",LISTEN!$A$12) | B31: =IF($A31="","",COUNTIFS(ERFASSUNG!$D$6:$D$3005,$A31,ERFASSUNG!$C$6:$C$3005,$B$3)) | C31: =IF($A31="","",SUMIFS(ERFASSUNG!$E$6:$E$3005,ERFASSUNG!$D$6:$D$3005,$A31,ERFASSUNG!$C$6:$C$3005,$B$3)) | D31: =IF($A31="","",SUMIFS(ERFASSUNG!$F$6:$F$3005,ERFASSUNG!$D$6:$D$3005,$A31,ERFASSUNG!$C$6:$C$3005,$B$3)) | E31: =IF($A31="","",SUMIFS(ERFASSUNG!$G$6:$G$3005,ERFASSUNG!$D$6:$D$3005,$A31,ERFASSUNG!$C$6:$C$3005,$B$3)) | F31: =IF($A31="","",SUMIFS(ERFASSUNG!$H$6:$H$3005,ERFASSUNG!$D$6:$D$3005,$A31,ERFASSUNG!$C$6:$C$3005,$B$3)) | G31: =IF($A31="","",SUMIFS(ERFASSUNG!$I$6:$I$3005,ERFASSUNG!$D$6:$D$3005,$A31,ERFASSUNG!$C$6:$C$3005,$B$3)) | H31: =IF($A31="","",SUMIFS(ERFASSUNG!$J$6:$J$3005,ERFASSUNG!$D$6:$D$3005,$A31,ERFASSUNG!$C$6:$C$3005,$B$3)) | I31: =IF($A31="","",SUMIFS(ERFASSUNG!$K$6:$K$3005,ERFASSUNG!$D$6:$D$3005,$A31,ERFASSUNG!$C$6:$C$3005,$B$3)) | J31: =IF($A31="","",SUMIFS(ERFASSUNG!$L$6:$L$3005,ERFASSUNG!$D$6:$D$3005,$A31,ERFASSUNG!$C$6:$C$3005,$B$3)) | K31: =IF($A31="","",SUMIFS(ERFASSUNG!$M$6:$M$3005,ERFASSUNG!$D$6:$D$3005,$A31,ERFASSUNG!$C$6:$C$3005,$B$3)) | L31: =IF($A31="","",SUMIFS(ERFASSUNG!$N$6:$N$3005,ERFASSUNG!$D$6:$D$3005,$A31,ERFASSUNG!$C$6:$C$3005,$B$3)) | M31: =IF(OR($A31="",N($G$51)=0),"",G31/$G$51)
A32: =IF(LISTEN!$A$13="","",LISTEN!$A$13) | B32: =IF($A32="","",COUNTIFS(ERFASSUNG!$D$6:$D$3005,$A32,ERFASSUNG!$C$6:$C$3005,$B$3)) | C32: =IF($A32="","",SUMIFS(ERFASSUNG!$E$6:$E$3005,ERFASSUNG!$D$6:$D$3005,$A32,ERFASSUNG!$C$6:$C$3005,$B$3)) | D32: =IF($A32="","",SUMIFS(ERFASSUNG!$F$6:$F$3005,ERFASSUNG!$D$6:$D$3005,$A32,ERFASSUNG!$C$6:$C$3005,$B$3)) | E32: =IF($A32="","",SUMIFS(ERFASSUNG!$G$6:$G$3005,ERFASSUNG!$D$6:$D$3005,$A32,ERFASSUNG!$C$6:$C$3005,$B$3)) | F32: =IF($A32="","",SUMIFS(ERFASSUNG!$H$6:$H$3005,ERFASSUNG!$D$6:$D$3005,$A32,ERFASSUNG!$C$6:$C$3005,$B$3)) | G32: =IF($A32="","",SUMIFS(ERFASSUNG!$I$6:$I$3005,ERFASSUNG!$D$6:$D$3005,$A32,ERFASSUNG!$C$6:$C$3005,$B$3)) | H32: =IF($A32="","",SUMIFS(ERFASSUNG!$J$6:$J$3005,ERFASSUNG!$D$6:$D$3005,$A32,ERFASSUNG!$C$6:$C$3005,$B$3)) | I32: =IF($A32="","",SUMIFS(ERFASSUNG!$K$6:$K$3005,ERFASSUNG!$D$6:$D$3005,$A32,ERFASSUNG!$C$6:$C$3005,$B$3)) | J32: =IF($A32="","",SUMIFS(ERFASSUNG!$L$6:$L$3005,ERFASSUNG!$D$6:$D$3005,$A32,ERFASSUNG!$C$6:$C$3005,$B$3)) | K32: =IF($A32="","",SUMIFS(ERFASSUNG!$M$6:$M$3005,ERFASSUNG!$D$6:$D$3005,$A32,ERFASSUNG!$C$6:$C$3005,$B$3)) | L32: =IF($A32="","",SUMIFS(ERFASSUNG!$N$6:$N$3005,ERFASSUNG!$D$6:$D$3005,$A32,ERFASSUNG!$C$6:$C$3005,$B$3)) | M32: =IF(OR($A32="",N($G$51)=0),"",G32/$G$51)
A33: =IF(LISTEN!$A$14="","",LISTEN!$A$14) | B33: =IF($A33="","",COUNTIFS(ERFASSUNG!$D$6:$D$3005,$A33,ERFASSUNG!$C$6:$C$3005,$B$3)) | C33: =IF($A33="","",SUMIFS(ERFASSUNG!$E$6:$E$3005,ERFASSUNG!$D$6:$D$3005,$A33,ERFASSUNG!$C$6:$C$3005,$B$3)) | D33: =IF($A33="","",SUMIFS(ERFASSUNG!$F$6:$F$3005,ERFASSUNG!$D$6:$D$3005,$A33,ERFASSUNG!$C$6:$C$3005,$B$3)) | E33: =IF($A33="","",SUMIFS(ERFASSUNG!$G$6:$G$3005,ERFASSUNG!$D$6:$D$3005,$A33,ERFASSUNG!$C$6:$C$3005,$B$3)) | F33: =IF($A33="","",SUMIFS(ERFASSUNG!$H$6:$H$3005,ERFASSUNG!$D$6:$D$3005,$A33,ERFASSUNG!$C$6:$C$3005,$B$3)) | G33: =IF($A33="","",SUMIFS(ERFASSUNG!$I$6:$I$3005,ERFASSUNG!$D$6:$D$3005,$A33,ERFASSUNG!$C$6:$C$3005,$B$3)) | H33: =IF($A33="","",SUMIFS(ERFASSUNG!$J$6:$J$3005,ERFASSUNG!$D$6:$D$3005,$A33,ERFASSUNG!$C$6:$C$3005,$B$3)) | I33: =IF($A33="","",SUMIFS(ERFASSUNG!$K$6:$K$3005,ERFASSUNG!$D$6:$D$3005,$A33,ERFASSUNG!$C$6:$C$3005,$B$3)) | J33: =IF($A33="","",SUMIFS(ERFASSUNG!$L$6:$L$3005,ERFASSUNG!$D$6:$D$3005,$A33,ERFASSUNG!$C$6:$C$3005,$B$3)) | K33: =IF($A33="","",SUMIFS(ERFASSUNG!$M$6:$M$3005,ERFASSUNG!$D$6:$D$3005,$A33,ERFASSUNG!$C$6:$C$3005,$B$3)) | L33: =IF($A33="","",SUMIFS(ERFASSUNG!$N$6:$N$3005,ERFASSUNG!$D$6:$D$3005,$A33,ERFASSUNG!$C$6:$C$3005,$B$3)) | M33: =IF(OR($A33="",N($G$51)=0),"",G33/$G$51)
A34: =IF(LISTEN!$A$15="","",LISTEN!$A$15) | B34: =IF($A34="","",COUNTIFS(ERFASSUNG!$D$6:$D$3005,$A34,ERFASSUNG!$C$6:$C$3005,$B$3)) | C34: =IF($A34="","",SUMIFS(ERFASSUNG!$E$6:$E$3005,ERFASSUNG!$D$6:$D$3005,$A34,ERFASSUNG!$C$6:$C$3005,$B$3)) | D34: =IF($A34="","",SUMIFS(ERFASSUNG!$F$6:$F$3005,ERFASSUNG!$D$6:$D$3005,$A34,ERFASSUNG!$C$6:$C$3005,$B$3)) | E34: =IF($A34="","",SUMIFS(ERFASSUNG!$G$6:$G$3005,ERFASSUNG!$D$6:$D$3005,$A34,ERFASSUNG!$C$6:$C$3005,$B$3)) | F34: =IF($A34="","",SUMIFS(ERFASSUNG!$H$6:$H$3005,ERFASSUNG!$D$6:$D$3005,$A34,ERFASSUNG!$C$6:$C$3005,$B$3)) | G34: =IF($A34="","",SUMIFS(ERFASSUNG!$I$6:$I$3005,ERFASSUNG!$D$6:$D$3005,$A34,ERFASSUNG!$C$6:$C$3005,$B$3)) | H34: =IF($A34="","",SUMIFS(ERFASSUNG!$J$6:$J$3005,ERFASSUNG!$D$6:$D$3005,$A34,ERFASSUNG!$C$6:$C$3005,$B$3)) | I34: =IF($A34="","",SUMIFS(ERFASSUNG!$K$6:$K$3005,ERFASSUNG!$D$6:$D$3005,$A34,ERFASSUNG!$C$6:$C$3005,$B$3)) | J34: =IF($A34="","",SUMIFS(ERFASSUNG!$L$6:$L$3005,ERFASSUNG!$D$6:$D$3005,$A34,ERFASSUNG!$C$6:$C$3005,$B$3)) | K34: =IF($A34="","",SUMIFS(ERFASSUNG!$M$6:$M$3005,ERFASSUNG!$D$6:$D$3005,$A34,ERFASSUNG!$C$6:$C$3005,$B$3)) | L34: =IF($A34="","",SUMIFS(ERFASSUNG!$N$6:$N$3005,ERFASSUNG!$D$6:$D$3005,$A34,ERFASSUNG!$C$6:$C$3005,$B$3)) | M34: =IF(OR($A34="",N($G$51)=0),"",G34/$G$51)
A35: =IF(LISTEN!$A$16="","",LISTEN!$A$16) | B35: =IF($A35="","",COUNTIFS(ERFASSUNG!$D$6:$D$3005,$A35,ERFASSUNG!$C$6:$C$3005,$B$3)) | C35: =IF($A35="","",SUMIFS(ERFASSUNG!$E$6:$E$3005,ERFASSUNG!$D$6:$D$3005,$A35,ERFASSUNG!$C$6:$C$3005,$B$3)) | D35: =IF($A35="","",SUMIFS(ERFASSUNG!$F$6:$F$3005,ERFASSUNG!$D$6:$D$3005,$A35,ERFASSUNG!$C$6:$C$3005,$B$3)) | E35: =IF($A35="","",SUMIFS(ERFASSUNG!$G$6:$G$3005,ERFASSUNG!$D$6:$D$3005,$A35,ERFASSUNG!$C$6:$C$3005,$B$3)) | F35: =IF($A35="","",SUMIFS(ERFASSUNG!$H$6:$H$3005,ERFASSUNG!$D$6:$D$3005,$A35,ERFASSUNG!$C$6:$C$3005,$B$3)) | G35: =IF($A35="","",SUMIFS(ERFASSUNG!$I$6:$I$3005,ERFASSUNG!$D$6:$D$3005,$A35,ERFASSUNG!$C$6:$C$3005,$B$3)) | H35: =IF($A35="","",SUMIFS(ERFASSUNG!$J$6:$J$3005,ERFASSUNG!$D$6:$D$3005,$A35,ERFASSUNG!$C$6:$C$3005,$B$3)) | I35: =IF($A35="","",SUMIFS(ERFASSUNG!$K$6:$K$3005,ERFASSUNG!$D$6:$D$3005,$A35,ERFASSUNG!$C$6:$C$3005,$B$3)) | J35: =IF($A35="","",SUMIFS(ERFASSUNG!$L$6:$L$3005,ERFASSUNG!$D$6:$D$3005,$A35,ERFASSUNG!$C$6:$C$3005,$B$3)) | K35: =IF($A35="","",SUMIFS(ERFASSUNG!$M$6:$M$3005,ERFASSUNG!$D$6:$D$3005,$A35,ERFASSUNG!$C$6:$C$3005,$B$3)) | L35: =IF($A35="","",SUMIFS(ERFASSUNG!$N$6:$N$3005,ERFASSUNG!$D$6:$D$3005,$A35,ERFASSUNG!$C$6:$C$3005,$B$3)) | M35: =IF(OR($A35="",N($G$51)=0),"",G35/$G$51)
A36: =IF(LISTEN!$A$17="","",LISTEN!$A$17) | B36: =IF($A36="","",COUNTIFS(ERFASSUNG!$D$6:$D$3005,$A36,ERFASSUNG!$C$6:$C$3005,$B$3)) | C36: =IF($A36="","",SUMIFS(ERFASSUNG!$E$6:$E$3005,ERFASSUNG!$D$6:$D$3005,$A36,ERFASSUNG!$C$6:$C$3005,$B$3)) | D36: =IF($A36="","",SUMIFS(ERFASSUNG!$F$6:$F$3005,ERFASSUNG!$D$6:$D$3005,$A36,ERFASSUNG!$C$6:$C$3005,$B$3)) | E36: =IF($A36="","",SUMIFS(ERFASSUNG!$G$6:$G$3005,ERFASSUNG!$D$6:$D$3005,$A36,ERFASSUNG!$C$6:$C$3005,$B$3)) | F36: =IF($A36="","",SUMIFS(ERFASSUNG!$H$6:$H$3005,ERFASSUNG!$D$6:$D$3005,$A36,ERFASSUNG!$C$6:$C$3005,$B$3)) | G36: =IF($A36="","",SUMIFS(ERFASSUNG!$I$6:$I$3005,ERFASSUNG!$D$6:$D$3005,$A36,ERFASSUNG!$C$6:$C$3005,$B$3)) | H36: =IF($A36="","",SUMIFS(ERFASSUNG!$J$6:$J$3005,ERFASSUNG!$D$6:$D$3005,$A36,ERFASSUNG!$C$6:$C$3005,$B$3)) | I36: =IF($A36="","",SUMIFS(ERFASSUNG!$K$6:$K$3005,ERFASSUNG!$D$6:$D$3005,$A36,ERFASSUNG!$C$6:$C$3005,$B$3)) | J36: =IF($A36="","",SUMIFS(ERFASSUNG!$L$6:$L$3005,ERFASSUNG!$D$6:$D$3005,$A36,ERFASSUNG!$C$6:$C$3005,$B$3)) | K36: =IF($A36="","",SUMIFS(ERFASSUNG!$M$6:$M$3005,ERFASSUNG!$D$6:$D$3005,$A36,ERFASSUNG!$C$6:$C$3005,$B$3)) | L36: =IF($A36="","",SUMIFS(ERFASSUNG!$N$6:$N$3005,ERFASSUNG!$D$6:$D$3005,$A36,ERFASSUNG!$C$6:$C$3005,$B$3)) | M36: =IF(OR($A36="",N($G$51)=0),"",G36/$G$51)
A37: =IF(LISTEN!$A$18="","",LISTEN!$A$18) | B37: =IF($A37="","",COUNTIFS(ERFASSUNG!$D$6:$D$3005,$A37,ERFASSUNG!$C$6:$C$3005,$B$3)) | C37: =IF($A37="","",SUMIFS(ERFASSUNG!$E$6:$E$3005,ERFASSUNG!$D$6:$D$3005,$A37,ERFASSUNG!$C$6:$C$3005,$B$3)) | D37: =IF($A37="","",SUMIFS(ERFASSUNG!$F$6:$F$3005,ERFASSUNG!$D$6:$D$3005,$A37,ERFASSUNG!$C$6:$C$3005,$B$3)) | E37: =IF($A37="","",SUMIFS(ERFASSUNG!$G$6:$G$3005,ERFASSUNG!$D$6:$D$3005,$A37,ERFASSUNG!$C$6:$C$3005,$B$3)) | F37: =IF($A37="","",SUMIFS(ERFASSUNG!$H$6:$H$3005,ERFASSUNG!$D$6:$D$3005,$A37,ERFASSUNG!$C$6:$C$3005,$B$3)) | G37: =IF($A37="","",SUMIFS(ERFASSUNG!$I$6:$I$3005,ERFASSUNG!$D$6:$D$3005,$A37,ERFASSUNG!$C$6:$C$3005,$B$3)) | H37: =IF($A37="","",SUMIFS(ERFASSUNG!$J$6:$J$3005,ERFASSUNG!$D$6:$D$3005,$A37,ERFASSUNG!$C$6:$C$3005,$B$3)) | I37: =IF($A37="","",SUMIFS(ERFASSUNG!$K$6:$K$3005,ERFASSUNG!$D$6:$D$3005,$A37,ERFASSUNG!$C$6:$C$3005,$B$3)) | J37: =IF($A37="","",SUMIFS(ERFASSUNG!$L$6:$L$3005,ERFASSUNG!$D$6:$D$3005,$A37,ERFASSUNG!$C$6:$C$3005,$B$3)) | K37: =IF($A37="","",SUMIFS(ERFASSUNG!$M$6:$M$3005,ERFASSUNG!$D$6:$D$3005,$A37,ERFASSUNG!$C$6:$C$3005,$B$3)) | L37: =IF($A37="","",SUMIFS(ERFASSUNG!$N$6:$N$3005,ERFASSUNG!$D$6:$D$3005,$A37,ERFASSUNG!$C$6:$C$3005,$B$3)) | M37: =IF(OR($A37="",N($G$51)=0),"",G37/$G$51)
A38: =IF(LISTEN!$A$19="","",LISTEN!$A$19) | B38: =IF($A38="","",COUNTIFS(ERFASSUNG!$D$6:$D$3005,$A38,ERFASSUNG!$C$6:$C$3005,$B$3)) | C38: =IF($A38="","",SUMIFS(ERFASSUNG!$E$6:$E$3005,ERFASSUNG!$D$6:$D$3005,$A38,ERFASSUNG!$C$6:$C$3005,$B$3)) | D38: =IF($A38="","",SUMIFS(ERFASSUNG!$F$6:$F$3005,ERFASSUNG!$D$6:$D$3005,$A38,ERFASSUNG!$C$6:$C$3005,$B$3)) | E38: =IF($A38="","",SUMIFS(ERFASSUNG!$G$6:$G$3005,ERFASSUNG!$D$6:$D$3005,$A38,ERFASSUNG!$C$6:$C$3005,$B$3)) | F38: =IF($A38="","",SUMIFS(ERFASSUNG!$H$6:$H$3005,ERFASSUNG!$D$6:$D$3005,$A38,ERFASSUNG!$C$6:$C$3005,$B$3)) | G38: =IF($A38="","",SUMIFS(ERFASSUNG!$I$6:$I$3005,ERFASSUNG!$D$6:$D$3005,$A38,ERFASSUNG!$C$6:$C$3005,$B$3)) | H38: =IF($A38="","",SUMIFS(ERFASSUNG!$J$6:$J$3005,ERFASSUNG!$D$6:$D$3005,$A38,ERFASSUNG!$C$6:$C$3005,$B$3)) | I38: =IF($A38="","",SUMIFS(ERFASSUNG!$K$6:$K$3005,ERFASSUNG!$D$6:$D$3005,$A38,ERFASSUNG!$C$6:$C$3005,$B$3)) | J38: =IF($A38="","",SUMIFS(ERFASSUNG!$L$6:$L$3005,ERFASSUNG!$D$6:$D$3005,$A38,ERFASSUNG!$C$6:$C$3005,$B$3)) | K38: =IF($A38="","",SUMIFS(ERFASSUNG!$M$6:$M$3005,ERFASSUNG!$D$6:$D$3005,$A38,ERFASSUNG!$C$6:$C$3005,$B$3)) | L38: =IF($A38="","",SUMIFS(ERFASSUNG!$N$6:$N$3005,ERFASSUNG!$D$6:$D$3005,$A38,ERFASSUNG!$C$6:$C$3005,$B$3)) | M38: =IF(OR($A38="",N($G$51)=0),"",G38/$G$51)
A39: =IF(LISTEN!$A$20="","",LISTEN!$A$20) | B39: =IF($A39="","",COUNTIFS(ERFASSUNG!$D$6:$D$3005,$A39,ERFASSUNG!$C$6:$C$3005,$B$3)) | C39: =IF($A39="","",SUMIFS(ERFASSUNG!$E$6:$E$3005,ERFASSUNG!$D$6:$D$3005,$A39,ERFASSUNG!$C$6:$C$3005,$B$3)) | D39: =IF($A39="","",SUMIFS(ERFASSUNG!$F$6:$F$3005,ERFASSUNG!$D$6:$D$3005,$A39,ERFASSUNG!$C$6:$C$3005,$B$3)) | E39: =IF($A39="","",SUMIFS(ERFASSUNG!$G$6:$G$3005,ERFASSUNG!$D$6:$D$3005,$A39,ERFASSUNG!$C$6:$C$3005,$B$3)) | F39: =IF($A39="","",SUMIFS(ERFASSUNG!$H$6:$H$3005,ERFASSUNG!$D$6:$D$3005,$A39,ERFASSUNG!$C$6:$C$3005,$B$3)) | G39: =IF($A39="","",SUMIFS(ERFASSUNG!$I$6:$I$3005,ERFASSUNG!$D$6:$D$3005,$A39,ERFASSUNG!$C$6:$C$3005,$B$3)) | H39: =IF($A39="","",SUMIFS(ERFASSUNG!$J$6:$J$3005,ERFASSUNG!$D$6:$D$3005,$A39,ERFASSUNG!$C$6:$C$3005,$B$3)) | I39: =IF($A39="","",SUMIFS(ERFASSUNG!$K$6:$K$3005,ERFASSUNG!$D$6:$D$3005,$A39,ERFASSUNG!$C$6:$C$3005,$B$3)) | J39: =IF($A39="","",SUMIFS(ERFASSUNG!$L$6:$L$3005,ERFASSUNG!$D$6:$D$3005,$A39,ERFASSUNG!$C$6:$C$3005,$B$3)) | K39: =IF($A39="","",SUMIFS(ERFASSUNG!$M$6:$M$3005,ERFASSUNG!$D$6:$D$3005,$A39,ERFASSUNG!$C$6:$C$3005,$B$3)) | L39: =IF($A39="","",SUMIFS(ERFASSUNG!$N$6:$N$3005,ERFASSUNG!$D$6:$D$3005,$A39,ERFASSUNG!$C$6:$C$3005,$B$3)) | M39: =IF(OR($A39="",N($G$51)=0),"",G39/$G$51)
A40: =IF(LISTEN!$A$21="","",LISTEN!$A$21) | B40: =IF($A40="","",COUNTIFS(ERFASSUNG!$D$6:$D$3005,$A40,ERFASSUNG!$C$6:$C$3005,$B$3)) | C40: =IF($A40="","",SUMIFS(ERFASSUNG!$E$6:$E$3005,ERFASSUNG!$D$6:$D$3005,$A40,ERFASSUNG!$C$6:$C$3005,$B$3)) | D40: =IF($A40="","",SUMIFS(ERFASSUNG!$F$6:$F$3005,ERFASSUNG!$D$6:$D$3005,$A40,ERFASSUNG!$C$6:$C$3005,$B$3)) | E40: =IF($A40="","",SUMIFS(ERFASSUNG!$G$6:$G$3005,ERFASSUNG!$D$6:$D$3005,$A40,ERFASSUNG!$C$6:$C$3005,$B$3)) | F40: =IF($A40="","",SUMIFS(ERFASSUNG!$H$6:$H$3005,ERFASSUNG!$D$6:$D$3005,$A40,ERFASSUNG!$C$6:$C$3005,$B$3)) | G40: =IF($A40="","",SUMIFS(ERFASSUNG!$I$6:$I$3005,ERFASSUNG!$D$6:$D$3005,$A40,ERFASSUNG!$C$6:$C$3005,$B$3)) | H40: =IF($A40="","",SUMIFS(ERFASSUNG!$J$6:$J$3005,ERFASSUNG!$D$6:$D$3005,$A40,ERFASSUNG!$C$6:$C$3005,$B$3)) | I40: =IF($A40="","",SUMIFS(ERFASSUNG!$K$6:$K$3005,ERFASSUNG!$D$6:$D$3005,$A40,ERFASSUNG!$C$6:$C$3005,$B$3)) | J40: =IF($A40="","",SUMIFS(ERFASSUNG!$L$6:$L$3005,ERFASSUNG!$D$6:$D$3005,$A40,ERFASSUNG!$C$6:$C$3005,$B$3)) | K40: =IF($A40="","",SUMIFS(ERFASSUNG!$M$6:$M$3005,ERFASSUNG!$D$6:$D$3005,$A40,ERFASSUNG!$C$6:$C$3005,$B$3)) | L40: =IF($A40="","",SUMIFS(ERFASSUNG!$N$6:$N$3005,ERFASSUNG!$D$6:$D$3005,$A40,ERFASSUNG!$C$6:$C$3005,$B$3)) | M40: =IF(OR($A40="",N($G$51)=0),"",G40/$G$51)
A41: =IF(LISTEN!$A$22="","",LISTEN!$A$22) | B41: =IF($A41="","",COUNTIFS(ERFASSUNG!$D$6:$D$3005,$A41,ERFASSUNG!$C$6:$C$3005,$B$3)) | C41: =IF($A41="","",SUMIFS(ERFASSUNG!$E$6:$E$3005,ERFASSUNG!$D$6:$D$3005,$A41,ERFASSUNG!$C$6:$C$3005,$B$3)) | D41: =IF($A41="","",SUMIFS(ERFASSUNG!$F$6:$F$3005,ERFASSUNG!$D$6:$D$3005,$A41,ERFASSUNG!$C$6:$C$3005,$B$3)) | E41: =IF($A41="","",SUMIFS(ERFASSUNG!$G$6:$G$3005,ERFASSUNG!$D$6:$D$3005,$A41,ERFASSUNG!$C$6:$C$3005,$B$3)) | F41: =IF($A41="","",SUMIFS(ERFASSUNG!$H$6:$H$3005,ERFASSUNG!$D$6:$D$3005,$A41,ERFASSUNG!$C$6:$C$3005,$B$3)) | G41: =IF($A41="","",SUMIFS(ERFASSUNG!$I$6:$I$3005,ERFASSUNG!$D$6:$D$3005,$A41,ERFASSUNG!$C$6:$C$3005,$B$3)) | H41: =IF($A41="","",SUMIFS(ERFASSUNG!$J$6:$J$3005,ERFASSUNG!$D$6:$D$3005,$A41,ERFASSUNG!$C$6:$C$3005,$B$3)) | I41: =IF($A41="","",SUMIFS(ERFASSUNG!$K$6:$K$3005,ERFASSUNG!$D$6:$D$3005,$A41,ERFASSUNG!$C$6:$C$3005,$B$3)) | J41: =IF($A41="","",SUMIFS(ERFASSUNG!$L$6:$L$3005,ERFASSUNG!$D$6:$D$3005,$A41,ERFASSUNG!$C$6:$C$3005,$B$3)) | K41: =IF($A41="","",SUMIFS(ERFASSUNG!$M$6:$M$3005,ERFASSUNG!$D$6:$D$3005,$A41,ERFASSUNG!$C$6:$C$3005,$B$3)) | L41: =IF($A41="","",SUMIFS(ERFASSUNG!$N$6:$N$3005,ERFASSUNG!$D$6:$D$3005,$A41,ERFASSUNG!$C$6:$C$3005,$B$3)) | M41: =IF(OR($A41="",N($G$51)=0),"",G41/$G$51)
A42: =IF(LISTEN!$A$23="","",LISTEN!$A$23) | B42: =IF($A42="","",COUNTIFS(ERFASSUNG!$D$6:$D$3005,$A42,ERFASSUNG!$C$6:$C$3005,$B$3)) | C42: =IF($A42="","",SUMIFS(ERFASSUNG!$E$6:$E$3005,ERFASSUNG!$D$6:$D$3005,$A42,ERFASSUNG!$C$6:$C$3005,$B$3)) | D42: =IF($A42="","",SUMIFS(ERFASSUNG!$F$6:$F$3005,ERFASSUNG!$D$6:$D$3005,$A42,ERFASSUNG!$C$6:$C$3005,$B$3)) | E42: =IF($A42="","",SUMIFS(ERFASSUNG!$G$6:$G$3005,ERFASSUNG!$D$6:$D$3005,$A42,ERFASSUNG!$C$6:$C$3005,$B$3)) | F42: =IF($A42="","",SUMIFS(ERFASSUNG!$H$6:$H$3005,ERFASSUNG!$D$6:$D$3005,$A42,ERFASSUNG!$C$6:$C$3005,$B$3)) | G42: =IF($A42="","",SUMIFS(ERFASSUNG!$I$6:$I$3005,ERFASSUNG!$D$6:$D$3005,$A42,ERFASSUNG!$C$6:$C$3005,$B$3)) | H42: =IF($A42="","",SUMIFS(ERFASSUNG!$J$6:$J$3005,ERFASSUNG!$D$6:$D$3005,$A42,ERFASSUNG!$C$6:$C$3005,$B$3)) | I42: =IF($A42="","",SUMIFS(ERFASSUNG!$K$6:$K$3005,ERFASSUNG!$D$6:$D$3005,$A42,ERFASSUNG!$C$6:$C$3005,$B$3)) | J42: =IF($A42="","",SUMIFS(ERFASSUNG!$L$6:$L$3005,ERFASSUNG!$D$6:$D$3005,$A42,ERFASSUNG!$C$6:$C$3005,$B$3)) | K42: =IF($A42="","",SUMIFS(ERFASSUNG!$M$6:$M$3005,ERFASSUNG!$D$6:$D$3005,$A42,ERFASSUNG!$C$6:$C$3005,$B$3)) | L42: =IF($A42="","",SUMIFS(ERFASSUNG!$N$6:$N$3005,ERFASSUNG!$D$6:$D$3005,$A42,ERFASSUNG!$C$6:$C$3005,$B$3)) | M42: =IF(OR($A42="",N($G$51)=0),"",G42/$G$51)
A43: =IF(LISTEN!$A$24="","",LISTEN!$A$24) | B43: =IF($A43="","",COUNTIFS(ERFASSUNG!$D$6:$D$3005,$A43,ERFASSUNG!$C$6:$C$3005,$B$3)) | C43: =IF($A43="","",SUMIFS(ERFASSUNG!$E$6:$E$3005,ERFASSUNG!$D$6:$D$3005,$A43,ERFASSUNG!$C$6:$C$3005,$B$3)) | D43: =IF($A43="","",SUMIFS(ERFASSUNG!$F$6:$F$3005,ERFASSUNG!$D$6:$D$3005,$A43,ERFASSUNG!$C$6:$C$3005,$B$3)) | E43: =IF($A43="","",SUMIFS(ERFASSUNG!$G$6:$G$3005,ERFASSUNG!$D$6:$D$3005,$A43,ERFASSUNG!$C$6:$C$3005,$B$3)) | F43: =IF($A43="","",SUMIFS(ERFASSUNG!$H$6:$H$3005,ERFASSUNG!$D$6:$D$3005,$A43,ERFASSUNG!$C$6:$C$3005,$B$3)) | G43: =IF($A43="","",SUMIFS(ERFASSUNG!$I$6:$I$3005,ERFASSUNG!$D$6:$D$3005,$A43,ERFASSUNG!$C$6:$C$3005,$B$3)) | H43: =IF($A43="","",SUMIFS(ERFASSUNG!$J$6:$J$3005,ERFASSUNG!$D$6:$D$3005,$A43,ERFASSUNG!$C$6:$C$3005,$B$3)) | I43: =IF($A43="","",SUMIFS(ERFASSUNG!$K$6:$K$3005,ERFASSUNG!$D$6:$D$3005,$A43,ERFASSUNG!$C$6:$C$3005,$B$3)) | J43: =IF($A43="","",SUMIFS(ERFASSUNG!$L$6:$L$3005,ERFASSUNG!$D$6:$D$3005,$A43,ERFASSUNG!$C$6:$C$3005,$B$3)) | K43: =IF($A43="","",SUMIFS(ERFASSUNG!$M$6:$M$3005,ERFASSUNG!$D$6:$D$3005,$A43,ERFASSUNG!$C$6:$C$3005,$B$3)) | L43: =IF($A43="","",SUMIFS(ERFASSUNG!$N$6:$N$3005,ERFASSUNG!$D$6:$D$3005,$A43,ERFASSUNG!$C$6:$C$3005,$B$3)) | M43: =IF(OR($A43="",N($G$51)=0),"",G43/$G$51)
...

Sheet MONAT
A1: ="Monatsübersicht "&LISTEN!$F$3
A2: Monat in der gelben Zelle auswählen – alles andere rechnet automatisch.
A3: Monat: | B3: September | D3: von | E3: =DATE(LISTEN!$F$2,$AZ$3,1) | G3: bis | H3: =DATE(LISTEN!$F$2,$AZ$3+1,0) | AZ3: =IFERROR(MATCH($B$3,LISTEN!$H$2:$H$13,0),1)
A5: Öffnungstage | C5: Einträge (Angebote) | E5: Kontakte gesamt | G5: Ø Kontakte pro Öffnungstag | I5: Stunden | K5: weiblich | M5: divers | O5: männlich
A6: =SUMIFS(KALENDER!$G$5:$G$370,KALENDER!$D$5:$D$370,$AZ$3) | C6: =SUMIFS(KALENDER!$F$5:$F$370,KALENDER!$D$5:$D$370,$AZ$3) | E6: =($B$10+$C$10+$D$10) | G6: =IF(N(SUMIFS(KALENDER!$G$5:$G$370,KALENDER!$D$5:$D$370,$AZ$3))=0,0,($B$10+$C$10+$D$10)/SUMIFS(KALENDER!$G$5:$G$370,KALENDER!$D$5:$D$370,$AZ$3)) | I6: =SUMIFS(KALENDER!$H$5:$H$370,KALENDER!$D$5:$D$370,$AZ$3) | K6: =IF(($B$10+$C$10+$D$10)=0,0,$B$10/($B$10+$C$10+$D$10)) | M6: =IF(($B$10+$C$10+$D$10)=0,0,$C$10/($B$10+$C$10+$D$10)) | O6: =IF(($B$10+$C$10+$D$10)=0,0,$D$10/($B$10+$C$10+$D$10))
A8: Geschlecht & Alter
A9: Merkmal | B9: weiblich | C9: divers | D9: männlich | E9: unter 10 | F9: ab 10 | G9: ab 14 | H9: ab 16 | I9: ab 18
A10: Anzahl | B10: =SUMIFS(KALENDER!$I$5:$I$370,KALENDER!$D$5:$D$370,$AZ$3) | C10: =SUMIFS(KALENDER!$J$5:$J$370,KALENDER!$D$5:$D$370,$AZ$3) | D10: =SUMIFS(KALENDER!$K$5:$K$370,KALENDER!$D$5:$D$370,$AZ$3) | E10: =SUMIFS(KALENDER!$M$5:$M$370,KALENDER!$D$5:$D$370,$AZ$3) | F10: =SUMIFS(KALENDER!$N$5:$N$370,KALENDER!$D$5:$D$370,$AZ$3) | G10: =SUMIFS(KALENDER!$O$5:$O$370,KALENDER!$D$5:$D$370,$AZ$3) | H10: =SUMIFS(KALENDER!$P$5:$P$370,KALENDER!$D$5:$D$370,$AZ$3) | I10: =SUMIFS(KALENDER!$Q$5:$Q$370,KALENDER!$D$5:$D$370,$AZ$3)
A11: Anteil | B11: =IF(SUM($B$10:$D$10)=0,0,B10/SUM($B$10:$D$10)) | C11: =IF(SUM($B$10:$D$10)=0,0,C10/SUM($B$10:$D$10)) | D11: =IF(SUM($B$10:$D$10)=0,0,D10/SUM($B$10:$D$10)) | E11: =IF(SUM($E$10:$I$10)=0,0,E10/SUM($E$10:$I$10)) | F11: =IF(SUM($E$10:$I$10)=0,0,F10/SUM($E$10:$I$10)) | G11: =IF(SUM($E$10:$I$10)=0,0,G10/SUM($E$10:$I$10)) | H11: =IF(SUM($E$10:$I$10)=0,0,H10/SUM($E$10:$I$10)) | I11: =IF(SUM($E$10:$I$10)=0,0,I10/SUM($E$10:$I$10))
A13: Angebote im Monat
A14: Angebot | B14: Einträge | C14: Stunden | D14: w | E14: d | F14: m | G14: gesamt | H14: unter 10 | I14: ab 10 | J14: ab 14 | K14: ab 16 | L14: ab 18 | M14: Anteil
A15: =IF(LISTEN!$A$2="","",LISTEN!$A$2) | B15: =IF($A15="","",COUNTIFS(ERFASSUNG!$D$6:$D$3005,$A15,ERFASSUNG!$V$6:$V$3005,$AZ$3)) | C15: =IF($A15="","",SUMIFS(ERFASSUNG!$E$6:$E$3005,ERFASSUNG!$D$6:$D$3005,$A15,ERFASSUNG!$V$6:$V$3005,$AZ$3)) | D15: =IF($A15="","",SUMIFS(ERFASSUNG!$F$6:$F$3005,ERFASSUNG!$D$6:$D$3005,$A15,ERFASSUNG!$V$6:$V$3005,$AZ$3)) | E15: =IF($A15="","",SUMIFS(ERFASSUNG!$G$6:$G$3005,ERFASSUNG!$D$6:$D$3005,$A15,ERFASSUNG!$V$6:$V$3005,$AZ$3)) | F15: =IF($A15="","",SUMIFS(ERFASSUNG!$H$6:$H$3005,ERFASSUNG!$D$6:$D$3005,$A15,ERFASSUNG!$V$6:$V$3005,$AZ$3)) | G15: =IF($A15="","",SUMIFS(ERFASSUNG!$I$6:$I$3005,ERFASSUNG!$D$6:$D$3005,$A15,ERFASSUNG!$V$6:$V$3005,$AZ$3)) | H15: =IF($A15="","",SUMIFS(ERFASSUNG!$J$6:$J$3005,ERFASSUNG!$D$6:$D$3005,$A15,ERFASSUNG!$V$6:$V$3005,$AZ$3)) | I15: =IF($A15="","",SUMIFS(ERFASSUNG!$K$6:$K$3005,ERFASSUNG!$D$6:$D$3005,$A15,ERFASSUNG!$V$6:$V$3005,$AZ$3)) | J15: =IF($A15="","",SUMIFS(ERFASSUNG!$L$6:$L$3005,ERFASSUNG!$D$6:$D$3005,$A15,ERFASSUNG!$V$6:$V$3005,$AZ$3)) | K15: =IF($A15="","",SUMIFS(ERFASSUNG!$M$6:$M$3005,ERFASSUNG!$D$6:$D$3005,$A15,ERFASSUNG!$V$6:$V$3005,$AZ$3)) | L15: =IF($A15="","",SUMIFS(ERFASSUNG!$N$6:$N$3005,ERFASSUNG!$D$6:$D$3005,$A15,ERFASSUNG!$V$6:$V$3005,$AZ$3)) | M15: =IF(OR($A15="",N($G$45)=0),"",G15/$G$45)
A16: =IF(LISTEN!$A$3="","",LISTEN!$A$3) | B16: =IF($A16="","",COUNTIFS(ERFASSUNG!$D$6:$D$3005,$A16,ERFASSUNG!$V$6:$V$3005,$AZ$3)) | C16: =IF($A16="","",SUMIFS(ERFASSUNG!$E$6:$E$3005,ERFASSUNG!$D$6:$D$3005,$A16,ERFASSUNG!$V$6:$V$3005,$AZ$3)) | D16: =IF($A16="","",SUMIFS(ERFASSUNG!$F$6:$F$3005,ERFASSUNG!$D$6:$D$3005,$A16,ERFASSUNG!$V$6:$V$3005,$AZ$3)) | E16: =IF($A16="","",SUMIFS(ERFASSUNG!$G$6:$G$3005,ERFASSUNG!$D$6:$D$3005,$A16,ERFASSUNG!$V$6:$V$3005,$AZ$3)) | F16: =IF($A16="","",SUMIFS(ERFASSUNG!$H$6:$H$3005,ERFASSUNG!$D$6:$D$3005,$A16,ERFASSUNG!$V$6:$V$3005,$AZ$3)) | G16: =IF($A16="","",SUMIFS(ERFASSUNG!$I$6:$I$3005,ERFASSUNG!$D$6:$D$3005,$A16,ERFASSUNG!$V$6:$V$3005,$AZ$3)) | H16: =IF($A16="","",SUMIFS(ERFASSUNG!$J$6:$J$3005,ERFASSUNG!$D$6:$D$3005,$A16,ERFASSUNG!$V$6:$V$3005,$AZ$3)) | I16: =IF($A16="","",SUMIFS(ERFASSUNG!$K$6:$K$3005,ERFASSUNG!$D$6:$D$3005,$A16,ERFASSUNG!$V$6:$V$3005,$AZ$3)) | J16: =IF($A16="","",SUMIFS(ERFASSUNG!$L$6:$L$3005,ERFASSUNG!$D$6:$D$3005,$A16,ERFASSUNG!$V$6:$V$3005,$AZ$3)) | K16: =IF($A16="","",SUMIFS(ERFASSUNG!$M$6:$M$3005,ERFASSUNG!$D$6:$D$3005,$A16,ERFASSUNG!$V$6:$V$3005,$AZ$3)) | L16: =IF($A16="","",SUMIFS(ERFASSUNG!$N$6:$N$3005,ERFASSUNG!$D$6:$D$3005,$A16,ERFASSUNG!$V$6:$V$3005,$AZ$3)) | M16: =IF(OR($A16="",N($G$45)=0),"",G16/$G$45)
A17: =IF(LISTEN!$A$4="","",LISTEN!$A$4) | B17: =IF($A17="","",COUNTIFS(ERFASSUNG!$D$6:$D$3005,$A17,ERFASSUNG!$V$6:$V$3005,$AZ$3)) | C17: =IF($A17="","",SUMIFS(ERFASSUNG!$E$6:$E$3005,ERFASSUNG!$D$6:$D$3005,$A17,ERFASSUNG!$V$6:$V$3005,$AZ$3)) | D17: =IF($A17="","",SUMIFS(ERFASSUNG!$F$6:$F$3005,ERFASSUNG!$D$6:$D$3005,$A17,ERFASSUNG!$V$6:$V$3005,$AZ$3)) | E17: =IF($A17="","",SUMIFS(ERFASSUNG!$G$6:$G$3005,ERFASSUNG!$D$6:$D$3005,$A17,ERFASSUNG!$V$6:$V$3005,$AZ$3)) | F17: =IF($A17="","",SUMIFS(ERFASSUNG!$H$6:$H$3005,ERFASSUNG!$D$6:$D$3005,$A17,ERFASSUNG!$V$6:$V$3005,$AZ$3)) | G17: =IF($A17="","",SUMIFS(ERFASSUNG!$I$6:$I$3005,ERFASSUNG!$D$6:$D$3005,$A17,ERFASSUNG!$V$6:$V$3005,$AZ$3)) | H17: =IF($A17="","",SUMIFS(ERFASSUNG!$J$6:$J$3005,ERFASSUNG!$D$6:$D$3005,$A17,ERFASSUNG!$V$6:$V$3005,$AZ$3)) | I17: =IF($A17="","",SUMIFS(ERFASSUNG!$K$6:$K$3005,ERFASSUNG!$D$6:$D$3005,$A17,ERFASSUNG!$V$6:$V$3005,$AZ$3)) | J17: =IF($A17="","",SUMIFS(ERFASSUNG!$L$6:$L$3005,ERFASSUNG!$D$6:$D$3005,$A17,ERFASSUNG!$V$6:$V$3005,$AZ$3)) | K17: =IF($A17="","",SUMIFS(ERFASSUNG!$M$6:$M$3005,ERFASSUNG!$D$6:$D$3005,$A17,ERFASSUNG!$V$6:$V$3005,$AZ$3)) | L17: =IF($A17="","",SUMIFS(ERFASSUNG!$N$6:$N$3005,ERFASSUNG!$D$6:$D$3005,$A17,ERFASSUNG!$V$6:$V$3005,$AZ$3)) | M17: =IF(OR($A17="",N($G$45)=0),"",G17/$G$45)
A18: =IF(LISTEN!$A$5="","",LISTEN!$A$5) | B18: =IF($A18="","",COUNTIFS(ERFASSUNG!$D$6:$D$3005,$A18,ERFASSUNG!$V$6:$V$3005,$AZ$3)) | C18: =IF($A18="","",SUMIFS(ERFASSUNG!$E$6:$E$3005,ERFASSUNG!$D$6:$D$3005,$A18,ERFASSUNG!$V$6:$V$3005,$AZ$3)) | D18: =IF($A18="","",SUMIFS(ERFASSUNG!$F$6:$F$3005,ERFASSUNG!$D$6:$D$3005,$A18,ERFASSUNG!$V$6:$V$3005,$AZ$3)) | E18: =IF($A18="","",SUMIFS(ERFASSUNG!$G$6:$G$3005,ERFASSUNG!$D$6:$D$3005,$A18,ERFASSUNG!$V$6:$V$3005,$AZ$3)) | F18: =IF($A18="","",SUMIFS(ERFASSUNG!$H$6:$H$3005,ERFASSUNG!$D$6:$D$3005,$A18,ERFASSUNG!$V$6:$V$3005,$AZ$3)) | G18: =IF($A18="","",SUMIFS(ERFASSUNG!$I$6:$I$3005,ERFASSUNG!$D$6:$D$3005,$A18,ERFASSUNG!$V$6:$V$3005,$AZ$3)) | H18: =IF($A18="","",SUMIFS(ERFASSUNG!$J$6:$J$3005,ERFASSUNG!$D$6:$D$3005,$A18,ERFASSUNG!$V$6:$V$3005,$AZ$3)) | I18: =IF($A18="","",SUMIFS(ERFASSUNG!$K$6:$K$3005,ERFASSUNG!$D$6:$D$3005,$A18,ERFASSUNG!$V$6:$V$3005,$AZ$3)) | J18: =IF($A18="","",SUMIFS(ERFASSUNG!$L$6:$L$3005,ERFASSUNG!$D$6:$D$3005,$A18,ERFASSUNG!$V$6:$V$3005,$AZ$3)) | K18: =IF($A18="","",SUMIFS(ERFASSUNG!$M$6:$M$3005,ERFASSUNG!$D$6:$D$3005,$A18,ERFASSUNG!$V$6:$V$3005,$AZ$3)) | L18: =IF($A18="","",SUMIFS(ERFASSUNG!$N$6:$N$3005,ERFASSUNG!$D$6:$D$3005,$A18,ERFASSUNG!$V$6:$V$3005,$AZ$3)) | M18: =IF(OR($A18="",N($G$45)=0),"",G18/$G$45)
A19: =IF(LISTEN!$A$6="","",LISTEN!$A$6) | B19: =IF($A19="","",COUNTIFS(ERFASSUNG!$D$6:$D$3005,$A19,ERFASSUNG!$V$6:$V$3005,$AZ$3)) | C19: =IF($A19="","",SUMIFS(ERFASSUNG!$E$6:$E$3005,ERFASSUNG!$D$6:$D$3005,$A19,ERFASSUNG!$V$6:$V$3005,$AZ$3)) | D19: =IF($A19="","",SUMIFS(ERFASSUNG!$F$6:$F$3005,ERFASSUNG!$D$6:$D$3005,$A19,ERFASSUNG!$V$6:$V$3005,$AZ$3)) | E19: =IF($A19="","",SUMIFS(ERFASSUNG!$G$6:$G$3005,ERFASSUNG!$D$6:$D$3005,$A19,ERFASSUNG!$V$6:$V$3005,$AZ$3)) | F19: =IF($A19="","",SUMIFS(ERFASSUNG!$H$6:$H$3005,ERFASSUNG!$D$6:$D$3005,$A19,ERFASSUNG!$V$6:$V$3005,$AZ$3)) | G19: =IF($A19="","",SUMIFS(ERFASSUNG!$I$6:$I$3005,ERFASSUNG!$D$6:$D$3005,$A19,ERFASSUNG!$V$6:$V$3005,$AZ$3)) | H19: =IF($A19="","",SUMIFS(ERFASSUNG!$J$6:$J$3005,ERFASSUNG!$D$6:$D$3005,$A19,ERFASSUNG!$V$6:$V$3005,$AZ$3)) | I19: =IF($A19="","",SUMIFS(ERFASSUNG!$K$6:$K$3005,ERFASSUNG!$D$6:$D$3005,$A19,ERFASSUNG!$V$6:$V$3005,$AZ$3)) | J19: =IF($A19="","",SUMIFS(ERFASSUNG!$L$6:$L$3005,ERFASSUNG!$D$6:$D$3005,$A19,ERFASSUNG!$V$6:$V$3005,$AZ$3)) | K19: =IF($A19="","",SUMIFS(ERFASSUNG!$M$6:$M$3005,ERFASSUNG!$D$6:$D$3005,$A19,ERFASSUNG!$V$6:$V$3005,$AZ$3)) | L19: =IF($A19="","",SUMIFS(ERFASSUNG!$N$6:$N$3005,ERFASSUNG!$D$6:$D$3005,$A19,ERFASSUNG!$V$6:$V$3005,$AZ$3)) | M19: =IF(OR($A19="",N($G$45)=0),"",G19/$G$45)
A20: =IF(LISTEN!$A$7="","",LISTEN!$A$7) | B20: =IF($A20="","",COUNTIFS(ERFASSUNG!$D$6:$D$3005,$A20,ERFASSUNG!$V$6:$V$3005,$AZ$3)) | C20: =IF($A20="","",SUMIFS(ERFASSUNG!$E$6:$E$3005,ERFASSUNG!$D$6:$D$3005,$A20,ERFASSUNG!$V$6:$V$3005,$AZ$3)) | D20: =IF($A20="","",SUMIFS(ERFASSUNG!$F$6:$F$3005,ERFASSUNG!$D$6:$D$3005,$A20,ERFASSUNG!$V$6:$V$3005,$AZ$3)) | E20: =IF($A20="","",SUMIFS(ERFASSUNG!$G$6:$G$3005,ERFASSUNG!$D$6:$D$3005,$A20,ERFASSUNG!$V$6:$V$3005,$AZ$3)) | F20: =IF($A20="","",SUMIFS(ERFASSUNG!$H$6:$H$3005,ERFASSUNG!$D$6:$D$3005,$A20,ERFASSUNG!$V$6:$V$3005,$AZ$3)) | G20: =IF($A20="","",SUMIFS(ERFASSUNG!$I$6:$I$3005,ERFASSUNG!$D$6:$D$3005,$A20,ERFASSUNG!$V$6:$V$3005,$AZ$3)) | H20: =IF($A20="","",SUMIFS(ERFASSUNG!$J$6:$J$3005,ERFASSUNG!$D$6:$D$3005,$A20,ERFASSUNG!$V$6:$V$3005,$AZ$3)) | I20: =IF($A20="","",SUMIFS(ERFASSUNG!$K$6:$K$3005,ERFASSUNG!$D$6:$D$3005,$A20,ERFASSUNG!$V$6:$V$3005,$AZ$3)) | J20: =IF($A20="","",SUMIFS(ERFASSUNG!$L$6:$L$3005,ERFASSUNG!$D$6:$D$3005,$A20,ERFASSUNG!$V$6:$V$3005,$AZ$3)) | K20: =IF($A20="","",SUMIFS(ERFASSUNG!$M$6:$M$3005,ERFASSUNG!$D$6:$D$3005,$A20,ERFASSUNG!$V$6:$V$3005,$AZ$3)) | L20: =IF($A20="","",SUMIFS(ERFASSUNG!$N$6:$N$3005,ERFASSUNG!$D$6:$D$3005,$A20,ERFASSUNG!$V$6:$V$3005,$AZ$3)) | M20: =IF(OR($A20="",N($G$45)=0),"",G20/$G$45)
A21: =IF(LISTEN!$A$8="","",LISTEN!$A$8) | B21: =IF($A21="","",COUNTIFS(ERFASSUNG!$D$6:$D$3005,$A21,ERFASSUNG!$V$6:$V$3005,$AZ$3)) | C21: =IF($A21="","",SUMIFS(ERFASSUNG!$E$6:$E$3005,ERFASSUNG!$D$6:$D$3005,$A21,ERFASSUNG!$V$6:$V$3005,$AZ$3)) | D21: =IF($A21="","",SUMIFS(ERFASSUNG!$F$6:$F$3005,ERFASSUNG!$D$6:$D$3005,$A21,ERFASSUNG!$V$6:$V$3005,$AZ$3)) | E21: =IF($A21="","",SUMIFS(ERFASSUNG!$G$6:$G$3005,ERFASSUNG!$D$6:$D$3005,$A21,ERFASSUNG!$V$6:$V$3005,$AZ$3)) | F21: =IF($A21="","",SUMIFS(ERFASSUNG!$H$6:$H$3005,ERFASSUNG!$D$6:$D$3005,$A21,ERFASSUNG!$V$6:$V$3005,$AZ$3)) | G21: =IF($A21="","",SUMIFS(ERFASSUNG!$I$6:$I$3005,ERFASSUNG!$D$6:$D$3005,$A21,ERFASSUNG!$V$6:$V$3005,$AZ$3)) | H21: =IF($A21="","",SUMIFS(ERFASSUNG!$J$6:$J$3005,ERFASSUNG!$D$6:$D$3005,$A21,ERFASSUNG!$V$6:$V$3005,$AZ$3)) | I21: =IF($A21="","",SUMIFS(ERFASSUNG!$K$6:$K$3005,ERFASSUNG!$D$6:$D$3005,$A21,ERFASSUNG!$V$6:$V$3005,$AZ$3)) | J21: =IF($A21="","",SUMIFS(ERFASSUNG!$L$6:$L$3005,ERFASSUNG!$D$6:$D$3005,$A21,ERFASSUNG!$V$6:$V$3005,$AZ$3)) | K21: =IF($A21="","",SUMIFS(ERFASSUNG!$M$6:$M$3005,ERFASSUNG!$D$6:$D$3005,$A21,ERFASSUNG!$V$6:$V$3005,$AZ$3)) | L21: =IF($A21="","",SUMIFS(ERFASSUNG!$N$6:$N$3005,ERFASSUNG!$D$6:$D$3005,$A21,ERFASSUNG!$V$6:$V$3005,$AZ$3)) | M21: =IF(OR($A21="",N($G$45)=0),"",G21/$G$45)
A22: =IF(LISTEN!$A$9="","",LISTEN!$A$9) | B22: =IF($A22="","",COUNTIFS(ERFASSUNG!$D$6:$D$3005,$A22,ERFASSUNG!$V$6:$V$3005,$AZ$3)) | C22: =IF($A22="","",SUMIFS(ERFASSUNG!$E$6:$E$3005,ERFASSUNG!$D$6:$D$3005,$A22,ERFASSUNG!$V$6:$V$3005,$AZ$3)) | D22: =IF($A22="","",SUMIFS(ERFASSUNG!$F$6:$F$3005,ERFASSUNG!$D$6:$D$3005,$A22,ERFASSUNG!$V$6:$V$3005,$AZ$3)) | E22: =IF($A22="","",SUMIFS(ERFASSUNG!$G$6:$G$3005,ERFASSUNG!$D$6:$D$3005,$A22,ERFASSUNG!$V$6:$V$3005,$AZ$3)) | F22: =IF($A22="","",SUMIFS(ERFASSUNG!$H$6:$H$3005,ERFASSUNG!$D$6:$D$3005,$A22,ERFASSUNG!$V$6:$V$3005,$AZ$3)) | G22: =IF($A22="","",SUMIFS(ERFASSUNG!$I$6:$I$3005,ERFASSUNG!$D$6:$D$3005,$A22,ERFASSUNG!$V$6:$V$3005,$AZ$3)) | H22: =IF($A22="","",SUMIFS(ERFASSUNG!$J$6:$J$3005,ERFASSUNG!$D$6:$D$3005,$A22,ERFASSUNG!$V$6:$V$3005,$AZ$3)) | I22: =IF($A22="","",SUMIFS(ERFASSUNG!$K$6:$K$3005,ERFASSUNG!$D$6:$D$3005,$A22,ERFASSUNG!$V$6:$V$3005,$AZ$3)) | J22: =IF($A22="","",SUMIFS(ERFASSUNG!$L$6:$L$3005,ERFASSUNG!$D$6:$D$3005,$A22,ERFASSUNG!$V$6:$V$3005,$AZ$3)) | K22: =IF($A22="","",SUMIFS(ERFASSUNG!$M$6:$M$3005,ERFASSUNG!$D$6:$D$3005,$A22,ERFASSUNG!$V$6:$V$3005,$AZ$3)) | L22: =IF($A22="","",SUMIFS(ERFASSUNG!$N$6:$N$3005,ERFASSUNG!$D$6:$D$3005,$A22,ERFASSUNG!$V$6:$V$3005,$AZ$3)) | M22: =IF(OR($A22="",N($G$45)=0),"",G22/$G$45)
A23: =IF(LISTEN!$A$10="","",LISTEN!$A$10) | B23: =IF($A23="","",COUNTIFS(ERFASSUNG!$D$6:$D$3005,$A23,ERFASSUNG!$V$6:$V$3005,$AZ$3)) | C23: =IF($A23="","",SUMIFS(ERFASSUNG!$E$6:$E$3005,ERFASSUNG!$D$6:$D$3005,$A23,ERFASSUNG!$V$6:$V$3005,$AZ$3)) | D23: =IF($A23="","",SUMIFS(ERFASSUNG!$F$6:$F$3005,ERFASSUNG!$D$6:$D$3005,$A23,ERFASSUNG!$V$6:$V$3005,$AZ$3)) | E23: =IF($A23="","",SUMIFS(ERFASSUNG!$G$6:$G$3005,ERFASSUNG!$D$6:$D$3005,$A23,ERFASSUNG!$V$6:$V$3005,$AZ$3)) | F23: =IF($A23="","",SUMIFS(ERFASSUNG!$H$6:$H$3005,ERFASSUNG!$D$6:$D$3005,$A23,ERFASSUNG!$V$6:$V$3005,$AZ$3)) | G23: =IF($A23="","",SUMIFS(ERFASSUNG!$I$6:$I$3005,ERFASSUNG!$D$6:$D$3005,$A23,ERFASSUNG!$V$6:$V$3005,$AZ$3)) | H23: =IF($A23="","",SUMIFS(ERFASSUNG!$J$6:$J$3005,ERFASSUNG!$D$6:$D$3005,$A23,ERFASSUNG!$V$6:$V$3005,$AZ$3)) | I23: =IF($A23="","",SUMIFS(ERFASSUNG!$K$6:$K$3005,ERFASSUNG!$D$6:$D$3005,$A23,ERFASSUNG!$V$6:$V$3005,$AZ$3)) | J23: =IF($A23="","",SUMIFS(ERFASSUNG!$L$6:$L$3005,ERFASSUNG!$D$6:$D$3005,$A23,ERFASSUNG!$V$6:$V$3005,$AZ$3)) | K23: =IF($A23="","",SUMIFS(ERFASSUNG!$M$6:$M$3005,ERFASSUNG!$D$6:$D$3005,$A23,ERFASSUNG!$V$6:$V$3005,$AZ$3)) | L23: =IF($A23="","",SUMIFS(ERFASSUNG!$N$6:$N$3005,ERFASSUNG!$D$6:$D$3005,$A23,ERFASSUNG!$V$6:$V$3005,$AZ$3)) | M23: =IF(OR($A23="",N($G$45)=0),"",G23/$G$45)
