Workbook

Sheet ANLEITUNG
B2: Dienstdokumentation – Anleitung
B4: So funktioniert's
B5: 1. | C5: Im Blatt LISTEN das Jahr eintragen und bei Bedarf Angebote / Diensthabende anpassen (gelbe Zellen).
B6: 2. | C6: Pro Monat gibt es EIN Blatt. Pro Angebot und Tag wird EINE Zeile ausgefüllt – nur die Angebote, die wirklich stattgefunden haben.
B7: 3. | C7: Weiße Zellen = Eingabe. Graue Zellen = rechnen automatisch (nicht überschreiben).
B8: 4. | C8: Angebot und Diensthabende über das Dropdown wählen (Diensthabende kann auch frei getippt werden).
B9: 5. | C9: Rechts neben der Tabelle steht sofort die Monatsauswertung mit Diagrammen (Geschlecht, Alter, Angebote).
B10: 6. | C10: Das Blatt JAHRESAUSWERTUNG fasst alle Monate automatisch zusammen – inkl. Verlauf und Diagrammen.
B11: 7. | C11: Orange markiert: 'gesamt Alter' weicht von 'gesamt' ab → Zahlen prüfen. Wochenenden sind grau hinterlegt.
B12: 8. | C12: Mit dem Filter-Pfeil in der Kopfzeile lässt sich z.B. nach Angebot filtern – die Summenzeile oben rechnet dann nur die gefilterten Zeilen.
B14: Beispielzeile (so sieht ein Eintrag aus)
B15: Datum | C15: Tag | D15: Angebot | E15: Stunden | F15: w | G15: d | H15: m | I15: gesamt | J15: ab 10 | K15: ab 14 | L15: ab 16 | M15: ab 18 | N15: gesamt Alter | O15: Diensthabende | P15: Beschreibung | Q15: Wichtig
B16: 06.01.2026 | C16: Di | D16: JUGENDCAFE | E16: 4 | F16: 7 | G16: 1 | H16: 12 | I16: 20 | J16: 5 | K16: 9 | L16: 4 | M16: 2 | N16: 20 | O16: Anna, Max | P16: Billard-Turnier | Q16: Fenster WC defekt
B18: Spaltenbedeutung
B19: w / d / m | C19: Anzahl Besucher:innen weiblich / divers / männlich
B20: ab 10 … ab 18 | C20: Anzahl nach Altersgruppe (10–13, 14–15, 16–17, 18+)
B21: gesamt Alter | C21: Summe der Altersgruppen (Kontrolle zu 'gesamt')
B22: Einträge | C22: Wie oft das Angebot im Zeitraum stattgefunden hat

Sheet JAHRESAUSWERTUNG
A1: ="JAHRESAUSWERTUNG "&LISTEN!$E$2
A2: rechnet automatisch aus allen Monatsblättern – nichts eintragen
A4: Verlauf nach Monaten
A5: Monat | B5: Stunden | C5: w | D5: d | E5: m | F5: gesamt | G5: ab 10 | H5: ab 14 | I5: ab 16 | J5: ab 18 | K5: Einträge | L5: Öffnungstage
A6: Januar | B6: ='JANUAR'!S36 | C6: ='JANUAR'!T36 | D6: ='JANUAR'!U36 | E6: ='JANUAR'!V36 | F6: ='JANUAR'!W36 | G6: ='JANUAR'!X36 | H6: ='JANUAR'!Y36 | I6: ='JANUAR'!Z36 | ... K6: ='JANUAR'!AB36 | L6: ='JANUAR'!V39
A7: Februar | B7: ='FEBRUAR'!S36 | C7: ='FEBRUAR'!T36 | D7: ='FEBRUAR'!U36 | E7: ='FEBRUAR'!V36 | F7: ='FEBRUAR'!W36 | G7: ='FEBRUAR'!X36 | H7: ='FEBRUAR'!Y36 | I7: ='FEBRUAR'!Z36 | ... K7: ='FEBRUAR'!AB36 | L7: ='FEBRUAR'!V39
A8: März | B8: ='MÄRZ'!S36 | C8: ='MÄRZ'!T36 | D8: ='MÄRZ'!U36 | E8: ='MÄRZ'!V36 | F8: ='MÄRZ'!W36 | G8: ='MÄRZ'!X36 | H8: ='MÄRZ'!Y36 | I8: ='MÄRZ'!Z36 | ... K8: ='MÄRZ'!AB36 | L8: ='MÄRZ'!V39
A9: April | B9: ='APRIL'!S36 | C9: ='APRIL'!T36 | D9: ='APRIL'!U36 | E9: ='APRIL'!V36 | F9: ='APRIL'!W36 | G9: ='APRIL'!X36 | H9: ='APRIL'!Y36 | I9: ='APRIL'!Z36 | ... K9: ='APRIL'!AB36 | L9: ='APRIL'!V39
A10: Mai | B10: ='MAI'!S36 | C10: ='MAI'!T36 | D10: ='MAI'!U36 | E10: ='MAI'!V36 | F10: ='MAI'!W36 | G10: ='MAI'!X36 | H10: ='MAI'!Y36 | I10: ='MAI'!Z36 | ... K10: ='MAI'!AB36 | L10: ='MAI'!V39
A11: Juni | B11: ='JUNI'!S36 | C11: ='JUNI'!T36 | D11: ='JUNI'!U36 | E11: ='JUNI'!V36 | F11: ='JUNI'!W36 | G11: ='JUNI'!X36 | H11: ='JUNI'!Y36 | I11: ='JUNI'!Z36 | ... K11: ='JUNI'!AB36 | L11: ='JUNI'!V39
A12: Juli | B12: ='JULI'!S36 | C12: ='JULI'!T36 | D12: ='JULI'!U36 | E12: ='JULI'!V36 | F12: ='JULI'!W36 | G12: ='JULI'!X36 | H12: ='JULI'!Y36 | I12: ='JULI'!Z36 | ... K12: ='JULI'!AB36 | L12: ='JULI'!V39
A13: August | B13: ='AUGUST'!S36 | C13: ='AUGUST'!T36 | D13: ='AUGUST'!U36 | E13: ='AUGUST'!V36 | F13: ='AUGUST'!W36 | G13: ='AUGUST'!X36 | H13: ='AUGUST'!Y36 | I13: ='AUGUST'!Z36 | ... K13: ='AUGUST'!AB36 | L13: ='AUGUST'!V39
A14: September | B14: ='SEPTEMBER'!S36 | C14: ='SEPTEMBER'!T36 | D14: ='SEPTEMBER'!U36 | E14: ='SEPTEMBER'!V36 | F14: ='SEPTEMBER'!W36 | G14: ='SEPTEMBER'!X36 | H14: ='SEPTEMBER'!Y36 | I14: ='SEPTEMBER'!Z36 | ... K14: ='SEPTEMBER'!AB36 | L14: ='SEPTEMBER'!V39
A15: Oktober | B15: ='OKTOBER'!S36 | C15: ='OKTOBER'!T36 | D15: ='OKTOBER'!U36 | E15: ='OKTOBER'!V36 | F15: ='OKTOBER'!W36 | G15: ='OKTOBER'!X36 | H15: ='OKTOBER'!Y36 | I15: ='OKTOBER'!Z36 | ... K15: ='OKTOBER'!AB36 | L15: ='OKTOBER'!V39
A16: November | B16: ='NOVEMBER'!S36 | C16: ='NOVEMBER'!T36 | D16: ='NOVEMBER'!U36 | E16: ='NOVEMBER'!V36 | F16: ='NOVEMBER'!W36 | G16: ='NOVEMBER'!X36 | H16: ='NOVEMBER'!Y36 | I16: ='NOVEMBER'!Z36 | ... K16: ='NOVEMBER'!AB36 | L16: ='NOVEMBER'!V39
A17: Dezember | B17: ='DEZEMBER'!S36 | C17: ='DEZEMBER'!T36 | D17: ='DEZEMBER'!U36 | E17: ='DEZEMBER'!V36 | F17: ='DEZEMBER'!W36 | G17: ='DEZEMBER'!X36 | H17: ='DEZEMBER'!Y36 | I17: ='DEZEMBER'!Z36 | ... K17: ='DEZEMBER'!AB36 | L17: ='DEZEMBER'!V39
A18: JAHR | B18: =SUM(B6:B17) | C18: =SUM(C6:C17) | D18: =SUM(D6:D17) | E18: =SUM(E6:E17) | F18: =SUM(F6:F17) | G18: =SUM(G6:G17) | H18: =SUM(H6:H17) | I18: =SUM(I6:I17) | ... L18: =SUM(L6:L17)
A20: Anteile Jahr
A21: Merkmal | B21: weiblich | C21: divers | D21: männlich | E21: ab 10 | F21: ab 14 | G21: ab 16 | H21: ab 18
A22: Anzahl | B22: =C18 | C22: =D18 | D22: =E18 | E22: =G18 | F22: =H18 | G22: =I18 | H22: =J18 | J22: Ø Besucher:innen / Öffnungstag | M22: =IF(L18=0,0,F18/L18)
A23: Anteil | B23: =IF($F$18=0,0,C18/$F$18) | C23: =IF($F$18=0,0,D18/$F$18) | D23: =IF($F$18=0,0,E18/$F$18) | E23: =IF(SUM($G$18:$J$18)=0,0,G18/SUM($G$18:$J$18)) | F23: =IF(SUM($G$18:$J$18)=0,0,H18/SUM($G$18:$J$18)) | G23: =IF(SUM($G$18:$J$18)=0,0,I18/SUM($G$18:$J$18)) | H23: =IF(SUM($G$18:$J$18)=0,0,J18/SUM($G$18:$J$18))
A25: Angebote im Jahr
A26: Angebot | B26: Stunden | C26: w | D26: d | E26: m | F26: gesamt | G26: ab 10 | H26: ab 14 | I26: ab 16 | J26: ab 18 | K26: Einträge | L26: Anteil Besuche
A27: =IF(LISTEN!$A$2="","",LISTEN!$A$2) | B27: =IF($A27="","",N('JANUAR'!S6)+N('FEBRUAR'!S6)+N('MÄRZ'!S6)+N('APRIL'!S6)+N('MAI'!S6)+N('JUNI'!S6)+N('JULI'!S6)+N('AUGUST'!S6)+N('SEPTEMBER'!S6)+N('OKTOBER'!S6)+N('NOVEMBER'!S6)+N('DEZEMBER'!S6)) | C27: =IF($A27="","",N('JANUAR'!T6)+N('FEBRUAR'!T6)+N('MÄRZ'!T6)+N('APRIL'!T6)+N('MAI'!T6)+N('JUNI'!T6)+N('JULI'!T6)+N('AUGUST'!T6)+N('SEPTEMBER'!T6)+N('OKTOBER'!T6)+N('NOVEMBER'!T6)+N('DEZEMBER'!T6)) | D27: =IF($A27="","",N('JANUAR'!U6)+N('FEBRUAR'!U6)+N('MÄRZ'!U6)+N('APRIL'!U6)+N('MAI'!U6)+N('JUNI'!U6)+N('JULI'!U6)+N('AUGUST'!U6)+N('SEPTEMBER'!U6)+N('OKTOBER'!U6)+N('NOVEMBER'!U6)+N('DEZEMBER'!U6)) | E27: =IF($A27="","",N('JANUAR'!V6)+N('FEBRUAR'!V6)+N('MÄRZ'!V6)+N('APRIL'!V6)+N('MAI'!V6)+N('JUNI'!V6)+N('JULI'!V6)+N('AUGUST'!V6)+N('SEPTEMBER'!V6)+N('OKTOBER'!V6)+N('NOVEMBER'!V6)+N('DEZEMBER'!V6)) | F27: =IF($A27="","",N('JANUAR'!W6)+N('FEBRUAR'!W6)+N('MÄRZ'!W6)+N('APRIL'!W6)+N('MAI'!W6)+N('JUNI'!W6)+N('JULI'!W6)+N('AUGUST'!W6)+N('SEPTEMBER'!W6)+N('OKTOBER'!W6)+N('NOVEMBER'!W6)+N('DEZEMBER'!W6)) | G27: =IF($A27="","",N('JANUAR'!X6)+N('FEBRUAR'!X6)+N('MÄRZ'!X6)+N('APRIL'!X6)+N('MAI'!X6)+N('JUNI'!X6)+N('JULI'!X6)+N('AUGUST'!X6)+N('SEPTEMBER'!X6)+N('OKTOBER'!X6)+N('NOVEMBER'!X6)+N('DEZEMBER'!X6)) | H27: =IF($A27="","",N('JANUAR'!Y6)+N('FEBRUAR'!Y6)+N('MÄRZ'!Y6)+N('APRIL'!Y6)+N('MAI'!Y6)+N('JUNI'!Y6)+N('JULI'!Y6)+N('AUGUST'!Y6)+N('SEPTEMBER'!Y6)+N('OKTOBER'!Y6)+N('NOVEMBER'!Y6)+N('DEZEMBER'!Y6)) | I27: =IF($A27="","",N('JANUAR'!Z6)+N('FEBRUAR'!Z6)+N('MÄRZ'!Z6)+N('APRIL'!Z6)+N('MAI'!Z6)+N('JUNI'!Z6)+N('JULI'!Z6)+N('AUGUST'!Z6)+N('SEPTEMBER'!Z6)+N('OKTOBER'!Z6)+N('NOVEMBER'!Z6)+N('DEZEMBER'!Z6)) | ... K27: =IF($A27="","",N('JANUAR'!AB6)+N('FEBRUAR'!AB6)+N('MÄRZ'!AB6)+N('APRIL'!AB6)+N('MAI'!AB6)+N('JUNI'!AB6)+N('JULI'!AB6)+N('AUGUST'!AB6)+N('SEPTEMBER'!AB6)+N('OKTOBER'!AB6)+N('NOVEMBER'!AB6)+N('DEZEMBER'!AB6)) | L27: =IF(OR($A27="",$F$57=0),"",F27/$F$57)
A28: =IF(LISTEN!$A$3="","",LISTEN!$A$3) | B28: =IF($A28="","",N('JANUAR'!S7)+N('FEBRUAR'!S7)+N('MÄRZ'!S7)+N('APRIL'!S7)+N('MAI'!S7)+N('JUNI'!S7)+N('JULI'!S7)+N('AUGUST'!S7)+N('SEPTEMBER'!S7)+N('OKTOBER'!S7)+N('NOVEMBER'!S7)+N('DEZEMBER'!S7)) | C28: =IF($A28="","",N('JANUAR'!T7)+N('FEBRUAR'!T7)+N('MÄRZ'!T7)+N('APRIL'!T7)+N('MAI'!T7)+N('JUNI'!T7)+N('JULI'!T7)+N('AUGUST'!T7)+N('SEPTEMBER'!T7)+N('OKTOBER'!T7)+N('NOVEMBER'!T7)+N('DEZEMBER'!T7)) | D28: =IF($A28="","",N('JANUAR'!U7)+N('FEBRUAR'!U7)+N('MÄRZ'!U7)+N('APRIL'!U7)+N('MAI'!U7)+N('JUNI'!U7)+N('JULI'!U7)+N('AUGUST'!U7)+N('SEPTEMBER'!U7)+N('OKTOBER'!U7)+N('NOVEMBER'!U7)+N('DEZEMBER'!U7)) | E28: =IF($A28="","",N('JANUAR'!V7)+N('FEBRUAR'!V7)+N('MÄRZ'!V7)+N('APRIL'!V7)+N('MAI'!V7)+N('JUNI'!V7)+N('JULI'!V7)+N('AUGUST'!V7)+N('SEPTEMBER'!V7)+N('OKTOBER'!V7)+N('NOVEMBER'!V7)+N('DEZEMBER'!V7)) | F28: =IF($A28="","",N('JANUAR'!W7)+N('FEBRUAR'!W7)+N('MÄRZ'!W7)+N('APRIL'!W7)+N('MAI'!W7)+N('JUNI'!W7)+N('JULI'!W7)+N('AUGUST'!W7)+N('SEPTEMBER'!W7)+N('OKTOBER'!W7)+N('NOVEMBER'!W7)+N('DEZEMBER'!W7)) | G28: =IF($A28="","",N('JANUAR'!X7)+N('FEBRUAR'!X7)+N('MÄRZ'!X7)+N('APRIL'!X7)+N('MAI'!X7)+N('JUNI'!X7)+N('JULI'!X7)+N('AUGUST'!X7)+N('SEPTEMBER'!X7)+N('OKTOBER'!X7)+N('NOVEMBER'!X7)+N('DEZEMBER'!X7)) | H28: =IF($A28="","",N('JANUAR'!Y7)+N('FEBRUAR'!Y7)+N('MÄRZ'!Y7)+N('APRIL'!Y7)+N('MAI'!Y7)+N('JUNI'!Y7)+N('JULI'!Y7)+N('AUGUST'!Y7)+N('SEPTEMBER'!Y7)+N('OKTOBER'!Y7)+N('NOVEMBER'!Y7)+N('DEZEMBER'!Y7)) | I28: =IF($A28="","",N('JANUAR'!Z7)+N('FEBRUAR'!Z7)+N('MÄRZ'!Z7)+N('APRIL'!Z7)+N('MAI'!Z7)+N('JUNI'!Z7)+N('JULI'!Z7)+N('AUGUST'!Z7)+N('SEPTEMBER'!Z7)+N('OKTOBER'!Z7)+N('NOVEMBER'!Z7)+N('DEZEMBER'!Z7)) | ... K28: =IF($A28="","",N('JANUAR'!AB7)+N('FEBRUAR'!AB7)+N('MÄRZ'!AB7)+N('APRIL'!AB7)+N('MAI'!AB7)+N('JUNI'!AB7)+N('JULI'!AB7)+N('AUGUST'!AB7)+N('SEPTEMBER'!AB7)+N('OKTOBER'!AB7)+N('NOVEMBER'!AB7)+N('DEZEMBER'!AB7)) | L28: =IF(OR($A28="",$F$57=0),"",F28/$F$57)
A29: =IF(LISTEN!$A$4="","",LISTEN!$A$4) | B29: =IF($A29="","",N('JANUAR'!S8)+N('FEBRUAR'!S8)+N('MÄRZ'!S8)+N('APRIL'!S8)+N('MAI'!S8)+N('JUNI'!S8)+N('JULI'!S8)+N('AUGUST'!S8)+N('SEPTEMBER'!S8)+N('OKTOBER'!S8)+N('NOVEMBER'!S8)+N('DEZEMBER'!S8)) | C29: =IF($A29="","",N('JANUAR'!T8)+N('FEBRUAR'!T8)+N('MÄRZ'!T8)+N('APRIL'!T8)+N('MAI'!T8)+N('JUNI'!T8)+N('JULI'!T8)+N('AUGUST'!T8)+N('SEPTEMBER'!T8)+N('OKTOBER'!T8)+N('NOVEMBER'!T8)+N('DEZEMBER'!T8)) | D29: =IF($A29="","",N('JANUAR'!U8)+N('FEBRUAR'!U8)+N('MÄRZ'!U8)+N('APRIL'!U8)+N('MAI'!U8)+N('JUNI'!U8)+N('JULI'!U8)+N('AUGUST'!U8)+N('SEPTEMBER'!U8)+N('OKTOBER'!U8)+N('NOVEMBER'!U8)+N('DEZEMBER'!U8)) | E29: =IF($A29="","",N('JANUAR'!V8)+N('FEBRUAR'!V8)+N('MÄRZ'!V8)+N('APRIL'!V8)+N('MAI'!V8)+N('JUNI'!V8)+N('JULI'!V8)+N('AUGUST'!V8)+N('SEPTEMBER'!V8)+N('OKTOBER'!V8)+N('NOVEMBER'!V8)+N('DEZEMBER'!V8)) | F29: =IF($A29="","",N('JANUAR'!W8)+N('FEBRUAR'!W8)+N('MÄRZ'!W8)+N('APRIL'!W8)+N('MAI'!W8)+N('JUNI'!W8)+N('JULI'!W8)+N('AUGUST'!W8)+N('SEPTEMBER'!W8)+N('OKTOBER'!W8)+N('NOVEMBER'!W8)+N('DEZEMBER'!W8)) | G29: =IF($A29="","",N('JANUAR'!X8)+N('FEBRUAR'!X8)+N('MÄRZ'!X8)+N('APRIL'!X8)+N('MAI'!X8)+N('JUNI'!X8)+N('JULI'!X8)+N('AUGUST'!X8)+N('SEPTEMBER'!X8)+N('OKTOBER'!X8)+N('NOVEMBER'!X8)+N('DEZEMBER'!X8)) | H29: =IF($A29="","",N('JANUAR'!Y8)+N('FEBRUAR'!Y8)+N('MÄRZ'!Y8)+N('APRIL'!Y8)+N('MAI'!Y8)+N('JUNI'!Y8)+N('JULI'!Y8)+N('AUGUST'!Y8)+N('SEPTEMBER'!Y8)+N('OKTOBER'!Y8)+N('NOVEMBER'!Y8)+N('DEZEMBER'!Y8)) | I29: =IF($A29="","",N('JANUAR'!Z8)+N('FEBRUAR'!Z8)+N('MÄRZ'!Z8)+N('APRIL'!Z8)+N('MAI'!Z8)+N('JUNI'!Z8)+N('JULI'!Z8)+N('AUGUST'!Z8)+N('SEPTEMBER'!Z8)+N('OKTOBER'!Z8)+N('NOVEMBER'!Z8)+N('DEZEMBER'!Z8)) | ... K29: =IF($A29="","",N('JANUAR'!AB8)+N('FEBRUAR'!AB8)+N('MÄRZ'!AB8)+N('APRIL'!AB8)+N('MAI'!AB8)+N('JUNI'!AB8)+N('JULI'!AB8)+N('AUGUST'!AB8)+N('SEPTEMBER'!AB8)+N('OKTOBER'!AB8)+N('NOVEMBER'!AB8)+N('DEZEMBER'!AB8)) | L29: =IF(OR($A29="",$F$57=0),"",F29/$F$57)
A30: =IF(LISTEN!$A$5="","",LISTEN!$A$5) | B30: =IF($A30="","",N('JANUAR'!S9)+N('FEBRUAR'!S9)+N('MÄRZ'!S9)+N('APRIL'!S9)+N('MAI'!S9)+N('JUNI'!S9)+N('JULI'!S9)+N('AUGUST'!S9)+N('SEPTEMBER'!S9)+N('OKTOBER'!S9)+N('NOVEMBER'!S9)+N('DEZEMBER'!S9)) | C30: =IF($A30="","",N('JANUAR'!T9)+N('FEBRUAR'!T9)+N('MÄRZ'!T9)+N('APRIL'!T9)+N('MAI'!T9)+N('JUNI'!T9)+N('JULI'!T9)+N('AUGUST'!T9)+N('SEPTEMBER'!T9)+N('OKTOBER'!T9)+N('NOVEMBER'!T9)+N('DEZEMBER'!T9)) | D30: =IF($A30="","",N('JANUAR'!U9)+N('FEBRUAR'!U9)+N('MÄRZ'!U9)+N('APRIL'!U9)+N('MAI'!U9)+N('JUNI'!U9)+N('JULI'!U9)+N('AUGUST'!U9)+N('SEPTEMBER'!U9)+N('OKTOBER'!U9)+N('NOVEMBER'!U9)+N('DEZEMBER'!U9)) | E30: =IF($A30="","",N('JANUAR'!V9)+N('FEBRUAR'!V9)+N('MÄRZ'!V9)+N('APRIL'!V9)+N('MAI'!V9)+N('JUNI'!V9)+N('JULI'!V9)+N('AUGUST'!V9)+N('SEPTEMBER'!V9)+N('OKTOBER'!V9)+N('NOVEMBER'!V9)+N('DEZEMBER'!V9)) | F30: =IF($A30="","",N('JANUAR'!W9)+N('FEBRUAR'!W9)+N('MÄRZ'!W9)+N('APRIL'!W9)+N('MAI'!W9)+N('JUNI'!W9)+N('JULI'!W9)+N('AUGUST'!W9)+N('SEPTEMBER'!W9)+N('OKTOBER'!W9)+N('NOVEMBER'!W9)+N('DEZEMBER'!W9)) | G30: =IF($A30="","",N('JANUAR'!X9)+N('FEBRUAR'!X9)+N('MÄRZ'!X9)+N('APRIL'!X9)+N('MAI'!X9)+N('JUNI'!X9)+N('JULI'!X9)+N('AUGUST'!X9)+N('SEPTEMBER'!X9)+N('OKTOBER'!X9)+N('NOVEMBER'!X9)+N('DEZEMBER'!X9)) | H30: =IF($A30="","",N('JANUAR'!Y9)+N('FEBRUAR'!Y9)+N('MÄRZ'!Y9)+N('APRIL'!Y9)+N('MAI'!Y9)+N('JUNI'!Y9)+N('JULI'!Y9)+N('AUGUST'!Y9)+N('SEPTEMBER'!Y9)+N('OKTOBER'!Y9)+N('NOVEMBER'!Y9)+N('DEZEMBER'!Y9)) | I30: =IF($A30="","",N('JANUAR'!Z9)+N('FEBRUAR'!Z9)+N('MÄRZ'!Z9)+N('APRIL'!Z9)+N('MAI'!Z9)+N('JUNI'!Z9)+N('JULI'!Z9)+N('AUGUST'!Z9)+N('SEPTEMBER'!Z9)+N('OKTOBER'!Z9)+N('NOVEMBER'!Z9)+N('DEZEMBER'!Z9)) | ... K30: =IF($A30="","",N('JANUAR'!AB9)+N('FEBRUAR'!AB9)+N('MÄRZ'!AB9)+N('APRIL'!AB9)+N('MAI'!AB9)+N('JUNI'!AB9)+N('JULI'!AB9)+N('AUGUST'!AB9)+N('SEPTEMBER'!AB9)+N('OKTOBER'!AB9)+N('NOVEMBER'!AB9)+N('DEZEMBER'!AB9)) | L30: =IF(OR($A30="",$F$57=0),"",F30/$F$57)
A31: =IF(LISTEN!$A$6="","",LISTEN!$A$6) | B31: =IF($A31="","",N('JANUAR'!S10)+N('FEBRUAR'!S10)+N('MÄRZ'!S10)+N('APRIL'!S10)+N('MAI'!S10)+N('JUNI'!S10)+N('JULI'!S10)+N('AUGUST'!S10)+N('SEPTEMBER'!S10)+N('OKTOBER'!S10)+N('NOVEMBER'!S10)+N('DEZEMBER'!S10)) | C31: =IF($A31="","",N('JANUAR'!T10)+N('FEBRUAR'!T10)+N('MÄRZ'!T10)+N('APRIL'!T10)+N('MAI'!T10)+N('JUNI'!T10)+N('JULI'!T10)+N('AUGUST'!T10)+N('SEPTEMBER'!T10)+N('OKTOBER'!T10)+N('NOVEMBER'!T10)+N('DEZEMBER'!T10)) | D31: =IF($A31="","",N('JANUAR'!U10)+N('FEBRUAR'!U10)+N('MÄRZ'!U10)+N('APRIL'!U10)+N('MAI'!U10)+N('JUNI'!U10)+N('JULI'!U10)+N('AUGUST'!U10)+N('SEPTEMBER'!U10)+N('OKTOBER'!U10)+N('NOVEMBER'!U10)+N('DEZEMBER'!U10)) | E31: =IF($A31="","",N('JANUAR'!V10)+N('FEBRUAR'!V10)+N('MÄRZ'!V10)+N('APRIL'!V10)+N('MAI'!V10)+N('JUNI'!V10)+N('JULI'!V10)+N('AUGUST'!V10)+N('SEPTEMBER'!V10)+N('OKTOBER'!V10)+N('NOVEMBER'!V10)+N('DEZEMBER'!V10)) | F31: =IF($A31="","",N('JANUAR'!W10)+N('FEBRUAR'!W10)+N('MÄRZ'!W10)+N('APRIL'!W10)+N('MAI'!W10)+N('JUNI'!W10)+N('JULI'!W10)+N('AUGUST'!W10)+N('SEPTEMBER'!W10)+N('OKTOBER'!W10)+N('NOVEMBER'!W10)+N('DEZEMBER'!W10)) | G31: =IF($A31="","",N('JANUAR'!X10)+N('FEBRUAR'!X10)+N('MÄRZ'!X10)+N('APRIL'!X10)+N('MAI'!X10)+N('JUNI'!X10)+N('JULI'!X10)+N('AUGUST'!X10)+N('SEPTEMBER'!X10)+N('OKTOBER'!X10)+N('NOVEMBER'!X10)+N('DEZEMBER'!X10)) | H31: =IF($A31="","",N('JANUAR'!Y10)+N('FEBRUAR'!Y10)+N('MÄRZ'!Y10)+N('APRIL'!Y10)+N('MAI'!Y10)+N('JUNI'!Y10)+N('JULI'!Y10)+N('AUGUST'!Y10)+N('SEPTEMBER'!Y10)+N('OKTOBER'!Y10)+N('NOVEMBER'!Y10)+N('DEZEMBER'!Y10)) | I31: =IF($A31="","",N('JANUAR'!Z10)+N('FEBRUAR'!Z10)+N('MÄRZ'!Z10)+N('APRIL'!Z10)+N('MAI'!Z10)+N('JUNI'!Z10)+N('JULI'!Z10)+N('AUGUST'!Z10)+N('SEPTEMBER'!Z10)+N('OKTOBER'!Z10)+N('NOVEMBER'!Z10)+N('DEZEMBER'!Z10)) | ... K31: =IF($A31="","",N('JANUAR'!AB10)+N('FEBRUAR'!AB10)+N('MÄRZ'!AB10)+N('APRIL'!AB10)+N('MAI'!AB10)+N('JUNI'!AB10)+N('JULI'!AB10)+N('AUGUST'!AB10)+N('SEPTEMBER'!AB10)+N('OKTOBER'!AB10)+N('NOVEMBER'!AB10)+N('DEZEMBER'!AB10)) | L31: =IF(OR($A31="",$F$57=0),"",F31/$F$57)
A32: =IF(LISTEN!$A$7="","",LISTEN!$A$7) | B32: =IF($A32="","",N('JANUAR'!S11)+N('FEBRUAR'!S11)+N('MÄRZ'!S11)+N('APRIL'!S11)+N('MAI'!S11)+N('JUNI'!S11)+N('JULI'!S11)+N('AUGUST'!S11)+N('SEPTEMBER'!S11)+N('OKTOBER'!S11)+N('NOVEMBER'!S11)+N('DEZEMBER'!S11)) | C32: =IF($A32="","",N('JANUAR'!T11)+N('FEBRUAR'!T11)+N('MÄRZ'!T11)+N('APRIL'!T11)+N('MAI'!T11)+N('JUNI'!T11)+N('JULI'!T11)+N('AUGUST'!T11)+N('SEPTEMBER'!T11)+N('OKTOBER'!T11)+N('NOVEMBER'!T11)+N('DEZEMBER'!T11)) | D32: =IF($A32="","",N('JANUAR'!U11)+N('FEBRUAR'!U11)+N('MÄRZ'!U11)+N('APRIL'!U11)+N('MAI'!U11)+N('JUNI'!U11)+N('JULI'!U11)+N('AUGUST'!U11)+N('SEPTEMBER'!U11)+N('OKTOBER'!U11)+N('NOVEMBER'!U11)+N('DEZEMBER'!U11)) | E32: =IF($A32="","",N('JANUAR'!V11)+N('FEBRUAR'!V11)+N('MÄRZ'!V11)+N('APRIL'!V11)+N('MAI'!V11)+N('JUNI'!V11)+N('JULI'!V11)+N('AUGUST'!V11)+N('SEPTEMBER'!V11)+N('OKTOBER'!V11)+N('NOVEMBER'!V11)+N('DEZEMBER'!V11)) | F32: =IF($A32="","",N('JANUAR'!W11)+N('FEBRUAR'!W11)+N('MÄRZ'!W11)+N('APRIL'!W11)+N('MAI'!W11)+N('JUNI'!W11)+N('JULI'!W11)+N('AUGUST'!W11)+N('SEPTEMBER'!W11)+N('OKTOBER'!W11)+N('NOVEMBER'!W11)+N('DEZEMBER'!W11)) | G32: =IF($A32="","",N('JANUAR'!X11)+N('FEBRUAR'!X11)+N('MÄRZ'!X11)+N('APRIL'!X11)+N('MAI'!X11)+N('JUNI'!X11)+N('JULI'!X11)+N('AUGUST'!X11)+N('SEPTEMBER'!X11)+N('OKTOBER'!X11)+N('NOVEMBER'!X11)+N('DEZEMBER'!X11)) | H32: =IF($A32="","",N('JANUAR'!Y11)+N('FEBRUAR'!Y11)+N('MÄRZ'!Y11)+N('APRIL'!Y11)+N('MAI'!Y11)+N('JUNI'!Y11)+N('JULI'!Y11)+N('AUGUST'!Y11)+N('SEPTEMBER'!Y11)+N('OKTOBER'!Y11)+N('NOVEMBER'!Y11)+N('DEZEMBER'!Y11)) | I32: =IF($A32="","",N('JANUAR'!Z11)+N('FEBRUAR'!Z11)+N('MÄRZ'!Z11)+N('APRIL'!Z11)+N('MAI'!Z11)+N('JUNI'!Z11)+N('JULI'!Z11)+N('AUGUST'!Z11)+N('SEPTEMBER'!Z11)+N('OKTOBER'!Z11)+N('NOVEMBER'!Z11)+N('DEZEMBER'!Z11)) | ... K32: =IF($A32="","",N('JANUAR'!AB11)+N('FEBRUAR'!AB11)+N('MÄRZ'!AB11)+N('APRIL'!AB11)+N('MAI'!AB11)+N('JUNI'!AB11)+N('JULI'!AB11)+N('AUGUST'!AB11)+N('SEPTEMBER'!AB11)+N('OKTOBER'!AB11)+N('NOVEMBER'!AB11)+N('DEZEMBER'!AB11)) | L32: =IF(OR($A32="",$F$57=0),"",F32/$F$57)
A33: =IF(LISTEN!$A$8="","",LISTEN!$A$8) | B33: =IF($A33="","",N('JANUAR'!S12)+N('FEBRUAR'!S12)+N('MÄRZ'!S12)+N('APRIL'!S12)+N('MAI'!S12)+N('JUNI'!S12)+N('JULI'!S12)+N('AUGUST'!S12)+N('SEPTEMBER'!S12)+N('OKTOBER'!S12)+N('NOVEMBER'!S12)+N('DEZEMBER'!S12)) | C33: =IF($A33="","",N('JANUAR'!T12)+N('FEBRUAR'!T12)+N('MÄRZ'!T12)+N('APRIL'!T12)+N('MAI'!T12)+N('JUNI'!T12)+N('JULI'!T12)+N('AUGUST'!T12)+N('SEPTEMBER'!T12)+N('OKTOBER'!T12)+N('NOVEMBER'!T12)+N('DEZEMBER'!T12)) | D33: =IF($A33="","",N('JANUAR'!U12)+N('FEBRUAR'!U12)+N('MÄRZ'!U12)+N('APRIL'!U12)+N('MAI'!U12)+N('JUNI'!U12)+N('JULI'!U12)+N('AUGUST'!U12)+N('SEPTEMBER'!U12)+N('OKTOBER'!U12)+N('NOVEMBER'!U12)+N('DEZEMBER'!U12)) | E33: =IF($A33="","",N('JANUAR'!V12)+N('FEBRUAR'!V12)+N('MÄRZ'!V12)+N('APRIL'!V12)+N('MAI'!V12)+N('JUNI'!V12)+N('JULI'!V12)+N('AUGUST'!V12)+N('SEPTEMBER'!V12)+N('OKTOBER'!V12)+N('NOVEMBER'!V12)+N('DEZEMBER'!V12)) | F33: =IF($A33="","",N('JANUAR'!W12)+N('FEBRUAR'!W12)+N('MÄRZ'!W12)+N('APRIL'!W12)+N('MAI'!W12)+N('JUNI'!W12)+N('JULI'!W12)+N('AUGUST'!W12)+N('SEPTEMBER'!W12)+N('OKTOBER'!W12)+N('NOVEMBER'!W12)+N('DEZEMBER'!W12)) | G33: =IF($A33="","",N('JANUAR'!X12)+N('FEBRUAR'!X12)+N('MÄRZ'!X12)+N('APRIL'!X12)+N('MAI'!X12)+N('JUNI'!X12)+N('JULI'!X12)+N('AUGUST'!X12)+N('SEPTEMBER'!X12)+N('OKTOBER'!X12)+N('NOVEMBER'!X12)+N('DEZEMBER'!X12)) | H33: =IF($A33="","",N('JANUAR'!Y12)+N('FEBRUAR'!Y12)+N('MÄRZ'!Y12)+N('APRIL'!Y12)+N('MAI'!Y12)+N('JUNI'!Y12)+N('JULI'!Y12)+N('AUGUST'!Y12)+N('SEPTEMBER'!Y12)+N('OKTOBER'!Y12)+N('NOVEMBER'!Y12)+N('DEZEMBER'!Y12)) | I33: =IF($A33="","",N('JANUAR'!Z12)+N('FEBRUAR'!Z12)+N('MÄRZ'!Z12)+N('APRIL'!Z12)+N('MAI'!Z12)+N('JUNI'!Z12)+N('JULI'!Z12)+N('AUGUST'!Z12)+N('SEPTEMBER'!Z12)+N('OKTOBER'!Z12)+N('NOVEMBER'!Z12)+N('DEZEMBER'!Z12)) | ... K33: =IF($A33="","",N('JANUAR'!AB12)+N('FEBRUAR'!AB12)+N('MÄRZ'!AB12)+N('APRIL'!AB12)+N('MAI'!AB12)+N('JUNI'!AB12)+N('JULI'!AB12)+N('AUGUST'!AB12)+N('SEPTEMBER'!AB12)+N('OKTOBER'!AB12)+N('NOVEMBER'!AB12)+N('DEZEMBER'!AB12)) | L33: =IF(OR($A33="",$F$57=0),"",F33/$F$57)
A34: =IF(LISTEN!$A$9="","",LISTEN!$A$9) | B34: =IF($A34="","",N('JANUAR'!S13)+N('FEBRUAR'!S13)+N('MÄRZ'!S13)+N('APRIL'!S13)+N('MAI'!S13)+N('JUNI'!S13)+N('JULI'!S13)+N('AUGUST'!S13)+N('SEPTEMBER'!S13)+N('OKTOBER'!S13)+N('NOVEMBER'!S13)+N('DEZEMBER'!S13)) | C34: =IF($A34="","",N('JANUAR'!T13)+N('FEBRUAR'!T13)+N('MÄRZ'!T13)+N('APRIL'!T13)+N('MAI'!T13)+N('JUNI'!T13)+N('JULI'!T13)+N('AUGUST'!T13)+N('SEPTEMBER'!T13)+N('OKTOBER'!T13)+N('NOVEMBER'!T13)+N('DEZEMBER'!T13)) | D34: =IF($A34="","",N('JANUAR'!U13)+N('FEBRUAR'!U13)+N('MÄRZ'!U13)+N('APRIL'!U13)+N('MAI'!U13)+N('JUNI'!U13)+N('JULI'!U13)+N('AUGUST'!U13)+N('SEPTEMBER'!U13)+N('OKTOBER'!U13)+N('NOVEMBER'!U13)+N('DEZEMBER'!U13)) | E34: =IF($A34="","",N('JANUAR'!V13)+N('FEBRUAR'!V13)+N('MÄRZ'!V13)+N('APRIL'!V13)+N('MAI'!V13)+N('JUNI'!V13)+N('JULI'!V13)+N('AUGUST'!V13)+N('SEPTEMBER'!V13)+N('OKTOBER'!V13)+N('NOVEMBER'!V13)+N('DEZEMBER'!V13)) | F34: =IF($A34="","",N('JANUAR'!W13)+N('FEBRUAR'!W13)+N('MÄRZ'!W13)+N('APRIL'!W13)+N('MAI'!W13)+N('JUNI'!W13)+N('JULI'!W13)+N('AUGUST'!W13)+N('SEPTEMBER'!W13)+N('OKTOBER'!W13)+N('NOVEMBER'!W13)+N('DEZEMBER'!W13)) | G34: =IF($A34="","",N('JANUAR'!X13)+N('FEBRUAR'!X13)+N('MÄRZ'!X13)+N('APRIL'!X13)+N('MAI'!X13)+N('JUNI'!X13)+N('JULI'!X13)+N('AUGUST'!X13)+N('SEPTEMBER'!X13)+N('OKTOBER'!X13)+N('NOVEMBER'!X13)+N('DEZEMBER'!X13)) | H34: =IF($A34="","",N('JANUAR'!Y13)+N('FEBRUAR'!Y13)+N('MÄRZ'!Y13)+N('APRIL'!Y13)+N('MAI'!Y13)+N('JUNI'!Y13)+N('JULI'!Y13)+N('AUGUST'!Y13)+N('SEPTEMBER'!Y13)+N('OKTOBER'!Y13)+N('NOVEMBER'!Y13)+N('DEZEMBER'!Y13)) | I34: =IF($A34="","",N('JANUAR'!Z13)+N('FEBRUAR'!Z13)+N('MÄRZ'!Z13)+N('APRIL'!Z13)+N('MAI'!Z13)+N('JUNI'!Z13)+N('JULI'!Z13)+N('AUGUST'!Z13)+N('SEPTEMBER'!Z13)+N('OKTOBER'!Z13)+N('NOVEMBER'!Z13)+N('DEZEMBER'!Z13)) | ... K34: =IF($A34="","",N('JANUAR'!AB13)+N('FEBRUAR'!AB13)+N('MÄRZ'!AB13)+N('APRIL'!AB13)+N('MAI'!AB13)+N('JUNI'!AB13)+N('JULI'!AB13)+N('AUGUST'!AB13)+N('SEPTEMBER'!AB13)+N('OKTOBER'!AB13)+N('NOVEMBER'!AB13)+N('DEZEMBER'!AB13)) | L34: =IF(OR($A34="",$F$57=0),"",F34/$F$57)
A35: =IF(LISTEN!$A$10="","",LISTEN!$A$10) | B35: =IF($A35="","",N('JANUAR'!S14)+N('FEBRUAR'!S14)+N('MÄRZ'!S14)+N('APRIL'!S14)+N('MAI'!S14)+N('JUNI'!S14)+N('JULI'!S14)+N('AUGUST'!S14)+N('SEPTEMBER'!S14)+N('OKTOBER'!S14)+N('NOVEMBER'!S14)+N('DEZEMBER'!S14)) | C35: =IF($A35="","",N('JANUAR'!T14)+N('FEBRUAR'!T14)+N('MÄRZ'!T14)+N('APRIL'!T14)+N('MAI'!T14)+N('JUNI'!T14)+N('JULI'!T14)+N('AUGUST'!T14)+N('SEPTEMBER'!T14)+N('OKTOBER'!T14)+N('NOVEMBER'!T14)+N('DEZEMBER'!T14)) | D35: =IF($A35="","",N('JANUAR'!U14)+N('FEBRUAR'!U14)+N('MÄRZ'!U14)+N('APRIL'!U14)+N('MAI'!U14)+N('JUNI'!U14)+N('JULI'!U14)+N('AUGUST'!U14)+N('SEPTEMBER'!U14)+N('OKTOBER'!U14)+N('NOVEMBER'!U14)+N('DEZEMBER'!U14)) | E35: =IF($A35="","",N('JANUAR'!V14)+N('FEBRUAR'!V14)+N('MÄRZ'!V14)+N('APRIL'!V14)+N('MAI'!V14)+N('JUNI'!V14)+N('JULI'!V14)+N('AUGUST'!V14)+N('SEPTEMBER'!V14)+N('OKTOBER'!V14)+N('NOVEMBER'!V14)+N('DEZEMBER'!V14)) | F35: =IF($A35="","",N('JANUAR'!W14)+N('FEBRUAR'!W14)+N('MÄRZ'!W14)+N('APRIL'!W14)+N('MAI'!W14)+N('JUNI'!W14)+N('JULI'!W14)+N('AUGUST'!W14)+N('SEPTEMBER'!W14)+N('OKTOBER'!W14)+N('NOVEMBER'!W14)+N('DEZEMBER'!W14)) | G35: =IF($A35="","",N('JANUAR'!X14)+N('FEBRUAR'!X14)+N('MÄRZ'!X14)+N('APRIL'!X14)+N('MAI'!X14)+N('JUNI'!X14)+N('JULI'!X14)+N('AUGUST'!X14)+N('SEPTEMBER'!X14)+N('OKTOBER'!X14)+N('NOVEMBER'!X14)+N('DEZEMBER'!X14)) | H35: =IF($A35="","",N('JANUAR'!Y14)+N('FEBRUAR'!Y14)+N('MÄRZ'!Y14)+N('APRIL'!Y14)+N('MAI'!Y14)+N('JUNI'!Y14)+N('JULI'!Y14)+N('AUGUST'!Y14)+N('SEPTEMBER'!Y14)+N('OKTOBER'!Y14)+N('NOVEMBER'!Y14)+N('DEZEMBER'!Y14)) | I35: =IF($A35="","",N('JANUAR'!Z14)+N('FEBRUAR'!Z14)+N('MÄRZ'!Z14)+N('APRIL'!Z14)+N('MAI'!Z14)+N('JUNI'!Z14)+N('JULI'!Z14)+N('AUGUST'!Z14)+N('SEPTEMBER'!Z14)+N('OKTOBER'!Z14)+N('NOVEMBER'!Z14)+N('DEZEMBER'!Z14)) | ... K35: =IF($A35="","",N('JANUAR'!AB14)+N('FEBRUAR'!AB14)+N('MÄRZ'!AB14)+N('APRIL'!AB14)+N('MAI'!AB14)+N('JUNI'!AB14)+N('JULI'!AB14)+N('AUGUST'!AB14)+N('SEPTEMBER'!AB14)+N('OKTOBER'!AB14)+N('NOVEMBER'!AB14)+N('DEZEMBER'!AB14)) | L35: =IF(OR($A35="",$F$57=0),"",F35/$F$57)
A36: =IF(LISTEN!$A$11="","",LISTEN!$A$11) | B36: =IF($A36="","",N('JANUAR'!S15)+N('FEBRUAR'!S15)+N('MÄRZ'!S15)+N('APRIL'!S15)+N('MAI'!S15)+N('JUNI'!S15)+N('JULI'!S15)+N('AUGUST'!S15)+N('SEPTEMBER'!S15)+N('OKTOBER'!S15)+N('NOVEMBER'!S15)+N('DEZEMBER'!S15)) | C36: =IF($A36="","",N('JANUAR'!T15)+N('FEBRUAR'!T15)+N('MÄRZ'!T15)+N('APRIL'!T15)+N('MAI'!T15)+N('JUNI'!T15)+N('JULI'!T15)+N('AUGUST'!T15)+N('SEPTEMBER'!T15)+N('OKTOBER'!T15)+N('NOVEMBER'!T15)+N('DEZEMBER'!T15)) | D36: =IF($A36="","",N('JANUAR'!U15)+N('FEBRUAR'!U15)+N('MÄRZ'!U15)+N('APRIL'!U15)+N('MAI'!U15)+N('JUNI'!U15)+N('JULI'!U15)+N('AUGUST'!U15)+N('SEPTEMBER'!U15)+N('OKTOBER'!U15)+N('NOVEMBER'!U15)+N('DEZEMBER'!U15)) | E36: =IF($A36="","",N('JANUAR'!V15)+N('FEBRUAR'!V15)+N('MÄRZ'!V15)+N('APRIL'!V15)+N('MAI'!V15)+N('JUNI'!V15)+N('JULI'!V15)+N('AUGUST'!V15)+N('SEPTEMBER'!V15)+N('OKTOBER'!V15)+N('NOVEMBER'!V15)+N('DEZEMBER'!V15)) | F36: =IF($A36="","",N('JANUAR'!W15)+N('FEBRUAR'!W15)+N('MÄRZ'!W15)+N('APRIL'!W15)+N('MAI'!W15)+N('JUNI'!W15)+N('JULI'!W15)+N('AUGUST'!W15)+N('SEPTEMBER'!W15)+N('OKTOBER'!W15)+N('NOVEMBER'!W15)+N('DEZEMBER'!W15)) | G36: =IF($A36="","",N('JANUAR'!X15)+N('FEBRUAR'!X15)+N('MÄRZ'!X15)+N('APRIL'!X15)+N('MAI'!X15)+N('JUNI'!X15)+N('JULI'!X15)+N('AUGUST'!X15)+N('SEPTEMBER'!X15)+N('OKTOBER'!X15)+N('NOVEMBER'!X15)+N('DEZEMBER'!X15)) | H36: =IF($A36="","",N('JANUAR'!Y15)+N('FEBRUAR'!Y15)+N('MÄRZ'!Y15)+N('APRIL'!Y15)+N('MAI'!Y15)+N('JUNI'!Y15)+N('JULI'!Y15)+N('AUGUST'!Y15)+N('SEPTEMBER'!Y15)+N('OKTOBER'!Y15)+N('NOVEMBER'!Y15)+N('DEZEMBER'!Y15)) | I36: =IF($A36="","",N('JANUAR'!Z15)+N('FEBRUAR'!Z15)+N('MÄRZ'!Z15)+N('APRIL'!Z15)+N('MAI'!Z15)+N('JUNI'!Z15)+N('JULI'!Z15)+N('AUGUST'!Z15)+N('SEPTEMBER'!Z15)+N('OKTOBER'!Z15)+N('NOVEMBER'!Z15)+N('DEZEMBER'!Z15)) | ... K36: =IF($A36="","",N('JANUAR'!AB15)+N('FEBRUAR'!AB15)+N('MÄRZ'!AB15)+N('APRIL'!AB15)+N('MAI'!AB15)+N('JUNI'!AB15)+N('JULI'!AB15)+N('AUGUST'!AB15)+N('SEPTEMBER'!AB15)+N('OKTOBER'!AB15)+N('NOVEMBER'!AB15)+N('DEZEMBER'!AB15)) | L36: =IF(OR($A36="",$F$57=0),"",F36/$F$57)
A37: =IF(LISTEN!$A$12="","",LISTEN!$A$12) | B37: =IF($A37="","",N('JANUAR'!S16)+N('FEBRUAR'!S16)+N('MÄRZ'!S16)+N('APRIL'!S16)+N('MAI'!S16)+N('JUNI'!S16)+N('JULI'!S16)+N('AUGUST'!S16)+N('SEPTEMBER'!S16)+N('OKTOBER'!S16)+N('NOVEMBER'!S16)+N('DEZEMBER'!S16)) | C37: =IF($A37="","",N('JANUAR'!T16)+N('FEBRUAR'!T16)+N('MÄRZ'!T16)+N('APRIL'!T16)+N('MAI'!T16)+N('JUNI'!T16)+N('JULI'!T16)+N('AUGUST'!T16)+N('SEPTEMBER'!T16)+N('OKTOBER'!T16)+N('NOVEMBER'!T16)+N('DEZEMBER'!T16)) | D37: =IF($A37="","",N('JANUAR'!U16)+N('FEBRUAR'!U16)+N('MÄRZ'!U16)+N('APRIL'!U16)+N('MAI'!U16)+N('JUNI'!U16)+N('JULI'!U16)+N('AUGUST'!U16)+N('SEPTEMBER'!U16)+N('OKTOBER'!U16)+N('NOVEMBER'!U16)+N('DEZEMBER'!U16)) | E37: =IF($A37="","",N('JANUAR'!V16)+N('FEBRUAR'!V16)+N('MÄRZ'!V16)+N('APRIL'!V16)+N('MAI'!V16)+N('JUNI'!V16)+N('JULI'!V16)+N('AUGUST'!V16)+N('SEPTEMBER'!V16)+N('OKTOBER'!V16)+N('NOVEMBER'!V16)+N('DEZEMBER'!V16)) | F37: =IF($A37="","",N('JANUAR'!W16)+N('FEBRUAR'!W16)+N('MÄRZ'!W16)+N('APRIL'!W16)+N('MAI'!W16)+N('JUNI'!W16)+N('JULI'!W16)+N('AUGUST'!W16)+N('SEPTEMBER'!W16)+N('OKTOBER'!W16)+N('NOVEMBER'!W16)+N('DEZEMBER'!W16)) | G37: =IF($A37="","",N('JANUAR'!X16)+N('FEBRUAR'!X16)+N('MÄRZ'!X16)+N('APRIL'!X16)+N('MAI'!X16)+N('JUNI'!X16)+N('JULI'!X16)+N('AUGUST'!X16)+N('SEPTEMBER'!X16)+N('OKTOBER'!X16)+N('NOVEMBER'!X16)+N('DEZEMBER'!X16)) | H37: =IF($A37="","",N('JANUAR'!Y16)+N('FEBRUAR'!Y16)+N('MÄRZ'!Y16)+N('APRIL'!Y16)+N('MAI'!Y16)+N('JUNI'!Y16)+N('JULI'!Y16)+N('AUGUST'!Y16)+N('SEPTEMBER'!Y16)+N('OKTOBER'!Y16)+N('NOVEMBER'!Y16)+N('DEZEMBER'!Y16)) | I37: =IF($A37="","",N('JANUAR'!Z16)+N('FEBRUAR'!Z16)+N('MÄRZ'!Z16)+N('APRIL'!Z16)+N('MAI'!Z16)+N('JUNI'!Z16)+N('JULI'!Z16)+N('AUGUST'!Z16)+N('SEPTEMBER'!Z16)+N('OKTOBER'!Z16)+N('NOVEMBER'!Z16)+N('DEZEMBER'!Z16)) | ... K37: =IF($A37="","",N('JANUAR'!AB16)+N('FEBRUAR'!AB16)+N('MÄRZ'!AB16)+N('APRIL'!AB16)+N('MAI'!AB16)+N('JUNI'!AB16)+N('JULI'!AB16)+N('AUGUST'!AB16)+N('SEPTEMBER'!AB16)+N('OKTOBER'!AB16)+N('NOVEMBER'!AB16)+N('DEZEMBER'!AB16)) | L37: =IF(OR($A37="",$F$57=0),"",F37/$F$57)
A38: =IF(LISTEN!$A$13="","",LISTEN!$A$13) | B38: =IF($A38="","",N('JANUAR'!S17)+N('FEBRUAR'!S17)+N('MÄRZ'!S17)+N('APRIL'!S17)+N('MAI'!S17)+N('JUNI'!S17)+N('JULI'!S17)+N('AUGUST'!S17)+N('SEPTEMBER'!S17)+N('OKTOBER'!S17)+N('NOVEMBER'!S17)+N('DEZEMBER'!S17)) | C38: =IF($A38="","",N('JANUAR'!T17)+N('FEBRUAR'!T17)+N('MÄRZ'!T17)+N('APRIL'!T17)+N('MAI'!T17)+N('JUNI'!T17)+N('JULI'!T17)+N('AUGUST'!T17)+N('SEPTEMBER'!T17)+N('OKTOBER'!T17)+N('NOVEMBER'!T17)+N('DEZEMBER'!T17)) | D38: =IF($A38="","",N('JANUAR'!U17)+N('FEBRUAR'!U17)+N('MÄRZ'!U17)+N('APRIL'!U17)+N('MAI'!U17)+N('JUNI'!U17)+N('JULI'!U17)+N('AUGUST'!U17)+N('SEPTEMBER'!U17)+N('OKTOBER'!U17)+N('NOVEMBER'!U17)+N('DEZEMBER'!U17)) | E38: =IF($A38="","",N('JANUAR'!V17)+N('FEBRUAR'!V17)+N('MÄRZ'!V17)+N('APRIL'!V17)+N('MAI'!V17)+N('JUNI'!V17)+N('JULI'!V17)+N('AUGUST'!V17)+N('SEPTEMBER'!V17)+N('OKTOBER'!V17)+N('NOVEMBER'!V17)+N('DEZEMBER'!V17)) | F38: =IF($A38="","",N('JANUAR'!W17)+N('FEBRUAR'!W17)+N('MÄRZ'!W17)+N('APRIL'!W17)+N('MAI'!W17)+N('JUNI'!W17)+N('JULI'!W17)+N('AUGUST'!W17)+N('SEPTEMBER'!W17)+N('OKTOBER'!W17)+N('NOVEMBER'!W17)+N('DEZEMBER'!W17)) | G38: =IF($A38="","",N('JANUAR'!X17)+N('FEBRUAR'!X17)+N('MÄRZ'!X17)+N('APRIL'!X17)+N('MAI'!X17)+N('JUNI'!X17)+N('JULI'!X17)+N('AUGUST'!X17)+N('SEPTEMBER'!X17)+N('OKTOBER'!X17)+N('NOVEMBER'!X17)+N('DEZEMBER'!X17)) | H38: =IF($A38="","",N('JANUAR'!Y17)+N('FEBRUAR'!Y17)+N('MÄRZ'!Y17)+N('APRIL'!Y17)+N('MAI'!Y17)+N('JUNI'!Y17)+N('JULI'!Y17)+N('AUGUST'!Y17)+N('SEPTEMBER'!Y17)+N('OKTOBER'!Y17)+N('NOVEMBER'!Y17)+N('DEZEMBER'!Y17)) | I38: =IF($A38="","",N('JANUAR'!Z17)+N('FEBRUAR'!Z17)+N('MÄRZ'!Z17)+N('APRIL'!Z17)+N('MAI'!Z17)+N('JUNI'!Z17)+N('JULI'!Z17)+N('AUGUST'!Z17)+N('SEPTEMBER'!Z17)+N('OKTOBER'!Z17)+N('NOVEMBER'!Z17)+N('DEZEMBER'!Z17)) | ... K38: =IF($A38="","",N('JANUAR'!AB17)+N('FEBRUAR'!AB17)+N('MÄRZ'!AB17)+N('APRIL'!AB17)+N('MAI'!AB17)+N('JUNI'!AB17)+N('JULI'!AB17)+N('AUGUST'!AB17)+N('SEPTEMBER'!AB17)+N('OKTOBER'!AB17)+N('NOVEMBER'!AB17)+N('DEZEMBER'!AB17)) | L38: =IF(OR($A38="",$F$57=0),"",F38/$F$57)
A39: =IF(LISTEN!$A$14="","",LISTEN!$A$14) | B39: =IF($A39="","",N('JANUAR'!S18)+N('FEBRUAR'!S18)+N('MÄRZ'!S18)+N('APRIL'!S18)+N('MAI'!S18)+N('JUNI'!S18)+N('JULI'!S18)+N('AUGUST'!S18)+N('SEPTEMBER'!S18)+N('OKTOBER'!S18)+N('NOVEMBER'!S18)+N('DEZEMBER'!S18)) | C39: =IF($A39="","",N('JANUAR'!T18)+N('FEBRUAR'!T18)+N('MÄRZ'!T18)+N('APRIL'!T18)+N('MAI'!T18)+N('JUNI'!T18)+N('JULI'!T18)+N('AUGUST'!T18)+N('SEPTEMBER'!T18)+N('OKTOBER'!T18)+N('NOVEMBER'!T18)+N('DEZEMBER'!T18)) | D39: =IF($A39="","",N('JANUAR'!U18)+N('FEBRUAR'!U18)+N('MÄRZ'!U18)+N('APRIL'!U18)+N('MAI'!U18)+N('JUNI'!U18)+N('JULI'!U18)+N('AUGUST'!U18)+N('SEPTEMBER'!U18)+N('OKTOBER'!U18)+N('NOVEMBER'!U18)+N('DEZEMBER'!U18)) | E39: =IF($A39="","",N('JANUAR'!V18)+N('FEBRUAR'!V18)+N('MÄRZ'!V18)+N('APRIL'!V18)+N('MAI'!V18)+N('JUNI'!V18)+N('JULI'!V18)+N('AUGUST'!V18)+N('SEPTEMBER'!V18)+N('OKTOBER'!V18)+N('NOVEMBER'!V18)+N('DEZEMBER'!V18)) | F39: =IF($A39="","",N('JANUAR'!W18)+N('FEBRUAR'!W18)+N('MÄRZ'!W18)+N('APRIL'!W18)+N('MAI'!W18)+N('JUNI'!W18)+N('JULI'!W18)+N('AUGUST'!W18)+N('SEPTEMBER'!W18)+N('OKTOBER'!W18)+N('NOVEMBER'!W18)+N('DEZEMBER'!W18)) | G39: =IF($A39="","",N('JANUAR'!X18)+N('FEBRUAR'!X18)+N('MÄRZ'!X18)+N('APRIL'!X18)+N('MAI'!X18)+N('JUNI'!X18)+N('JULI'!X18)+N('AUGUST'!X18)+N('SEPTEMBER'!X18)+N('OKTOBER'!X18)+N('NOVEMBER'!X18)+N('DEZEMBER'!X18)) | H39: =IF($A39="","",N('JANUAR'!Y18)+N('FEBRUAR'!Y18)+N('MÄRZ'!Y18)+N('APRIL'!Y18)+N('MAI'!Y18)+N('JUNI'!Y18)+N('JULI'!Y18)+N('AUGUST'!Y18)+N('SEPTEMBER'!Y18)+N('OKTOBER'!Y18)+N('NOVEMBER'!Y18)+N('DEZEMBER'!Y18)) | I39: =IF($A39="","",N('JANUAR'!Z18)+N('FEBRUAR'!Z18)+N('MÄRZ'!Z18)+N('APRIL'!Z18)+N('MAI'!Z18)+N('JUNI'!Z18)+N('JULI'!Z18)+N('AUGUST'!Z18)+N('SEPTEMBER'!Z18)+N('OKTOBER'!Z18)+N('NOVEMBER'!Z18)+N('DEZEMBER'!Z18)) | ... K39: =IF($A39="","",N('JANUAR'!AB18)+N('FEBRUAR'!AB18)+N('MÄRZ'!AB18)+N('APRIL'!AB18)+N('MAI'!AB18)+N('JUNI'!AB18)+N('JULI'!AB18)+N('AUGUST'!AB18)+N('SEPTEMBER'!AB18)+N('OKTOBER'!AB18)+N('NOVEMBER'!AB18)+N('DEZEMBER'!AB18)) | L39: =IF(OR($A39="",$F$57=0),"",F39/$F$57)
A40: =IF(LISTEN!$A$15="","",LISTEN!$A$15) | B40: =IF($A40="","",N('JANUAR'!S19)+N('FEBRUAR'!S19)+N('MÄRZ'!S19)+N('APRIL'!S19)+N('MAI'!S19)+N('JUNI'!S19)+N('JULI'!S19)+N('AUGUST'!S19)+N('SEPTEMBER'!S19)+N('OKTOBER'!S19)+N('NOVEMBER'!S19)+N('DEZEMBER'!S19)) | C40: =IF($A40="","",N('JANUAR'!T19)+N('FEBRUAR'!T19)+N('MÄRZ'!T19)+N('APRIL'!T19)+N('MAI'!T19)+N('JUNI'!T19)+N('JULI'!T19)+N('AUGUST'!T19)+N('SEPTEMBER'!T19)+N('OKTOBER'!T19)+N('NOVEMBER'!T19)+N('DEZEMBER'!T19)) | D40: =IF($A40="","",N('JANUAR'!U19)+N('FEBRUAR'!U19)+N('MÄRZ'!U19)+N('APRIL'!U19)+N('MAI'!U19)+N('JUNI'!U19)+N('JULI'!U19)+N('AUGUST'!U19)+N('SEPTEMBER'!U19)+N('OKTOBER'!U19)+N('NOVEMBER'!U19)+N('DEZEMBER'!U19)) | E40: =IF($A40="","",N('JANUAR'!V19)+N('FEBRUAR'!V19)+N('MÄRZ'!V19)+N('APRIL'!V19)+N('MAI'!V19)+N('JUNI'!V19)+N('JULI'!V19)+N('AUGUST'!V19)+N('SEPTEMBER'!V19)+N('OKTOBER'!V19)+N('NOVEMBER'!V19)+N('DEZEMBER'!V19)) | F40: =IF($A40="","",N('JANUAR'!W19)+N('FEBRUAR'!W19)+N('MÄRZ'!W19)+N('APRIL'!W19)+N('MAI'!W19)+N('JUNI'!W19)+N('JULI'!W19)+N('AUGUST'!W19)+N('SEPTEMBER'!W19)+N('OKTOBER'!W19)+N('NOVEMBER'!W19)+N('DEZEMBER'!W19)) | G40: =IF($A40="","",N('JANUAR'!X19)+N('FEBRUAR'!X19)+N('MÄRZ'!X19)+N('APRIL'!X19)+N('MAI'!X19)+N('JUNI'!X19)+N('JULI'!X19)+N('AUGUST'!X19)+N('SEPTEMBER'!X19)+N('OKTOBER'!X19)+N('NOVEMBER'!X19)+N('DEZEMBER'!X19)) | H40: =IF($A40="","",N('JANUAR'!Y19)+N('FEBRUAR'!Y19)+N('MÄRZ'!Y19)+N('APRIL'!Y19)+N('MAI'!Y19)+N('JUNI'!Y19)+N('JULI'!Y19)+N('AUGUST'!Y19)+N('SEPTEMBER'!Y19)+N('OKTOBER'!Y19)+N('NOVEMBER'!Y19)+N('DEZEMBER'!Y19)) | I40: =IF($A40="","",N('JANUAR'!Z19)+N('FEBRUAR'!Z19)+N('MÄRZ'!Z19)+N('APRIL'!Z19)+N('MAI'!Z19)+N('JUNI'!Z19)+N('JULI'!Z19)+N('AUGUST'!Z19)+N('SEPTEMBER'!Z19)+N('OKTOBER'!Z19)+N('NOVEMBER'!Z19)+N('DEZEMBER'!Z19)) | ... K40: =IF($A40="","",N('JANUAR'!AB19)+N('FEBRUAR'!AB19)+N('MÄRZ'!AB19)+N('APRIL'!AB19)+N('MAI'!AB19)+N('JUNI'!AB19)+N('JULI'!AB19)+N('AUGUST'!AB19)+N('SEPTEMBER'!AB19)+N('OKTOBER'!AB19)+N('NOVEMBER'!AB19)+N('DEZEMBER'!AB19)) | L40: =IF(OR($A40="",$F$57=0),"",F40/$F$57)
A41: =IF(LISTEN!$A$16="","",LISTEN!$A$16) | B41: =IF($A41="","",N('JANUAR'!S20)+N('FEBRUAR'!S20)+N('MÄRZ'!S20)+N('APRIL'!S20)+N('MAI'!S20)+N('JUNI'!S20)+N('JULI'!S20)+N('AUGUST'!S20)+N('SEPTEMBER'!S20)+N('OKTOBER'!S20)+N('NOVEMBER'!S20)+N('DEZEMBER'!S20)) | C41: =IF($A41="","",N('JANUAR'!T20)+N('FEBRUAR'!T20)+N('MÄRZ'!T20)+N('APRIL'!T20)+N('MAI'!T20)+N('JUNI'!T20)+N('JULI'!T20)+N('AUGUST'!T20)+N('SEPTEMBER'!T20)+N('OKTOBER'!T20)+N('NOVEMBER'!T20)+N('DEZEMBER'!T20)) | D41: =IF($A41="","",N('JANUAR'!U20)+N('FEBRUAR'!U20)+N('MÄRZ'!U20)+N('APRIL'!U20)+N('MAI'!U20)+N('JUNI'!U20)+N('JULI'!U20)+N('AUGUST'!U20)+N('SEPTEMBER'!U20)+N('OKTOBER'!U20)+N('NOVEMBER'!U20)+N('DEZEMBER'!U20)) | E41: =IF($A41="","",N('JANUAR'!V20)+N('FEBRUAR'!V20)+N('MÄRZ'!V20)+N('APRIL'!V20)+N('MAI'!V20)+N('JUNI'!V20)+N('JULI'!V20)+N('AUGUST'!V20)+N('SEPTEMBER'!V20)+N('OKTOBER'!V20)+N('NOVEMBER'!V20)+N('DEZEMBER'!V20)) | F41: =IF($A41="","",N('JANUAR'!W20)+N('FEBRUAR'!W20)+N('MÄRZ'!W20)+N('APRIL'!W20)+N('MAI'!W20)+N('JUNI'!W20)+N('JULI'!W20)+N('AUGUST'!W20)+N('SEPTEMBER'!W20)+N('OKTOBER'!W20)+N('NOVEMBER'!W20)+N('DEZEMBER'!W20)) | G41: =IF($A41="","",N('JANUAR'!X20)+N('FEBRUAR'!X20)+N('MÄRZ'!X20)+N('APRIL'!X20)+N('MAI'!X20)+N('JUNI'!X20)+N('JULI'!X20)+N('AUGUST'!X20)+N('SEPTEMBER'!X20)+N('OKTOBER'!X20)+N('NOVEMBER'!X20)+N('DEZEMBER'!X20)) | H41: =IF($A41="","",N('JANUAR'!Y20)+N('FEBRUAR'!Y20)+N('MÄRZ'!Y20)+N('APRIL'!Y20)+N('MAI'!Y20)+N('JUNI'!Y20)+N('JULI'!Y20)+N('AUGUST'!Y20)+N('SEPTEMBER'!Y20)+N('OKTOBER'!Y20)+N('NOVEMBER'!Y20)+N('DEZEMBER'!Y20)) | I41: =IF($A41="","",N('JANUAR'!Z20)+N('FEBRUAR'!Z20)+N('MÄRZ'!Z20)+N('APRIL'!Z20)+N('MAI'!Z20)+N('JUNI'!Z20)+N('JULI'!Z20)+N('AUGUST'!Z20)+N('SEPTEMBER'!Z20)+N('OKTOBER'!Z20)+N('NOVEMBER'!Z20)+N('DEZEMBER'!Z20)) | ... K41: =IF($A41="","",N('JANUAR'!AB20)+N('FEBRUAR'!AB20)+N('MÄRZ'!AB20)+N('APRIL'!AB20)+N('MAI'!AB20)+N('JUNI'!AB20)+N('JULI'!AB20)+N('AUGUST'!AB20)+N('SEPTEMBER'!AB20)+N('OKTOBER'!AB20)+N('NOVEMBER'!AB20)+N('DEZEMBER'!AB20)) | L41: =IF(OR($A41="",$F$57=0),"",F41/$F$57)
A42: =IF(LISTEN!$A$17="","",LISTEN!$A$17) | B42: =IF($A42="","",N('JANUAR'!S21)+N('FEBRUAR'!S21)+N('MÄRZ'!S21)+N('APRIL'!S21)+N('MAI'!S21)+N('JUNI'!S21)+N('JULI'!S21)+N('AUGUST'!S21)+N('SEPTEMBER'!S21)+N('OKTOBER'!S21)+N('NOVEMBER'!S21)+N('DEZEMBER'!S21)) | C42: =IF($A42="","",N('JANUAR'!T21)+N('FEBRUAR'!T21)+N('MÄRZ'!T21)+N('APRIL'!T21)+N('MAI'!T21)+N('JUNI'!T21)+N('JULI'!T21)+N('AUGUST'!T21)+N('SEPTEMBER'!T21)+N('OKTOBER'!T21)+N('NOVEMBER'!T21)+N('DEZEMBER'!T21)) | D42: =IF($A42="","",N('JANUAR'!U21)+N('FEBRUAR'!U21)+N('MÄRZ'!U21)+N('APRIL'!U21)+N('MAI'!U21)+N('JUNI'!U21)+N('JULI'!U21)+N('AUGUST'!U21)+N('SEPTEMBER'!U21)+N('OKTOBER'!U21)+N('NOVEMBER'!U21)+N('DEZEMBER'!U21)) | E42: =IF($A42="","",N('JANUAR'!V21)+N('FEBRUAR'!V21)+N('MÄRZ'!V21)+N('APRIL'!V21)+N('MAI'!V21)+N('JUNI'!V21)+N('JULI'!V21)+N('AUGUST'!V21)+N('SEPTEMBER'!V21)+N('OKTOBER'!V21)+N('NOVEMBER'!V21)+N('DEZEMBER'!V21)) | F42: =IF($A42="","",N('JANUAR'!W21)+N('FEBRUAR'!W21)+N('MÄRZ'!W21)+N('APRIL'!W21)+N('MAI'!W21)+N('JUNI'!W21)+N('JULI'!W21)+N('AUGUST'!W21)+N('SEPTEMBER'!W21)+N('OKTOBER'!W21)+N('NOVEMBER'!W21)+N('DEZEMBER'!W21)) | G42: =IF($A42="","",N('JANUAR'!X21)+N('FEBRUAR'!X21)+N('MÄRZ'!X21)+N('APRIL'!X21)+N('MAI'!X21)+N('JUNI'!X21)+N('JULI'!X21)+N('AUGUST'!X21)+N('SEPTEMBER'!X21)+N('OKTOBER'!X21)+N('NOVEMBER'!X21)+N('DEZEMBER'!X21)) | H42: =IF($A42="","",N('JANUAR'!Y21)+N('FEBRUAR'!Y21)+N('MÄRZ'!Y21)+N('APRIL'!Y21)+N('MAI'!Y21)+N('JUNI'!Y21)+N('JULI'!Y21)+N('AUGUST'!Y21)+N('SEPTEMBER'!Y21)+N('OKTOBER'!Y21)+N('NOVEMBER'!Y21)+N('DEZEMBER'!Y21)) | I42: =IF($A42="","",N('JANUAR'!Z21)+N('FEBRUAR'!Z21)+N('MÄRZ'!Z21)+N('APRIL'!Z21)+N('MAI'!Z21)+N('JUNI'!Z21)+N('JULI'!Z21)+N('AUGUST'!Z21)+N('SEPTEMBER'!Z21)+N('OKTOBER'!Z21)+N('NOVEMBER'!Z21)+N('DEZEMBER'!Z21)) | ... K42: =IF($A42="","",N('JANUAR'!AB21)+N('FEBRUAR'!AB21)+N('MÄRZ'!AB21)+N('APRIL'!AB21)+N('MAI'!AB21)+N('JUNI'!AB21)+N('JULI'!AB21)+N('AUGUST'!AB21)+N('SEPTEMBER'!AB21)+N('OKTOBER'!AB21)+N('NOVEMBER'!AB21)+N('DEZEMBER'!AB21)) | L42: =IF(OR($A42="",$F$57=0),"",F42/$F$57)
A43: =IF(LISTEN!$A$18="","",LISTEN!$A$18) | B43: =IF($A43="","",N('JANUAR'!S22)+N('FEBRUAR'!S22)+N('MÄRZ'!S22)+N('APRIL'!S22)+N('MAI'!S22)+N('JUNI'!S22)+N('JULI'!S22)+N('AUGUST'!S22)+N('SEPTEMBER'!S22)+N('OKTOBER'!S22)+N('NOVEMBER'!S22)+N('DEZEMBER'!S22)) | C43: =IF($A43="","",N('JANUAR'!T22)+N('FEBRUAR'!T22)+N('MÄRZ'!T22)+N('APRIL'!T22)+N('MAI'!T22)+N('JUNI'!T22)+N('JULI'!T22)+N('AUGUST'!T22)+N('SEPTEMBER'!T22)+N('OKTOBER'!T22)+N('NOVEMBER'!T22)+N('DEZEMBER'!T22)) | D43: =IF($A43="","",N('JANUAR'!U22)+N('FEBRUAR'!U22)+N('MÄRZ'!U22)+N('APRIL'!U22)+N('MAI'!U22)+N('JUNI'!U22)+N('JULI'!U22)+N('AUGUST'!U22)+N('SEPTEMBER'!U22)+N('OKTOBER'!U22)+N('NOVEMBER'!U22)+N('DEZEMBER'!U22)) | E43: =IF($A43="","",N('JANUAR'!V22)+N('FEBRUAR'!V22)+N('MÄRZ'!V22)+N('APRIL'!V22)+N('MAI'!V22)+N('JUNI'!V22)+N('JULI'!V22)+N('AUGUST'!V22)+N('SEPTEMBER'!V22)+N('OKTOBER'!V22)+N('NOVEMBER'!V22)+N('DEZEMBER'!V22)) | F43: =IF($A43="","",N('JANUAR'!W22)+N('FEBRUAR'!W22)+N('MÄRZ'!W22)+N('APRIL'!W22)+N('MAI'!W22)+N('JUNI'!W22)+N('JULI'!W22)+N('AUGUST'!W22)+N('SEPTEMBER'!W22)+N('OKTOBER'!W22)+N('NOVEMBER'!W22)+N('DEZEMBER'!W22)) | G43: =IF($A43="","",N('JANUAR'!X22)+N('FEBRUAR'!X22)+N('MÄRZ'!X22)+N('APRIL'!X22)+N('MAI'!X22)+N('JUNI'!X22)+N('JULI'!X22)+N('AUGUST'!X22)+N('SEPTEMBER'!X22)+N('OKTOBER'!X22)+N('NOVEMBER'!X22)+N('DEZEMBER'!X22)) | H43: =IF($A43="","",N('JANUAR'!Y22)+N('FEBRUAR'!Y22)+N('MÄRZ'!Y22)+N('APRIL'!Y22)+N('MAI'!Y22)+N('JUNI'!Y22)+N('JULI'!Y22)+N('AUGUST'!Y22)+N('SEPTEMBER'!Y22)+N('OKTOBER'!Y22)+N('NOVEMBER'!Y22)+N('DEZEMBER'!Y22)) | I43: =IF($A43="","",N('JANUAR'!Z22)+N('FEBRUAR'!Z22)+N('MÄRZ'!Z22)+N('APRIL'!Z22)+N('MAI'!Z22)+N('JUNI'!Z22)+N('JULI'!Z22)+N('AUGUST'!Z22)+N('SEPTEMBER'!Z22)+N('OKTOBER'!Z22)+N('NOVEMBER'!Z22)+N('DEZEMBER'!Z22)) | ... K43: =IF($A43="","",N('JANUAR'!AB22)+N('FEBRUAR'!AB22)+N('MÄRZ'!AB22)+N('APRIL'!AB22)+N('MAI'!AB22)+N('JUNI'!AB22)+N('JULI'!AB22)+N('AUGUST'!AB22)+N('SEPTEMBER'!AB22)+N('OKTOBER'!AB22)+N('NOVEMBER'!AB22)+N('DEZEMBER'!AB22)) | L43: =IF(OR($A43="",$F$57=0),"",F43/$F$57)
...

Sheet JANUAR
A1: ="JANUAR "&LISTEN!$E$2 | R1: Monatsauswertung
A2: Eine Zeile pro Angebot und Tag. Weiße Zellen ausfüllen, graue rechnen automatisch. | R2: rechnet automatisch – nicht überschreiben
C4: SUMME (gefiltert) | D4: =SUBTOTAL(9,D6:D405) | E4: =SUBTOTAL(9,E6:E405) | F4: =SUBTOTAL(9,F6:F405) | G4: =SUBTOTAL(9,G6:G405) | H4: =SUBTOTAL(9,H6:H405) | I4: =SUBTOTAL(9,I6:I405) | J4: =SUBTOTAL(9,J6:J405) | K4: =SUBTOTAL(9,K6:K405) | ... M4: =SUBTOTAL(9,M6:M405)
A5: Datum | B5: Tag | C5: Angebot | D5: Stunden | E5: w | F5: d | G5: m | H5: gesamt | I5: ab 10 | J5: ab 14 | K5: ab 16 | L5: ab 18 | M5: gesamt Alter | N5: Diensthabende | O5: Beschreibung | P5: Wichtig | R5: Angebot | S5: Stunden | T5: w | U5: d | V5: m | W5: gesamt | X5: ab 10 | Y5: ab 14 | Z5: ab 16 | AA5: ab 18 | AB5: Einträge
B6: =IF(A6="","",CHOOSE(WEEKDAY(A6,2),"Mo","Di","Mi","Do","Fr","Sa","So")) | H6: =IF(COUNT(E6:G6)=0,"",SUM(E6:G6)) | M6: =IF(COUNT(I6:L6)=0,"",SUM(I6:L6)) | R6: =IF(LISTEN!$A$2="","",LISTEN!$A$2) | S6: =IF($R6="","",SUMIFS($D$6:$D$405,$C$6:$C$405,$R6)) | T6: =IF($R6="","",SUMIFS($E$6:$E$405,$C$6:$C$405,$R6)) | U6: =IF($R6="","",SUMIFS($F$6:$F$405,$C$6:$C$405,$R6)) | V6: =IF($R6="","",SUMIFS($G$6:$G$405,$C$6:$C$405,$R6)) | W6: =IF($R6="","",SUMIFS($H$6:$H$405,$C$6:$C$405,$R6)) | X6: =IF($R6="","",SUMIFS($I$6:$I$405,$C$6:$C$405,$R6)) | Y6: =IF($R6="","",SUMIFS($J$6:$J$405,$C$6:$C$405,$R6)) | Z6: =IF($R6="","",SUMIFS($K$6:$K$405,$C$6:$C$405,$R6)) | AA6: =IF($R6="","",SUMIFS($L$6:$L$405,$C$6:$C$405,$R6)) | AB6: =IF($R6="","",COUNTIF($C$6:$C$405,$R6))
B7: =IF(A7="","",CHOOSE(WEEKDAY(A7,2),"Mo","Di","Mi","Do","Fr","Sa","So")) | H7: =IF(COUNT(E7:G7)=0,"",SUM(E7:G7)) | M7: =IF(COUNT(I7:L7)=0,"",SUM(I7:L7)) | R7: =IF(LISTEN!$A$3="","",LISTEN!$A$3) | S7: =IF($R7="","",SUMIFS($D$6:$D$405,$C$6:$C$405,$R7)) | T7: =IF($R7="","",SUMIFS($E$6:$E$405,$C$6:$C$405,$R7)) | U7: =IF($R7="","",SUMIFS($F$6:$F$405,$C$6:$C$405,$R7)) | V7: =IF($R7="","",SUMIFS($G$6:$G$405,$C$6:$C$405,$R7)) | W7: =IF($R7="","",SUMIFS($H$6:$H$405,$C$6:$C$405,$R7)) | X7: =IF($R7="","",SUMIFS($I$6:$I$405,$C$6:$C$405,$R7)) | Y7: =IF($R7="","",SUMIFS($J$6:$J$405,$C$6:$C$405,$R7)) | Z7: =IF($R7="","",SUMIFS($K$6:$K$405,$C$6:$C$405,$R7)) | AA7: =IF($R7="","",SUMIFS($L$6:$L$405,$C$6:$C$405,$R7)) | AB7: =IF($R7="","",COUNTIF($C$6:$C$405,$R7))
B8: =IF(A8="","",CHOOSE(WEEKDAY(A8,2),"Mo","Di","Mi","Do","Fr","Sa","So")) | H8: =IF(COUNT(E8:G8)=0,"",SUM(E8:G8)) | M8: =IF(COUNT(I8:L8)=0,"",SUM(I8:L8)) | R8: =IF(LISTEN!$A$4="","",LISTEN!$A$4) | S8: =IF($R8="","",SUMIFS($D$6:$D$405,$C$6:$C$405,$R8)) | T8: =IF($R8="","",SUMIFS($E$6:$E$405,$C$6:$C$405,$R8)) | U8: =IF($R8="","",SUMIFS($F$6:$F$405,$C$6:$C$405,$R8)) | V8: =IF($R8="","",SUMIFS($G$6:$G$405,$C$6:$C$405,$R8)) | W8: =IF($R8="","",SUMIFS($H$6:$H$405,$C$6:$C$405,$R8)) | X8: =IF($R8="","",SUMIFS($I$6:$I$405,$C$6:$C$405,$R8)) | Y8: =IF($R8="","",SUMIFS($J$6:$J$405,$C$6:$C$405,$R8)) | Z8: =IF($R8="","",SUMIFS($K$6:$K$405,$C$6:$C$405,$R8)) | AA8: =IF($R8="","",SUMIFS($L$6:$L$405,$C$6:$C$405,$R8)) | AB8: =IF($R8="","",COUNTIF($C$6:$C$405,$R8))
B9: =IF(A9="","",CHOOSE(WEEKDAY(A9,2),"Mo","Di","Mi","Do","Fr","Sa","So")) | H9: =IF(COUNT(E9:G9)=0,"",SUM(E9:G9)) | M9: =IF(COUNT(I9:L9)=0,"",SUM(I9:L9)) | R9: =IF(LISTEN!$A$5="","",LISTEN!$A$5) | S9: =IF($R9="","",SUMIFS($D$6:$D$405,$C$6:$C$405,$R9)) | T9: =IF($R9="","",SUMIFS($E$6:$E$405,$C$6:$C$405,$R9)) | U9: =IF($R9="","",SUMIFS($F$6:$F$405,$C$6:$C$405,$R9)) | V9: =IF($R9="","",SUMIFS($G$6:$G$405,$C$6:$C$405,$R9)) | W9: =IF($R9="","",SUMIFS($H$6:$H$405,$C$6:$C$405,$R9)) | X9: =IF($R9="","",SUMIFS($I$6:$I$405,$C$6:$C$405,$R9)) | Y9: =IF($R9="","",SUMIFS($J$6:$J$405,$C$6:$C$405,$R9)) | Z9: =IF($R9="","",SUMIFS($K$6:$K$405,$C$6:$C$405,$R9)) | AA9: =IF($R9="","",SUMIFS($L$6:$L$405,$C$6:$C$405,$R9)) | AB9: =IF($R9="","",COUNTIF($C$6:$C$405,$R9))
B10: =IF(A10="","",CHOOSE(WEEKDAY(A10,2),"Mo","Di","Mi","Do","Fr","Sa","So")) | H10: =IF(COUNT(E10:G10)=0,"",SUM(E10:G10)) | M10: =IF(COUNT(I10:L10)=0,"",SUM(I10:L10)) | R10: =IF(LISTEN!$A$6="","",LISTEN!$A$6) | S10: =IF($R10="","",SUMIFS($D$6:$D$405,$C$6:$C$405,$R10)) | T10: =IF($R10="","",SUMIFS($E$6:$E$405,$C$6:$C$405,$R10)) | U10: =IF($R10="","",SUMIFS($F$6:$F$405,$C$6:$C$405,$R10)) | V10: =IF($R10="","",SUMIFS($G$6:$G$405,$C$6:$C$405,$R10)) | W10: =IF($R10="","",SUMIFS($H$6:$H$405,$C$6:$C$405,$R10)) | X10: =IF($R10="","",SUMIFS($I$6:$I$405,$C$6:$C$405,$R10)) | Y10: =IF($R10="","",SUMIFS($J$6:$J$405,$C$6:$C$405,$R10)) | Z10: =IF($R10="","",SUMIFS($K$6:$K$405,$C$6:$C$405,$R10)) | AA10: =IF($R10="","",SUMIFS($L$6:$L$405,$C$6:$C$405,$R10)) | AB10: =IF($R10="","",COUNTIF($C$6:$C$405,$R10))
B11: =IF(A11="","",CHOOSE(WEEKDAY(A11,2),"Mo","Di","Mi","Do","Fr","Sa","So")) | H11: =IF(COUNT(E11:G11)=0,"",SUM(E11:G11)) | M11: =IF(COUNT(I11:L11)=0,"",SUM(I11:L11)) | R11: =IF(LISTEN!$A$7="","",LISTEN!$A$7) | S11: =IF($R11="","",SUMIFS($D$6:$D$405,$C$6:$C$405,$R11)) | T11: =IF($R11="","",SUMIFS($E$6:$E$405,$C$6:$C$405,$R11)) | U11: =IF($R11="","",SUMIFS($F$6:$F$405,$C$6:$C$405,$R11)) | V11: =IF($R11="","",SUMIFS($G$6:$G$405,$C$6:$C$405,$R11)) | W11: =IF($R11="","",SUMIFS($H$6:$H$405,$C$6:$C$405,$R11)) | X11: =IF($R11="","",SUMIFS($I$6:$I$405,$C$6:$C$405,$R11)) | Y11: =IF($R11="","",SUMIFS($J$6:$J$405,$C$6:$C$405,$R11)) | Z11: =IF($R11="","",SUMIFS($K$6:$K$405,$C$6:$C$405,$R11)) | AA11: =IF($R11="","",SUMIFS($L$6:$L$405,$C$6:$C$405,$R11)) | AB11: =IF($R11="","",COUNTIF($C$6:$C$405,$R11))
B12: =IF(A12="","",CHOOSE(WEEKDAY(A12,2),"Mo","Di","Mi","Do","Fr","Sa","So")) | H12: =IF(COUNT(E12:G12)=0,"",SUM(E12:G12)) | M12: =IF(COUNT(I12:L12)=0,"",SUM(I12:L12)) | R12: =IF(LISTEN!$A$8="","",LISTEN!$A$8) | S12: =IF($R12="","",SUMIFS($D$6:$D$405,$C$6:$C$405,$R12)) | T12: =IF($R12="","",SUMIFS($E$6:$E$405,$C$6:$C$405,$R12)) | U12: =IF($R12="","",SUMIFS($F$6:$F$405,$C$6:$C$405,$R12)) | V12: =IF($R12="","",SUMIFS($G$6:$G$405,$C$6:$C$405,$R12)) | W12: =IF($R12="","",SUMIFS($H$6:$H$405,$C$6:$C$405,$R12)) | X12: =IF($R12="","",SUMIFS($I$6:$I$405,$C$6:$C$405,$R12)) | Y12: =IF($R12="","",SUMIFS($J$6:$J$405,$C$6:$C$405,$R12)) | Z12: =IF($R12="","",SUMIFS($K$6:$K$405,$C$6:$C$405,$R12)) | AA12: =IF($R12="","",SUMIFS($L$6:$L$405,$C$6:$C$405,$R12)) | AB12: =IF($R12="","",COUNTIF($C$6:$C$405,$R12))
B13: =IF(A13="","",CHOOSE(WEEKDAY(A13,2),"Mo","Di","Mi","Do","Fr","Sa","So")) | H13: =IF(COUNT(E13:G13)=0,"",SUM(E13:G13)) | M13: =IF(COUNT(I13:L13)=0,"",SUM(I13:L13)) | R13: =IF(LISTEN!$A$9="","",LISTEN!$A$9) | S13: =IF($R13="","",SUMIFS($D$6:$D$405,$C$6:$C$405,$R13)) | T13: =IF($R13="","",SUMIFS($E$6:$E$405,$C$6:$C$405,$R13)) | U13: =IF($R13="","",SUMIFS($F$6:$F$405,$C$6:$C$405,$R13)) | V13: =IF($R13="","",SUMIFS($G$6:$G$405,$C$6:$C$405,$R13)) | W13: =IF($R13="","",SUMIFS($H$6:$H$405,$C$6:$C$405,$R13)) | X13: =IF($R13="","",SUMIFS($I$6:$I$405,$C$6:$C$405,$R13)) | Y13: =IF($R13="","",SUMIFS($J$6:$J$405,$C$6:$C$405,$R13)) | Z13: =IF($R13="","",SUMIFS($K$6:$K$405,$C$6:$C$405,$R13)) | AA13: =IF($R13="","",SUMIFS($L$6:$L$405,$C$6:$C$405,$R13)) | AB13: =IF($R13="","",COUNTIF($C$6:$C$405,$R13))
B14: =IF(A14="","",CHOOSE(WEEKDAY(A14,2),"Mo","Di","Mi","Do","Fr","Sa","So")) | H14: =IF(COUNT(E14:G14)=0,"",SUM(E14:G14)) | M14: =IF(COUNT(I14:L14)=0,"",SUM(I14:L14)) | R14: =IF(LISTEN!$A$10="","",LISTEN!$A$10) | S14: =IF($R14="","",SUMIFS($D$6:$D$405,$C$6:$C$405,$R14)) | T14: =IF($R14="","",SUMIFS($E$6:$E$405,$C$6:$C$405,$R14)) | U14: =IF($R14="","",SUMIFS($F$6:$F$405,$C$6:$C$405,$R14)) | V14: =IF($R14="","",SUMIFS($G$6:$G$405,$C$6:$C$405,$R14)) | W14: =IF($R14="","",SUMIFS($H$6:$H$405,$C$6:$C$405,$R14)) | X14: =IF($R14="","",SUMIFS($I$6:$I$405,$C$6:$C$405,$R14)) | Y14: =IF($R14="","",SUMIFS($J$6:$J$405,$C$6:$C$405,$R14)) | Z14: =IF($R14="","",SUMIFS($K$6:$K$405,$C$6:$C$405,$R14)) | AA14: =IF($R14="","",SUMIFS($L$6:$L$405,$C$6:$C$405,$R14)) | AB14: =IF($R14="","",COUNTIF($C$6:$C$405,$R14))
B15: =IF(A15="","",CHOOSE(WEEKDAY(A15,2),"Mo","Di","Mi","Do","Fr","Sa","So")) | H15: =IF(COUNT(E15:G15)=0,"",SUM(E15:G15)) | M15: =IF(COUNT(I15:L15)=0,"",SUM(I15:L15)) | R15: =IF(LISTEN!$A$11="","",LISTEN!$A$11) | S15: =IF($R15="","",SUMIFS($D$6:$D$405,$C$6:$C$405,$R15)) | T15: =IF($R15="","",SUMIFS($E$6:$E$405,$C$6:$C$405,$R15)) | U15: =IF($R15="","",SUMIFS($F$6:$F$405,$C$6:$C$405,$R15)) | V15: =IF($R15="","",SUMIFS($G$6:$G$405,$C$6:$C$405,$R15)) | W15: =IF($R15="","",SUMIFS($H$6:$H$405,$C$6:$C$405,$R15)) | X15: =IF($R15="","",SUMIFS($I$6:$I$405,$C$6:$C$405,$R15)) | Y15: =IF($R15="","",SUMIFS($J$6:$J$405,$C$6:$C$405,$R15)) | Z15: =IF($R15="","",SUMIFS($K$6:$K$405,$C$6:$C$405,$R15)) | AA15: =IF($R15="","",SUMIFS($L$6:$L$405,$C$6:$C$405,$R15)) | AB15: =IF($R15="","",COUNTIF($C$6:$C$405,$R15))
B16: =IF(A16="","",CHOOSE(WEEKDAY(A16,2),"Mo","Di","Mi","Do","Fr","Sa","So")) | H16: =IF(COUNT(E16:G16)=0,"",SUM(E16:G16)) | M16: =IF(COUNT(I16:L16)=0,"",SUM(I16:L16)) | R16: =IF(LISTEN!$A$12="","",LISTEN!$A$12) | S16: =IF($R16="","",SUMIFS($D$6:$D$405,$C$6:$C$405,$R16)) | T16: =IF($R16="","",SUMIFS($E$6:$E$405,$C$6:$C$405,$R16)) | U16: =IF($R16="","",SUMIFS($F$6:$F$405,$C$6:$C$405,$R16)) | V16: =IF($R16="","",SUMIFS($G$6:$G$405,$C$6:$C$405,$R16)) | W16: =IF($R16="","",SUMIFS($H$6:$H$405,$C$6:$C$405,$R16)) | X16: =IF($R16="","",SUMIFS($I$6:$I$405,$C$6:$C$405,$R16)) | Y16: =IF($R16="","",SUMIFS($J$6:$J$405,$C$6:$C$405,$R16)) | Z16: =IF($R16="","",SUMIFS($K$6:$K$405,$C$6:$C$405,$R16)) | AA16: =IF($R16="","",SUMIFS($L$6:$L$405,$C$6:$C$405,$R16)) | AB16: =IF($R16="","",COUNTIF($C$6:$C$405,$R16))
B17: =IF(A17="","",CHOOSE(WEEKDAY(A17,2),"Mo","Di","Mi","Do","Fr","Sa","So")) | H17: =IF(COUNT(E17:G17)=0,"",SUM(E17:G17)) | M17: =IF(COUNT(I17:L17)=0,"",SUM(I17:L17)) | R17: =IF(LISTEN!$A$13="","",LISTEN!$A$13) | S17: =IF($R17="","",SUMIFS($D$6:$D$405,$C$6:$C$405,$R17)) | T17: =IF($R17="","",SUMIFS($E$6:$E$405,$C$6:$C$405,$R17)) | U17: =IF($R17="","",SUMIFS($F$6:$F$405,$C$6:$C$405,$R17)) | V17: =IF($R17="","",SUMIFS($G$6:$G$405,$C$6:$C$405,$R17)) | W17: =IF($R17="","",SUMIFS($H$6:$H$405,$C$6:$C$405,$R17)) | X17: =IF($R17="","",SUMIFS($I$6:$I$405,$C$6:$C$405,$R17)) | Y17: =IF($R17="","",SUMIFS($J$6:$J$405,$C$6:$C$405,$R17)) | Z17: =IF($R17="","",SUMIFS($K$6:$K$405,$C$6:$C$405,$R17)) | AA17: =IF($R17="","",SUMIFS($L$6:$L$405,$C$6:$C$405,$R17)) | AB17: =IF($R17="","",COUNTIF($C$6:$C$405,$R17))
B18: =IF(A18="","",CHOOSE(WEEKDAY(A18,2),"Mo","Di","Mi","Do","Fr","Sa","So")) | H18: =IF(COUNT(E18:G18)=0,"",SUM(E18:G18)) | M18: =IF(COUNT(I18:L18)=0,"",SUM(I18:L18)) | R18: =IF(LISTEN!$A$14="","",LISTEN!$A$14) | S18: =IF($R18="","",SUMIFS($D$6:$D$405,$C$6:$C$405,$R18)) | T18: =IF($R18="","",SUMIFS($E$6:$E$405,$C$6:$C$405,$R18)) | U18: =IF($R18="","",SUMIFS($F$6:$F$405,$C$6:$C$405,$R18)) | V18: =IF($R18="","",SUMIFS($G$6:$G$405,$C$6:$C$405,$R18)) | W18: =IF($R18="","",SUMIFS($H$6:$H$405,$C$6:$C$405,$R18)) | X18: =IF($R18="","",SUMIFS($I$6:$I$405,$C$6:$C$405,$R18)) | Y18: =IF($R18="","",SUMIFS($J$6:$J$405,$C$6:$C$405,$R18)) | Z18: =IF($R18="","",SUMIFS($K$6:$K$405,$C$6:$C$405,$R18)) | AA18: =IF($R18="","",SUMIFS($L$6:$L$405,$C$6:$C$405,$R18)) | AB18: =IF($R18="","",COUNTIF($C$6:$C$405,$R18))
B19: =IF(A19="","",CHOOSE(WEEKDAY(A19,2),"Mo","Di","Mi","Do","Fr","Sa","So")) | H19: =IF(COUNT(E19:G19)=0,"",SUM(E19:G19)) | M19: =IF(COUNT(I19:L19)=0,"",SUM(I19:L19)) | R19: =IF(LISTEN!$A$15="","",LISTEN!$A$15) | S19: =IF($R19="","",SUMIFS($D$6:$D$405,$C$6:$C$405,$R19)) | T19: =IF($R19="","",SUMIFS($E$6:$E$405,$C$6:$C$405,$R19)) | U19: =IF($R19="","",SUMIFS($F$6:$F$405,$C$6:$C$405,$R19)) | V19: =IF($R19="","",SUMIFS($G$6:$G$405,$C$6:$C$405,$R19)) | W19: =IF($R19="","",SUMIFS($H$6:$H$405,$C$6:$C$405,$R19)) | X19: =IF($R19="","",SUMIFS($I$6:$I$405,$C$6:$C$405,$R19)) | Y19: =IF($R19="","",SUMIFS($J$6:$J$405,$C$6:$C$405,$R19)) | Z19: =IF($R19="","",SUMIFS($K$6:$K$405,$C$6:$C$405,$R19)) | AA19: =IF($R19="","",SUMIFS($L$6:$L$405,$C$6:$C$405,$R19)) | AB19: =IF($R19="","",COUNTIF($C$6:$C$405,$R19))
B20: =IF(A20="","",CHOOSE(WEEKDAY(A20,2),"Mo","Di","Mi","Do","Fr","Sa","So")) | H20: =IF(COUNT(E20:G20)=0,"",SUM(E20:G20)) | M20: =IF(COUNT(I20:L20)=0,"",SUM(I20:L20)) | R20: =IF(LISTEN!$A$16="","",LISTEN!$A$16) | S20: =IF($R20="","",SUMIFS($D$6:$D$405,$C$6:$C$405,$R20)) | T20: =IF($R20="","",SUMIFS($E$6:$E$405,$C$6:$C$405,$R20)) | U20: =IF($R20="","",SUMIFS($F$6:$F$405,$C$6:$C$405,$R20)) | V20: =IF($R20="","",SUMIFS($G$6:$G$405,$C$6:$C$405,$R20)) | W20: =IF($R20="","",SUMIFS($H$6:$H$405,$C$6:$C$405,$R20)) | X20: =IF($R20="","",SUMIFS($I$6:$I$405,$C$6:$C$405,$R20)) | Y20: =IF($R20="","",SUMIFS($J$6:$J$405,$C$6:$C$405,$R20)) | Z20: =IF($R20="","",SUMIFS($K$6:$K$405,$C$6:$C$405,$R20)) | AA20: =IF($R20="","",SUMIFS($L$6:$L$405,$C$6:$C$405,$R20)) | AB20: =IF($R20="","",COUNTIF($C$6:$C$405,$R20))
B21: =IF(A21="","",CHOOSE(WEEKDAY(A21,2),"Mo","Di","Mi","Do","Fr","Sa","So")) | H21: =IF(COUNT(E21:G21)=0,"",SUM(E21:G21)) | M21: =IF(COUNT(I21:L21)=0,"",SUM(I21:L21)) | R21: =IF(LISTEN!$A$17="","",LISTEN!$A$17) | S21: =IF($R21="","",SUMIFS($D$6:$D$405,$C$6:$C$405,$R21)) | T21: =IF($R21="","",SUMIFS($E$6:$E$405,$C$6:$C$405,$R21)) | U21: =IF($R21="","",SUMIFS($F$6:$F$405,$C$6:$C$405,$R21)) | V21: =IF($R21="","",SUMIFS($G$6:$G$405,$C$6:$C$405,$R21)) | W21: =IF($R21="","",SUMIFS($H$6:$H$405,$C$6:$C$405,$R21)) | X21: =IF($R21="","",SUMIFS($I$6:$I$405,$C$6:$C$405,$R21)) | Y21: =IF($R21="","",SUMIFS($J$6:$J$405,$C$6:$C$405,$R21)) | Z21: =IF($R21="","",SUMIFS($K$6:$K$405,$C$6:$C$405,$R21)) | AA21: =IF($R21="","",SUMIFS($L$6:$L$405,$C$6:$C$405,$R21)) | AB21: =IF($R21="","",COUNTIF($C$6:$C$405,$R21))
B22: =IF(A22="","",CHOOSE(WEEKDAY(A22,2),"Mo","Di","Mi","Do","Fr","Sa","So")) | H22: =IF(COUNT(E22:G22)=0,"",SUM(E22:G22)) | M22: =IF(COUNT(I22:L22)=0,"",SUM(I22:L22)) | R22: =IF(LISTEN!$A$18="","",LISTEN!$A$18) | S22: =IF($R22="","",SUMIFS($D$6:$D$405,$C$6:$C$405,$R22)) | T22: =IF($R22="","",SUMIFS($E$6:$E$405,$C$6:$C$405,$R22)) | U22: =IF($R22="","",SUMIFS($F$6:$F$405,$C$6:$C$405,$R22)) | V22: =IF($R22="","",SUMIFS($G$6:$G$405,$C$6:$C$405,$R22)) | W22: =IF($R22="","",SUMIFS($H$6:$H$405,$C$6:$C$405,$R22)) | X22: =IF($R22="","",SUMIFS($I$6:$I$405,$C$6:$C$405,$R22)) | Y22: =IF($R22="","",SUMIFS($J$6:$J$405,$C$6:$C$405,$R22)) | Z22: =IF($R22="","",SUMIFS($K$6:$K$405,$C$6:$C$405,$R22)) | AA22: =IF($R22="","",SUMIFS($L$6:$L$405,$C$6:$C$405,$R22)) | AB22: =IF($R22="","",COUNTIF($C$6:$C$405,$R22))
B23: =IF(A23="","",CHOOSE(WEEKDAY(A23,2),"Mo","Di","Mi","Do","Fr","Sa","So")) | H23: =IF(COUNT(E23:G23)=0,"",SUM(E23:G23)) | M23: =IF(COUNT(I23:L23)=0,"",SUM(I23:L23)) | R23: =IF(LISTEN!$A$19="","",LISTEN!$A$19) | S23: =IF($R23="","",SUMIFS($D$6:$D$405,$C$6:$C$405,$R23)) | T23: =IF($R23="","",SUMIFS($E$6:$E$405,$C$6:$C$405,$R23)) | U23: =IF($R23="","",SUMIFS($F$6:$F$405,$C$6:$C$405,$R23)) | V23: =IF($R23="","",SUMIFS($G$6:$G$405,$C$6:$C$405,$R23)) | W23: =IF($R23="","",SUMIFS($H$6:$H$405,$C$6:$C$405,$R23)) | X23: =IF($R23="","",SUMIFS($I$6:$I$405,$C$6:$C$405,$R23)) | Y23: =IF($R23="","",SUMIFS($J$6:$J$405,$C$6:$C$405,$R23)) | Z23: =IF($R23="","",SUMIFS($K$6:$K$405,$C$6:$C$405,$R23)) | AA23: =IF($R23="","",SUMIFS($L$6:$L$405,$C$6:$C$405,$R23)) | AB23: =IF($R23="","",COUNTIF($C$6:$C$405,$R23))
B24: =IF(A24="","",CHOOSE(WEEKDAY(A24,2),"Mo","Di","Mi","Do","Fr","Sa","So")) | H24: =IF(COUNT(E24:G24)=0,"",SUM(E24:G24)) | M24: =IF(COUNT(I24:L24)=0,"",SUM(I24:L24)) | R24: =IF(LISTEN!$A$20="","",LISTEN!$A$20) | S24: =IF($R24="","",SUMIFS($D$6:$D$405,$C$6:$C$405,$R24)) | T24: =IF($R24="","",SUMIFS($E$6:$E$405,$C$6:$C$405,$R24)) | U24: =IF($R24="","",SUMIFS($F$6:$F$405,$C$6:$C$405,$R24)) | V24: =IF($R24="","",SUMIFS($G$6:$G$405,$C$6:$C$405,$R24)) | W24: =IF($R24="","",SUMIFS($H$6:$H$405,$C$6:$C$405,$R24)) | X24: =IF($R24="","",SUMIFS($I$6:$I$405,$C$6:$C$405,$R24)) | Y24: =IF($R24="","",SUMIFS($J$6:$J$405,$C$6:$C$405,$R24)) | Z24: =IF($R24="","",SUMIFS($K$6:$K$405,$C$6:$C$405,$R24)) | AA24: =IF($R24="","",SUMIFS($L$6:$L$405,$C$6:$C$405,$R24)) | AB24: =IF($R24="","",COUNTIF($C$6:$C$405,$R24))
B25: =IF(A25="","",CHOOSE(WEEKDAY(A25,2),"Mo","Di","Mi","Do","Fr","Sa","So")) | H25: =IF(COUNT(E25:G25)=0,"",SUM(E25:G25)) | M25: =IF(COUNT(I25:L25)=0,"",SUM(I25:L25)) | R25: =IF(LISTEN!$A$21="","",LISTEN!$A$21) | S25: =IF($R25="","",SUMIFS($D$6:$D$405,$C$6:$C$405,$R25)) | T25: =IF($R25="","",SUMIFS($E$6:$E$405,$C$6:$C$405,$R25)) | U25: =IF($R25="","",SUMIFS($F$6:$F$405,$C$6:$C$405,$R25)) | V25: =IF($R25="","",SUMIFS($G$6:$G$405,$C$6:$C$405,$R25)) | W25: =IF($R25="","",SUMIFS($H$6:$H$405,$C$6:$C$405,$R25)) | X25: =IF($R25="","",SUMIFS($I$6:$I$405,$C$6:$C$405,$R25)) | Y25: =IF($R25="","",SUMIFS($J$6:$J$405,$C$6:$C$405,$R25)) | Z25: =IF($R25="","",SUMIFS($K$6:$K$405,$C$6:$C$405,$R25)) | AA25: =IF($R25="","",SUMIFS($L$6:$L$405,$C$6:$C$405,$R25)) | AB25: =IF($R25="","",COUNTIF($C$6:$C$405,$R25))
B26: =IF(A26="","",CHOOSE(WEEKDAY(A26,2),"Mo","Di","Mi","Do","Fr","Sa","So")) | H26: =IF(COUNT(E26:G26)=0,"",SUM(E26:G26)) | M26: =IF(COUNT(I26:L26)=0,"",SUM(I26:L26)) | R26: =IF(LISTEN!$A$22="","",LISTEN!$A$22) | S26: =IF($R26="","",SUMIFS($D$6:$D$405,$C$6:$C$405,$R26)) | T26: =IF($R26="","",SUMIFS($E$6:$E$405,$C$6:$C$405,$R26)) | U26: =IF($R26="","",SUMIFS($F$6:$F$405,$C$6:$C$405,$R26)) | V26: =IF($R26="","",SUMIFS($G$6:$G$405,$C$6:$C$405,$R26)) | W26: =IF($R26="","",SUMIFS($H$6:$H$405,$C$6:$C$405,$R26)) | X26: =IF($R26="","",SUMIFS($I$6:$I$405,$C$6:$C$405,$R26)) | Y26: =IF($R26="","",SUMIFS($J$6:$J$405,$C$6:$C$405,$R26)) | Z26: =IF($R26="","",SUMIFS($K$6:$K$405,$C$6:$C$405,$R26)) | AA26: =IF($R26="","",SUMIFS($L$6:$L$405,$C$6:$C$405,$R26)) | AB26: =IF($R26="","",COUNTIF($C$6:$C$405,$R26))
B27: =IF(A27="","",CHOOSE(WEEKDAY(A27,2),"Mo","Di","Mi","Do","Fr","Sa","So")) | H27: =IF(COUNT(E27:G27)=0,"",SUM(E27:G27)) | M27: =IF(COUNT(I27:L27)=0,"",SUM(I27:L27)) | R27: =IF(LISTEN!$A$23="","",LISTEN!$A$23) | S27: =IF($R27="","",SUMIFS($D$6:$D$405,$C$6:$C$405,$R27)) | T27: =IF($R27="","",SUMIFS($E$6:$E$405,$C$6:$C$405,$R27)) | U27: =IF($R27="","",SUMIFS($F$6:$F$405,$C$6:$C$405,$R27)) | V27: =IF($R27="","",SUMIFS($G$6:$G$405,$C$6:$C$405,$R27)) | W27: =IF($R27="","",SUMIFS($H$6:$H$405,$C$6:$C$405,$R27)) | X27: =IF($R27="","",SUMIFS($I$6:$I$405,$C$6:$C$405,$R27)) | Y27: =IF($R27="","",SUMIFS($J$6:$J$405,$C$6:$C$405,$R27)) | Z27: =IF($R27="","",SUMIFS($K$6:$K$405,$C$6:$C$405,$R27)) | AA27: =IF($R27="","",SUMIFS($L$6:$L$405,$C$6:$C$405,$R27)) | AB27: =IF($R27="","",COUNTIF($C$6:$C$405,$R27))
B28: =IF(A28="","",CHOOSE(WEEKDAY(A28,2),"Mo","Di","Mi","Do","Fr","Sa","So")) | H28: =IF(COUNT(E28:G28)=0,"",SUM(E28:G28)) | M28: =IF(COUNT(I28:L28)=0,"",SUM(I28:L28)) | R28: =IF(LISTEN!$A$24="","",LISTEN!$A$24) | S28: =IF($R28="","",SUMIFS($D$6:$D$405,$C$6:$C$405,$R28)) | T28: =IF($R28="","",SUMIFS($E$6:$E$405,$C$6:$C$405,$R28)) | U28: =IF($R28="","",SUMIFS($F$6:$F$405,$C$6:$C$405,$R28)) | V28: =IF($R28="","",SUMIFS($G$6:$G$405,$C$6:$C$405,$R28)) | W28: =IF($R28="","",SUMIFS($H$6:$H$405,$C$6:$C$405,$R28)) | X28: =IF($R28="","",SUMIFS($I$6:$I$405,$C$6:$C$405,$R28)) | Y28: =IF($R28="","",SUMIFS($J$6:$J$405,$C$6:$C$405,$R28)) | Z28: =IF($R28="","",SUMIFS($K$6:$K$405,$C$6:$C$405,$R28)) | AA28: =IF($R28="","",SUMIFS($L$6:$L$405,$C$6:$C$405,$R28)) | AB28: =IF($R28="","",COUNTIF($C$6:$C$405,$R28))
B29: =IF(A29="","",CHOOSE(WEEKDAY(A29,2),"Mo","Di","Mi","Do","Fr","Sa","So")) | H29: =IF(COUNT(E29:G29)=0,"",SUM(E29:G29)) | M29: =IF(COUNT(I29:L29)=0,"",SUM(I29:L29)) | R29: =IF(LISTEN!$A$25="","",LISTEN!$A$25) | S29: =IF($R29="","",SUMIFS($D$6:$D$405,$C$6:$C$405,$R29)) | T29: =IF($R29="","",SUMIFS($E$6:$E$405,$C$6:$C$405,$R29)) | U29: =IF($R29="","",SUMIFS($F$6:$F$405,$C$6:$C$405,$R29)) | V29: =IF($R29="","",SUMIFS($G$6:$G$405,$C$6:$C$405,$R29)) | W29: =IF($R29="","",SUMIFS($H$6:$H$405,$C$6:$C$405,$R29)) | X29: =IF($R29="","",SUMIFS($I$6:$I$405,$C$6:$C$405,$R29)) | Y29: =IF($R29="","",SUMIFS($J$6:$J$405,$C$6:$C$405,$R29)) | Z29: =IF($R29="","",SUMIFS($K$6:$K$405,$C$6:$C$405,$R29)) | AA29: =IF($R29="","",SUMIFS($L$6:$L$405,$C$6:$C$405,$R29)) | AB29: =IF($R29="","",COUNTIF($C$6:$C$405,$R29))
